Workbook
Name ________ys1: {#N/A,#N/A,FALSE,"abs";#N/A,#N/A,FALSE,"Annex-I";#N/A,#N/A,FALSE,"Annex-II";#N/A,#N/A,FALSE,"Annex-III";#N/A,#N/A,FALSE,"Annex-IV";#N/A,#N/A,FALSE,"Annex-V";#N/A,#N/A,FALSE,"Annex-VI"}
Name ________ys1: {#N/A,#N/A,FALSE,"abs";#N/A,#N/A,FALSE,"Annex-I";#N/A,#N/A,FALSE,"Annex-II";#N/A,#N/A,FALSE,"Annex-III";#N/A,#N/A,FALSE,"Annex-IV";#N/A,#N/A,FALSE,"Annex-V";#N/A,#N/A,FALSE,"Annex-VI"}
Name ________ys1: {#N/A,#N/A,FALSE,"abs";#N/A,#N/A,FALSE,"Annex-I";#N/A,#N/A,FALSE,"Annex-II";#N/A,#N/A,FALSE,"Annex-III";#N/A,#N/A,FALSE,"Annex-IV";#N/A,#N/A,FALSE,"Annex-V";#N/A,#N/A,FALSE,"Annex-VI"}
Name _______ys1: {#N/A,#N/A,FALSE,"abs";#N/A,#N/A,FALSE,"Annex-I";#N/A,#N/A,FALSE,"Annex-II";#N/A,#N/A,FALSE,"Annex-III";#N/A,#N/A,FALSE,"Annex-IV";#N/A,#N/A,FALSE,"Annex-V";#N/A,#N/A,FALSE,"Annex-VI"}
Name _______ys1: {#N/A,#N/A,FALSE,"abs";#N/A,#N/A,FALSE,"Annex-I";#N/A,#N/A,FALSE,"Annex-II";#N/A,#N/A,FALSE,"Annex-III";#N/A,#N/A,FALSE,"Annex-IV";#N/A,#N/A,FALSE,"Annex-V";#N/A,#N/A,FALSE,"Annex-VI"}
Name _______ys1: {#N/A,#N/A,FALSE,"abs";#N/A,#N/A,FALSE,"Annex-I";#N/A,#N/A,FALSE,"Annex-II";#N/A,#N/A,FALSE,"Annex-III";#N/A,#N/A,FALSE,"Annex-IV";#N/A,#N/A,FALSE,"Annex-V";#N/A,#N/A,FALSE,"Annex-VI"}
Name ______ys1: {#N/A,#N/A,FALSE,"abs";#N/A,#N/A,FALSE,"Annex-I";#N/A,#N/A,FALSE,"Annex-II";#N/A,#N/A,FALSE,"Annex-III";#N/A,#N/A,FALSE,"Annex-IV";#N/A,#N/A,FALSE,"Annex-V";#N/A,#N/A,FALSE,"Annex-VI"}
Name ______ys1: {#N/A,#N/A,FALSE,"abs";#N/A,#N/A,FALSE,"Annex-I";#N/A,#N/A,FALSE,"Annex-II";#N/A,#N/A,FALSE,"Annex-III";#N/A,#N/A,FALSE,"Annex-IV";#N/A,#N/A,FALSE,"Annex-V";#N/A,#N/A,FALSE,"Annex-VI"}
Name ______ys1: {#N/A,#N/A,FALSE,"abs";#N/A,#N/A,FALSE,"Annex-I";#N/A,#N/A,FALSE,"Annex-II";#N/A,#N/A,FALSE,"Annex-III";#N/A,#N/A,FALSE,"Annex-IV";#N/A,#N/A,FALSE,"Annex-V";#N/A,#N/A,FALSE,"Annex-VI"}
Name _____ys1: {#N/A,#N/A,FALSE,"abs";#N/A,#N/A,FALSE,"Annex-I";#N/A,#N/A,FALSE,"Annex-II";#N/A,#N/A,FALSE,"Annex-III";#N/A,#N/A,FALSE,"Annex-IV";#N/A,#N/A,FALSE,"Annex-V";#N/A,#N/A,FALSE,"Annex-VI"}
Name _____ys1: {#N/A,#N/A,FALSE,"abs";#N/A,#N/A,FALSE,"Annex-I";#N/A,#N/A,FALSE,"Annex-II";#N/A,#N/A,FALSE,"Annex-III";#N/A,#N/A,FALSE,"Annex-IV";#N/A,#N/A,FALSE,"Annex-V";#N/A,#N/A,FALSE,"Annex-VI"}
Name _____ys1: {#N/A,#N/A,FALSE,"abs";#N/A,#N/A,FALSE,"Annex-I";#N/A,#N/A,FALSE,"Annex-II";#N/A,#N/A,FALSE,"Annex-III";#N/A,#N/A,FALSE,"Annex-IV";#N/A,#N/A,FALSE,"Annex-V";#N/A,#N/A,FALSE,"Annex-VI"}
Name ____d2: {#N/A,#N/A,FALSE,"mgtsum.XLS";#N/A,#N/A,FALSE,"CAPONE";#N/A,#N/A,FALSE,"CAPTWO";#N/A,#N/A,FALSE,"CAPTHREE"}
Name ____d2: {#N/A,#N/A,FALSE,"mgtsum.XLS";#N/A,#N/A,FALSE,"CAPONE";#N/A,#N/A,FALSE,"CAPTWO";#N/A,#N/A,FALSE,"CAPTHREE"}
Name ____d2: {#N/A,#N/A,FALSE,"mgtsum.XLS";#N/A,#N/A,FALSE,"CAPONE";#N/A,#N/A,FALSE,"CAPTWO";#N/A,#N/A,FALSE,"CAPTHREE"}
Name ____ys1: {#N/A,#N/A,FALSE,"abs";#N/A,#N/A,FALSE,"Annex-I";#N/A,#N/A,FALSE,"Annex-II";#N/A,#N/A,FALSE,"Annex-III";#N/A,#N/A,FALSE,"Annex-IV";#N/A,#N/A,FALSE,"Annex-V";#N/A,#N/A,FALSE,"Annex-VI"}
Name ____ys1: {#N/A,#N/A,FALSE,"abs";#N/A,#N/A,FALSE,"Annex-I";#N/A,#N/A,FALSE,"Annex-II";#N/A,#N/A,FALSE,"Annex-III";#N/A,#N/A,FALSE,"Annex-IV";#N/A,#N/A,FALSE,"Annex-V";#N/A,#N/A,FALSE,"Annex-VI"}
Name ____ys1: {#N/A,#N/A,FALSE,"abs";#N/A,#N/A,FALSE,"Annex-I";#N/A,#N/A,FALSE,"Annex-II";#N/A,#N/A,FALSE,"Annex-III";#N/A,#N/A,FALSE,"Annex-IV";#N/A,#N/A,FALSE,"Annex-V";#N/A,#N/A,FALSE,"Annex-VI"}
Name ___d2: {#N/A,#N/A,FALSE,"mgtsum.XLS";#N/A,#N/A,FALSE,"CAPONE";#N/A,#N/A,FALSE,"CAPTWO";#N/A,#N/A,FALSE,"CAPTHREE"}
Name ___d2: {#N/A,#N/A,FALSE,"mgtsum.XLS";#N/A,#N/A,FALSE,"CAPONE";#N/A,#N/A,FALSE,"CAPTWO";#N/A,#N/A,FALSE,"CAPTHREE"}
Name ___d2: {#N/A,#N/A,FALSE,"mgtsum.XLS";#N/A,#N/A,FALSE,"CAPONE";#N/A,#N/A,FALSE,"CAPTWO";#N/A,#N/A,FALSE,"CAPTHREE"}
Name ___fco2: {#N/A,#N/A,FALSE,"gc (2)"}
Name ___fco2: {#N/A,#N/A,FALSE,"gc (2)"}
Name ___fco2: {#N/A,#N/A,FALSE,"gc (2)"}
Name ___ns1: {#N/A,#N/A,FALSE,"COVER1.XLS ";#N/A,#N/A,FALSE,"RACT1.XLS";#N/A,#N/A,FALSE,"RACT2.XLS";#N/A,#N/A,FALSE,"ECCMP";#N/A,#N/A,FALSE,"WELDER.XLS"}
Name ___ns1: {#N/A,#N/A,FALSE,"COVER1.XLS ";#N/A,#N/A,FALSE,"RACT1.XLS";#N/A,#N/A,FALSE,"RACT2.XLS";#N/A,#N/A,FALSE,"ECCMP";#N/A,#N/A,FALSE,"WELDER.XLS"}
Name ___ns1: {#N/A,#N/A,FALSE,"COVER1.XLS ";#N/A,#N/A,FALSE,"RACT1.XLS";#N/A,#N/A,FALSE,"RACT2.XLS";#N/A,#N/A,FALSE,"ECCMP";#N/A,#N/A,FALSE,"WELDER.XLS"}
Name ___ram1: {#N/A,#N/A,FALSE,"gc (2)"}
Name ___ram1: {#N/A,#N/A,FALSE,"gc (2)"}
Name ___ram1: {#N/A,#N/A,FALSE,"gc (2)"}
Name ___sti02: {#N/A,#N/A,FALSE,"gc (2)"}
Name ___sti02: {#N/A,#N/A,FALSE,"gc (2)"}
Name ___sti02: {#N/A,#N/A,FALSE,"gc (2)"}
Name ___ta1: {#N/A,#N/A,TRUE,"Financials";#N/A,#N/A,TRUE,"Operating Statistics";#N/A,#N/A,TRUE,"Capex & Depreciation";#N/A,#N/A,TRUE,"Debt"}
Name ___ta1: {#N/A,#N/A,TRUE,"Financials";#N/A,#N/A,TRUE,"Operating Statistics";#N/A,#N/A,TRUE,"Capex & Depreciation";#N/A,#N/A,TRUE,"Debt"}
Name ___ta1: {#N/A,#N/A,TRUE,"Financials";#N/A,#N/A,TRUE,"Operating Statistics";#N/A,#N/A,TRUE,"Capex & Depreciation";#N/A,#N/A,TRUE,"Debt"}
Name ___tb1: {#N/A,#N/A,FALSE,"One Pager";#N/A,#N/A,FALSE,"Technical"}
Name ___tb1: {#N/A,#N/A,FALSE,"One Pager";#N/A,#N/A,FALSE,"Technical"}
Name ___tb1: {#N/A,#N/A,FALSE,"One Pager";#N/A,#N/A,FALSE,"Technical"}
Name ___xlfn.BAHTTEXT: #NAME?
Name ___ys1: {#N/A,#N/A,FALSE,"abs";#N/A,#N/A,FALSE,"Annex-I";#N/A,#N/A,FALSE,"Annex-II";#N/A,#N/A,FALSE,"Annex-III";#N/A,#N/A,FALSE,"Annex-IV";#N/A,#N/A,FALSE,"Annex-V";#N/A,#N/A,FALSE,"Annex-VI"}
Name ___ys1: {#N/A,#N/A,FALSE,"abs";#N/A,#N/A,FALSE,"Annex-I";#N/A,#N/A,FALSE,"Annex-II";#N/A,#N/A,FALSE,"Annex-III";#N/A,#N/A,FALSE,"Annex-IV";#N/A,#N/A,FALSE,"Annex-V";#N/A,#N/A,FALSE,"Annex-VI"}
Name ___ys1: {#N/A,#N/A,FALSE,"abs";#N/A,#N/A,FALSE,"Annex-I";#N/A,#N/A,FALSE,"Annex-II";#N/A,#N/A,FALSE,"Annex-III";#N/A,#N/A,FALSE,"Annex-IV";#N/A,#N/A,FALSE,"Annex-V";#N/A,#N/A,FALSE,"Annex-VI"}
Name __d2: {#N/A,#N/A,FALSE,"mgtsum.XLS";#N/A,#N/A,FALSE,"CAPONE";#N/A,#N/A,FALSE,"CAPTWO";#N/A,#N/A,FALSE,"CAPTHREE"}
Name __d2: {#N/A,#N/A,FALSE,"mgtsum.XLS";#N/A,#N/A,FALSE,"CAPONE";#N/A,#N/A,FALSE,"CAPTWO";#N/A,#N/A,FALSE,"CAPTHREE"}
Name __d2: {#N/A,#N/A,FALSE,"mgtsum.XLS";#N/A,#N/A,FALSE,"CAPONE";#N/A,#N/A,FALSE,"CAPTWO";#N/A,#N/A,FALSE,"CAPTHREE"}
Name __FDS_HYPERLINK_TOGGLE_STATE__: "ON"
Name __IntlFixup: TRUE
Name __ta1: {#N/A,#N/A,TRUE,"Financials";#N/A,#N/A,TRUE,"Operating Statistics";#N/A,#N/A,TRUE,"Capex & Depreciation";#N/A,#N/A,TRUE,"Debt"}
Name __ta1: {#N/A,#N/A,TRUE,"Financials";#N/A,#N/A,TRUE,"Operating Statistics";#N/A,#N/A,TRUE,"Capex & Depreciation";#N/A,#N/A,TRUE,"Debt"}
Name __ta1: {#N/A,#N/A,TRUE,"Financials";#N/A,#N/A,TRUE,"Operating Statistics";#N/A,#N/A,TRUE,"Capex & Depreciation";#N/A,#N/A,TRUE,"Debt"}
Name __tb1: {#N/A,#N/A,FALSE,"One Pager";#N/A,#N/A,FALSE,"Technical"}
Name __tb1: {#N/A,#N/A,FALSE,"One Pager";#N/A,#N/A,FALSE,"Technical"}
Name __tb1: {#N/A,#N/A,FALSE,"One Pager";#N/A,#N/A,FALSE,"Technical"}
Name __xlfn.BAHTTEXT: #NAME?
Name __ys1: {#N/A,#N/A,FALSE,"abs";#N/A,#N/A,FALSE,"Annex-I";#N/A,#N/A,FALSE,"Annex-II";#N/A,#N/A,FALSE,"Annex-III";#N/A,#N/A,FALSE,"Annex-IV";#N/A,#N/A,FALSE,"Annex-V";#N/A,#N/A,FALSE,"Annex-VI"}
Name __ys1: {#N/A,#N/A,FALSE,"abs";#N/A,#N/A,FALSE,"Annex-I";#N/A,#N/A,FALSE,"Annex-II";#N/A,#N/A,FALSE,"Annex-III";#N/A,#N/A,FALSE,"Annex-IV";#N/A,#N/A,FALSE,"Annex-V";#N/A,#N/A,FALSE,"Annex-VI"}
Name __ys1: {#N/A,#N/A,FALSE,"abs";#N/A,#N/A,FALSE,"Annex-I";#N/A,#N/A,FALSE,"Annex-II";#N/A,#N/A,FALSE,"Annex-III";#N/A,#N/A,FALSE,"Annex-IV";#N/A,#N/A,FALSE,"Annex-V";#N/A,#N/A,FALSE,"Annex-VI"}
Name _abs123: {#N/A,#N/A,FALSE,"M&B_43A_fab";#N/A,#N/A,FALSE,"M&B_43A_ERE.";#N/A,#N/A,FALSE,"M&B-43A-ALIGN"}
Name _abs123: {#N/A,#N/A,FALSE,"M&B_43A_fab";#N/A,#N/A,FALSE,"M&B_43A_ERE.";#N/A,#N/A,FALSE,"M&B-43A-ALIGN"}

Sheet SUMMARY
A1: CLIENT | B1: M/s. Paytm Bengaluru
A2: SUBJECT | B2: Detailed Offer
A3: DATE | B3: 46125
A4: CARPET AREA | B4: 12377
A5: REVISION | B5: R0
A6: SR NO | B6: PARTICULARS | C6: PER SFT | D6: AMOUNT | E6: REMARKS
A7: PART - C | B7: MEP WORKS
A8: 1 | B8: ELECTRICAL WORKS | C8: =D8/B$4 -> 458.62115 | D8: ='MEP SUMMARY'!E6 -> 5676354
A9: =+A8+1 -> 2 | B9: LIGHT FIXTURES | C9: =D9/B$4 -> 10.167973 | D9: ='MEP SUMMARY'!E7 -> 125849
A10: =+A9+1 -> 3 | B10: UPS | C10: =D10/B$4 -> #REF! | D10: =#REF! -> #REF!
A11: =+A10+1 -> 4 | B11: HVAC WORKS | C11: =D11/B$4 -> 339.3391 | D11: ='MEP SUMMARY'!E8 -> 4200000
A12: =+A11+1 -> 5 | B12: FIRE AND SAFTY | C12: =D12/B$4 -> 233.84791 | D12: ='MEP SUMMARY'!E9 -> 2894335.6
A13: =+A12+1 -> 6 | B13: ACCESS AND CCTV | C13: =D13/B$4 -> 99.16054 | D13: ='MEP SUMMARY'!E10 -> 1227310
A14: =+A13+1 -> 7 | B14: BMS
A15: =+A14+1 -> 8 | B15: NETWORKING
A16: =+A15+1 -> 9 | B16: HDMI CABLES /USB CABLES
A17: =+A16+1 -> 10 | B17: AV WORK
B18: TOTAL FOR PART - C | C18: =D18/B$4 -> #REF! | D18: =SUM(D8:D17) -> #REF!
A20: I | B20: TOTAL - WITHOUT TAXES | C20: =D20/B$4 -> #REF! | D20: =SUM(D7:D18)/2 -> #REF!
A21: a | B21: ADD LABOR CESS @1% | C21: =D21/B$4 -> #REF! | D21: =N(D20*1%) -> #REF!
A22: II | B22: TOTAL - WITH BOCW | C22: =D22/B$4 -> #REF! | D22: =SUM(D20:D21) -> #REF!
B24: KITCHEN EQUIPMENTS | C24: =D24/B$4 -> 0 | D24: 0 | E24: Not Applicable

Sheet MEP SUMMARY
A1: PAYTM MEP COSTING SUMMERY SHEET
A2: Project Location | C2: Bangalore
A3: Area
A4: Sl.No | B4: Package | C4: Supply | D4: Installation | E4: Total | F4: Remarks
A6: 1 | B6: ELECTRICAL WORKS | C6: ='ELEC BOQ'!H1400 -> 4715431 | D6: ='ELEC BOQ'!I1400 -> 960923 | E6: =SUM(C6:D6) -> 5676354
A7: =A6+1 -> 2 | B7: LIGHT FIXTURES | C7: ='LGT BOQ'!I69 -> 0 | D7: ='LGT BOQ'!J69 -> 125849 | E7: =SUM(C7:D7) -> 125849
A8: =A7+1 -> 3 | B8: HVAC WORKS | C8: ='HVAC BOQ'!G401 -> 3463623 | D8: ='HVAC BOQ'!H401 -> 736377 | E8: =SUM(C8:D8) -> 4200000
A9: =A8+1 -> 4 | B9: FIRE AND SAFTY | C9: ='FIRE & SAFETY'!G188 -> 2437564 | D9: ='FIRE & SAFETY'!H188 -> 456771.6 | E9: =SUM(C9:D9) -> 2894335.6
A10: =A9+1 -> 5 | B10: ACCESS AND CCTV | C10: ='ACS & CCTV '!H88 -> 1115510 | D10: ='ACS & CCTV '!I88 -> 111800 | E10: =SUM(C10:D10) -> 1227310
B11: Grand TOTAL | C11: =SUM(C6:C10) -> 11732128 | D11: =SUM(D6:D10) -> 2391720.6 | E11: =SUM(E6:E10) -> 14123849

Sheet PREAMBLE
A1: Preamble Points:
B3: Following is integral part of Contractors Scope of Work points and Contractor to take note of same while quoting and during execution for the work:
A5: 1 | B5: The Preamble to the Bills of Quantities must be read with the Drawings, Conditions of Contract and the Specification and the tenderer shall be deemed to have examined the Drawings, Specifications, Conditions of Contract and to have acquainted himself with the Works to be done and the way in which they are to be carried out. This preamble to the Bills of Quantities shall form part of the Contract.
A6: =A5+1 -> 2 | B6: The Tenderers are requested to inspect the site and obtain for themselves at their own expense all necessary information and particulars to enable them to submit the tender.
A7: =A6+1 -> 3 | B7: The dimensions shown in the drawings shall have to be verified by the contractor at site before execution of the items and necessary allowance's) have to be made as per the actual dimensions available at site.
A8: =A7+1 -> 4 | B8: For the items of works having Basic rate of material, price adjustment will be made only on the actual quantity measured. Wastage & Installation shall be to Contractors account. Basic rate indicates loading unloading, transportation etc.
A9: =A8+1 -> 5 | B9: The contractor should refer to the tender drawings / 3D views / Technical specifications for details. In case of any discrepancy, the drawing will take precedence, unless specifically mentioned in the BOQ.
A10: =A9+1 -> 6 | B10: All pre-fabrication works wherever possible shall be carried outside the client's premises, only assembling and finishing work will be allowed within the Site. This is specific to finishing works involving high VOC items which are not permissible to be executed within the premises. The list of such works will be mutually agreed during the kick off meeting.
A11: =A10+1 -> 7 | B11: Unless specifically mentioned otherwise in the contract, the tenderer shall quote for the finished items and shall provide for the complete cost towards labour, materials, plant and machinery, operational costs, levies, taxes, transport, repairs, rectification, maintenance till handing over, revenue expenses, contingencies, overheads, profits and all incidental items not specifically mentioned but reasonably implied and necessary to complete the works according to the contract.
A12: =A11+1 -> 8 | B12: The quantities of the various items mentioned in the schedule of items are approximate and may vary up to any extent or be deleted altogether. The quoted rates of each item shall remain firm for all works. The contractor, in his own interest, should get an indication of the probable extent of the work to be executed under any item in this schedule, before undertaking any preliminary and enabling work or purchasing bought out components related to the work.
A13: =A12+1 -> 9 | B13: Sample: Contractor at his own cost shall produce the samples for approval from Architect or EIC, after the due approval of sample contractor shall go for procurement, if architect ask for more samples contractor shall arrange for the same without delay.
A14: =A13+1 -> 10 | B14: Mock-ups: Contractor shall make or Build mock-ups to verify selections made under sample Submittals and to demonstrate aesthetic effects and qualities of materials and execution as instructed by EIC. Approval of mock-ups does not constitute approval of deviations from the Contract Documents contained in mock-ups unless Architect specifically approves such deviations in writing. Approved mock-ups may become part of the completed Work if undisturbed at time of Substantial Completion. The mock up shall be free of cost.
A15: =A14+1 -> 11 | B15: Procedure of work: The contractor shall arrange the operations that have been agreed to by the Project consultants /Employer. He shall adhere to the schedule presented by him and agreed by the project consultants and shall complete all works allotted to him in time, giving best workmanship to the entire satisfaction of the Project consultants.
A16: =A15+1 -> 12 | B16: Protection of work: Contractor shall do protection of asset’s which are not to be demolished and asset’s which are to be handover to client. He shall also provide and maintain any other temporary covering that required for the protection of financed / unfinished woodwork that may be damaged during the progress of the work if left unprotected.
A17: =A16+1 -> 13 | B17: Contractor should protect with PVC bubble guard sheet of 6mm thk all the completed works in his scope and uncover the same while it’s being handed over.
... A23: =A22+1 -> 19 | B23: Safety of contractor supplied material is contractor scope.
A24: =A23+1 -> 20
A25: =A24+1 -> 21 | B25: Items of work provided in this schedule but not covered in the specifications shall be executed strictly as per instructions of the project manager/architect.
A26: =A25+1 -> 22 | B26: All stones mentioned in the tender shall be brought to site only from the lots pre-approved /selected by the architects.
A27: =A26+1 -> 23 | B27: All Samples of tiles, fittings etc. shall be presented after ensuring that the necessary quantities of the relevant item(s) for which the same are invited are available, (ex-stock, or otherwise) and shall be approved by the architect before placing of mass orders.
A28: =A27+1 -> 24 | B28: All the Dado and/ Flooring shall include rates of the 3mm thk spacers with colour matching grouts and Edge Guards of matching colour of the dado wherever the walls are in right angles, as per instructions / related specifications towards the same, by the consulting architects
A29: =A28+1 -> 25 | B29: All joints, wherever necessary, shall be undertaken after prior approval of the same from the Architects.
A30: =A29+1 -> 26 | B30: All materials utilized shall be as per tender recommendations and shall be applied according to manufacturer's specifications.
A31: =A30+1 -> 27 | B31: The rates for all tiles, slabs of marble, granite, Kota or any other stone should be inclusive of all materials, transport, loading unloading, Octroi and all taxes thereon. The rate mentioned is the maximum and in no way should exceed, the one mentioned.
A32: =A31+1 -> 28 | B32: Rates quoted for items of counter, etc. shall be inclusive of making necessary cutouts for sinks, basins and inclusive of polishing the cut edge to the profile as indicated on the drawings, to the entire satisfaction of the supervising architects.
A33: =A32+1 -> 29 | B33: Rates quoted for the Ramps/ treads of the staircases shall be deemed to be inclusive of making all necessary cutouts, for railing balustrades, etc., in 'workmanlike manner, and, to the entire satisfaction of the supervising architects
A34: =A33+1 -> 30 | B34: Unless other wise specified all rates shall be in INR
A35: =A34+1 -> 31 | B35: Work shall be at all heights including double and triple heights and rate shall include the cost of necessary scaffolding and staging
A36: =A35+1 -> 32 | B36: Any/all inserts/U/Hat/Corner etc. profiles/grooving and laying patterns shall be as per architects specifications and shall form part of the relevant panelling detail(s) and shall not be paid for extra, unless otherwise specified/ mentioned
... A53: =A52+1 -> 49 | B53: Make list to be as per Architect / Consultants choice.

Sheet MAKES - MEP 
A1: PROJECT | B1: PAYTM
A2: SUBJECT | B2: MAKE LIST
A3: DATE | B3: 46113
A4: VERSION | B4: V0
A6: SUBJECT: STANDARD MAKES- PAYTM
B7: ITEMS | C7: MAKES
A8: A | B8: ELECTRICAL&ELV
A9: 1 | B9: LT CABLES | C9: KEI/ POLYCAB/ RR KABEL | D9: Polycab
A10: 2 | B10: CABLE GLANDS & LUGS | C10: BRACO / DOWELS / JAISON / SMI / HMI | D10: Dowells
A11: 3 | B11: FRLS / ZHFR WIRES & MULTI CORE FLEXIBLE CABLES | C11: POLYCAB / KEI/ RR KABEL | D11: Polycab
A12: 4 | B12: TECHNICAL LIGHT FIXTURES | C12: WIPRO/ PHILIPS/ARRAY STORM/ LEGERO / CENZER
A13: 5 | B13: DECORATIVE LIGHT FIXTURES | C13: LEGERO/RIPPL/ LUNNARK / PURPLE TURTLES /LANCE
A14: 6 | B14: LIGHTING CONTROL SENSORS | C14: HONEYWELL / ZEN CONTROL / LUTRON
A15: 7 | B15: FANS & EXHAUST FANS | C15: CROMPTON/ BAJAJ/ HAVELLS | D15: Caryaire
A16: 8 | B16: FLOOR BOXES & WORKSTATION POP Ups | C16: Connect System / CJ Infra
A17: 9 | B17: SWITCHES / SOCKETS & MODULAR FACE PLATES | C17: ANCHOR- ROMA / SCHNEIDER - LIVIA / LEGRAND / INDOASIA SHYNORA / SIEMENS
A18: 10 | B18: DISTRIBUTION BOARDS | C18: ABB / SCHNEIDER/ LEGRAND/ SIEMENS
A19: 11 | B19: MCBs/RCCB/RCBOs/ Isolators | C19: ABB / SCHNEIDER/ LEGRAND/ SIEMENS
A20: 12 | B20: MCCBs | C20: ABB / SCHNEIDER/ LEGRAND/ SIEMENS
A21: 13 | B21: INDUSTRIAL SOCKETS | C21: LEGRAND / SCAME / NEPTUNE / HAGER
A22: 14 | B22: PVC CONDUITS & ACCESSORIES | C22: VIP / AVANPLAST | D22: VIP
A23: 15 | B23: MS / GI CONDUITS & ACCESSORIES | C23: GUPTA / AKG/ GB
A24: 16 | B24: GI RACEWAYS / CABLE TRAYS | C24: CLASSIC / PUSHPAK / PROFAB | D24: Vickram
A25: 17 | B25: ALUMINIUM RACEWAYS | C25: JINDAL
A26: 18 | B26: UPVC TRUNKING/RACEWAY | C26: MK/ OBO BETTERMANN/ LEGRAND | D26: OBO
A27: 19 | B27: HRC SWITCH FUSE UNITS | C27: GE / L&T / SIEMENS / ABB / SCHNEIDER (MERLIN GERIN)
A28: 20 | B28: RG59 OUTLETS | C28: ANCHOR / CRABTREE(VERONA)
A29: 21 | B29: RG59 COAXIAL CABLE | C29: FINOLEX / POLYCAB
A30: 22 | B30: LOAD MANAGERS / MEASURING INSTRUMENT | C30: TRINITY / HPL / ENERCON / SECURE / SCHNEIDER / ELMEASURE
A31: 23 | B31: CONTACTORS | C31: L & T / SCHNEIDER (MERLIN GERIN) / LEGRAND
A32: 24 | B32: C.T UNIT | C32: INDCOIL / MECO / SIEMENS
A33: 25 | B33: CAPACITOR | C33: SUBODHAN / LEGRAND / EPCOS / SIEMENS
A34: 26 | B34: P.F. RELAY | C34: TRINITY / ENERCON / SECURE / L&T / SIEMENS
A35: 27 | B35: MANUAL CHANGE OVER SWITCH | C35: L & T / SCHNEIDER (MERLIN GERIN) / SOCOMEC
A36: 28 | B36: AUTOMATIC TRANSFER SWITCH (ATS) | C36: ASCO / LT / SOCOMEC
A37: 29 | B37: PANEL ACCESSORIES | C37: L&T / SIEMENS / MG / GE
A38: 30 | B38: SPD/TVSS | C38: LEGRAND / SCHNEIDER (MERLIN GERIN) / HAGER/OBO
A39: 31 | B39: LT PANELS & Fabricated DBs | C39: SHARAN CONTROLS/ MASS ENGINEERING/ SAMRUDHI CONTROLS
A41: B | B41: UPS & INVERTERS
A42: 1 | B42: UPS | C42: Vertiv / APC Schenider
...

Sheet ELEC  BOQ
A1: PROJECT | B1: : PAYTM BANGALORE
A2: SUBJECT | B2: : BILL OF QUANTITIES - ELECTRICAL
A3: DATE | B3: : 30.03.2026
A4: VERSION | B4: : V0 | D4: Quantity
A5: Sl.No. | B5: DESCRIPTION | C5: UNIT | D5: 6F | E5: Total | F5: RATE | H5: AMOUNT | J5: Total | K5: REMARKS
F6: Supply | G6: Installation | H6: Supply | I6: Installation
A8: =ROMAN(1) -> I | B8: LT PANELS :
A9: A | B9: All Panels Should be as per Technical specifications & Power distribution scheme
B10: Supply, installation, testing & commisioning of 3 Phase, 4 wire, 415 V, 50 Hz panels. The fabrication shall be made with cold rolled annealed sheet with Machine pressing. The surface shall be rigorously treated for derusting in 7 tank process with powder coating. The panel shall be totally enclosed metal clad type with double gasketting with rubber / foam gasketting. The panel shall be off- white painted inside and shall be having control directory pasted on the inside surface of the panel door. The panel shall be suitable for mounting on existing trench and shall have cable entry provision from the top and bottom with suitable alley as the case may be. The panel shall be tested for the same KA rating of the relevant highest rating of breaker. All components shall be of approved make and shall have relevant IS/IEC approvals (Fabrication, drawing, list of components and panel detail shall be got approved before fabrication). The panel shall include base frame channel support.All complete as per relevant standard, technical specification, SLD, data sheets and direction of Engineer-in-charge.
B11: Indoor type LT Switchboards, Floor mounting type, Bottom/Top entry. Refer enclosed SLD for component details.
B12: Doors:2mm Body:2mm Gland Plate :3mm covers and partitions:1.6mm
B13: IP class:IP52 for Indoor/IP55 with weather proof enclosure with top cover for outdoor
B14: Bus bars: Electrolytic grade conductivity as per standard IS 5082
B15: Bus bar Material: As per SLD
B16: Bus bar supports: DMC/FRP/SMC
B17: Bus bar joints: Shrouded/Tinned
B18: Protection releases: As per SLD (Adjustable over current & short circuit unless otherwise specified)
B19: Shade: Epoxy powder coated RAL 7032 for RP Panel & another colour for UPS Panel
B20: Design: Modular type & Form 3B Construction
B21: Cable entry: As per site condition
... B69: CPRI certified
A71: 1.1 | B71: FLOOR LT PANEL | C71: No. | D71: 1 | E71: =D71 -> 1 | F71: 336995 | G71: 30742 | H71: =+N($E71)*N(F71) -> 336995 | I71: =+N($E71)*N(G71) -> 30742 | J71: =SUM(H71:I71) -> 367737
E72: =D72 | H72: =+N($E72)*N(F72) -> 0 | I72: =+N($E72)*N(G72) -> 0 | J72: =SUM(H72:I72) -> 0
A73: =A71+0.1 -> 1.2 | B73: WORKSTATION UPS OUTPUT PANEL | C73: No. | D73: 1 | E73: =D73 -> 1 | F73: 106006 | G73: 13176 | H73: =+N($E73)*N(F73) -> 106006 | I73: =+N($E73)*N(G73) -> 13176 | J73: =SUM(H73:I73) -> 119182
E74: =D74 | H74: =+N($E74)*N(F74) -> 0 | I74: =+N($E74)*N(G74) -> 0 | J74: =SUM(H74:I74) -> 0
A75: =A73+0.1 -> 1.3 | B75: Supply, Installation, testing & commisioning of 160A, 36kA 4P MCCB Tapoff Box with RYB indicating lamps with MCB control & Meter.Tap-off to be fixed to existing rising main. For Cable termination Additional Box to be considered in costing. Existing Rising main make : All standrads to be matched with installed tap-off ratings & quality | C75: No. | D75: RO | E75: =D75 -> RO | H75: =+N($E75)*N(F75) -> 0 | I75: =+N($E75)*N(G75) -> 0 | J75: =SUM(H75:I75) -> 0
E76: =D76 | H76: =+N($E76)*N(F76) -> 0 | I76: =+N($E76)*N(G76) -> 0 | J76: =SUM(H76:I76) -> 0
A77: =A75+0.1 -> 1.4 | B77: Supply, Installation, testing & commisioning of 200A, 36kA 4P MCCB Tapoff Box with RYB indicating lamps with MCB control & Meter.Tap-off to be fixed to existing rising main. For Cable termination Additional Box to be considered in costing. Existing Rising main make : All standrads to be matched with installed tap-off ratings & quality | C77: No. | D77: RO | E77: =D77 -> RO | H77: =+N($E77)*N(F77) -> 0 | I77: =+N($E77)*N(G77) -> 0 | J77: =SUM(H77:I77) -> 0
E78: =D78 | H78: =+N($E78)*N(F78) -> 0 | I78: =+N($E78)*N(G78) -> 0 | J78: =SUM(H78:I78) -> 0
A79: =A77+0.1 -> 1.5 | B79: Supply, Installation, testing & commisioning of 400A, 36kA 4P MCCB Tapoff Box with RYB indicating lamps with MCB control & Meter.Tap-off to be fixed to existing rising main. For Cable termination Additional Box to be considered in costing. Existing Rising main make : All standrads to be matched with installed tap-off ratings & quality | C79: No. | D79: RO | E79: =D79 -> RO | H79: =+N($E79)*N(F79) -> 0 | I79: =+N($E79)*N(G79) -> 0 | J79: =SUM(H79:I79) -> 0
E80: =D80 | H80: =+N($E80)*N(F80) -> 0 | I80: =+N($E80)*N(G80) -> 0 | J80: =SUM(H80:I80) -> 0
A81: =A79+0.1 -> 1.6 | B81: Supply, Installation, testing & commisioning of 630A, 36kA 4P MCCB Tapoff Box with RYB indicating lamps with MCB control & Meter.Tap-off to be fixed to existing rising main. For Cable termination Additional Box to be considered in costing. Existing Rising main make : All standrads to be matched with installed tap-off ratings & quality | C81: No. | D81: RO | E81: =D81 -> RO | H81: =+N($E81)*N(F81) -> 0 | I81: =+N($E81)*N(G81) -> 0 | J81: =SUM(H81:I81) -> 0
E82: =D82 | H82: =+N($E82)*N(F82) -> 0 | I82: =+N($E82)*N(G82) -> 0 | J82: =SUM(H82:I82) -> 0
A83: =A81+0.1 -> 1.7 | B83: Supply, installation, testing & commissioning of 160A 4P MCCB 36KA to existing Builder Main panel . Costing shall include all necessary accessories like indication lamp , Meters , CT & control wiring etc. Vendor should do the site survey for better understanding & clarity. Panel RAL colour & Quality of additional works should match with existing panel.Costing shall include opening of cutout , cable box as per site condition & site survey to be done for any clarification .. Required all costing to be quoted in this line item to complete the works | C83: No. | D83: RO | E83: =D83 -> RO | H83: =+N($E83)*N(F83) -> 0 | I83: =+N($E83)*N(G83) -> 0 | J83: =SUM(H83:I83) -> 0
E84: =D84 | H84: =+N($E84)*N(F84) -> 0 | I84: =+N($E84)*N(G84) -> 0 | J84: =SUM(H84:I84) -> 0
A85: =A83+0.1 -> 1.8 | B85: Supply, installation, testing & commissioning of 250A 4P MCCB 36KA to existing Builder Main panel . Costing shall include all necessary accessories like indication lamp , Meters , CT & control wiring etc. Vendor should do the site survey for better understanding & clarity. Panel RAL colour & Quality of additional works should match with existing panel.Costing shall include opening of cutout , cable box as per site condition & site survey to be done for any clarification .. Required all costing to be quoted in this line item to complete the works | C85: No. | D85: RO | E85: =D85 -> RO | H85: =+N($E85)*N(F85) -> 0 | I85: =+N($E85)*N(G85) -> 0 | J85: =SUM(H85:I85) -> 0
E86: =D86 | H86: =+N($E86)*N(F86) -> 0 | I86: =+N($E86)*N(G86) -> 0 | J86: =SUM(H86:I86) -> 0
A87: =A85+0.1 -> 1.9 | B87: Supply, installation, testing & commissioning of 400A 4P MCCB 36KA to existing Builder Main panel . Costing shall include all necessary accessories like indication lamp , Meters , CT & control wiring etc. Vendor should do the site survey for better understanding & clarity. Panel RAL colour & Quality of additional works should match with existing panel.Costing shall include opening of cutout , cable box as per site condition & site survey to be done for any clarification .. Required all costing to be quoted in this line item to complete the works | C87: No. | D87: RO | E87: =D87 -> RO | H87: =+N($E87)*N(F87) -> 0 | I87: =+N($E87)*N(G87) -> 0 | J87: =SUM(H87:I87) -> 0
E88: =D88 | H88: =+N($E88)*N(F88) -> 0 | I88: =+N($E88)*N(G88) -> 0 | J88: =SUM(H88:I88) -> 0
A89: =A87-0.8 -> 1.1 | B89: Supply, installation, testing & commissioning of 630A 4P MCCB 36KA to existing Builder Main panel . Costing shall include all necessary accessories like indication lamp , Meters , CT & control wiring etc. Vendor should do the site survey for better understanding & clarity. Panel RAL colour & Quality of additional works should match with existing panel.Costing shall include opening of cutout , cable box as per site condition & site survey to be done for any clarification .. Required all costing to be quoted in this line item to complete the works | C89: No. | D89: RO | E89: =D89 -> RO | H89: =+N($E89)*N(F89) -> 0 | I89: =+N($E89)*N(G89) -> 0 | J89: =SUM(H89:I89) -> 0
...

Sheet LGT BOQ
A1: PROJECT | B1: : PAYTM BANGALORE
A2: SUBJECT | B2: : BILL OF QUANTITES - LIGHTING
A3: DATE | B3: : 30.03.2026
A4: VERSION | B4: : V0
A6: Sl.No. | B6: DESCRIPTION | C6: REFERENCE IMAGES | D6: UNIT | E6: 6F | F6: Total | G6: RATE | I6: TOTAL | K6: TOTAL AMOUNT | L6: REMARKS
G7: Supply | H7: Installation | I7: Supply | J7: Installation
A9: =ROMAN(13) -> XIII | B9: Supply, Installation, testing & commissioning of Light fixtures and lamps with all accessories, fixing on the wall / ceiling/false ceiling/open ceiling with wooden blocks, screws ,hardware's ,suspension chain hooks/ wires with anchor fasteners as required as per the site conditions (including the earthing of fixture)
B10: Light fixtures complete with accessories like control gear, low loss (<5W ) HF Electronic ballast ,HF Electronic analogue driver, HF dimmable dali driver, HPF condensor (PF shall be >0.85 lag. ) , energy efficient high lumen output LED/fluorescent tubes / CFL lamps etc.,
B11: Note : The make & the catalogue no. mentioned here is only indicative & any of the make mentioned in recommended list of makes is preferred.
B12: The rate shall include for fittings along with transformers where required, diffuser, drivers, power factor improvement capacitors, wires, downrods etc., complete with all accessories to complete the installation as required.
B13: The Electronic analogue driver & dimmable dali driver shall be with THD between 6-8 %.
B14: Glare free symmetrical distribution
B15: IP 20
B16: Light Distribution: Direct symmetrical.
B17: CRI(Ra) >= 80
B18: surge protection: 2.5kV.
B19: Electrical protection: Class II
B20: Uniformity factor 0.8
B21: LED colour to be 6500k or as per Architect/client approval.
... B29: Note : Cost shall Include all necessary supports required for Functional as well as Decorative light fixtures
A31: A | B31: OFFICE AREA LIGHTS
A33: 13.1 | B33: Supply, Installation, testing & commisioning of Pendant Luminaire VIRAJ 70 with LED (Light Emitting Diode ) system power 30W / Meter , Should be,Luminous Flux of luminaire is ,6500k , Neutral White ,CRI >80, 230V, Direct Emission, Profile in Anodised Aluminium with Natural , Black , Champagne Light , Champagne Dark and Brown Anodising , Pre-wired batten made of Anodised Aluminium , Snap-Fit System , Screw less End-caps, Halogen free internal wiring , PMMA Diamond Prism Diffuser for Homogenous Light distribution.length - 1200mm (L ) x 80mm (H)x 60mm (W) | D33: Mtrs | E33: =40+15 -> 55 | F33: =SUM(E33) -> 55 | H33: 316 | I33: =+N($F33)*N(G33) -> 0 | J33: =+N($F33)*N(H33) -> 17380 | K33: =+SUM(I33:J33) -> 17380
F34: =SUM(E34) -> 0 | H34: 0 | I34: =+N($F34)*N(G34) -> 0 | J34: =+N($F34)*N(H34) -> 0 | K34: =+SUM(I34:J34) -> 0
A35: =A33+0.1 -> 13.2 | B35: Supply, Installation, testing & commisioning of Pendant Luminaire VIRAJ 70 with LED (Light Emitting Diode ) system power 30W / Meter , Should be,Luminous Flux of luminaire is 6500k , Neutral White ,CRI >80, 230V, Direct Emission, Profile in Anodised Aluminium with Natural , Black , Champagne Light , Champagne Dark and Brown Anodising , Pre-wired batten made of Anodised Aluminium , Snap-Fit System , Screw less End-caps, Halogen free internal wiring , PMMA Diamond Prism Diffuser for Homogenous Light distribution.length - 1200mm (L ) x 80mm (H)x 60mm (W)(DALI DIMMABLE DRIVER) | D35: Mtrs | E35: =35+10 -> 45 | F35: =SUM(E35) -> 45 | H35: 316 | I35: =+N($F35)*N(G35) -> 0 | J35: =+N($F35)*N(H35) -> 14220 | K35: =+SUM(I35:J35) -> 14220
H36: 0
A37: =A35+0.1 -> 13.3 | B37: Supply, Installation, testing & commisioning of Pendant Luminaire VIRAJ 70 with LED (Light Emitting Diode ) system power 30W / Meter , Should be,Luminous Flux of luminaire is ,6500k , Neutral White ,CRI >80, 230V, Direct Emission, Profile in Anodised Aluminium with Natural , Black , Champagne Light , Champagne Dark and Brown Anodising , Pre-wired batten made of Anodised Aluminium , Snap-Fit System , Screw less End-caps, Halogen free internal wiring , PMMA Diamond Prism Diffuser for Homogenous Light distribution.length - 1500mm (L ) x 80mm (H)x 60mm (W) | D37: Mtrs | E37: 16 | F37: =SUM(E37) -> 16 | H37: 316 | I37: =+N($F37)*N(G37) -> 0 | J37: =+N($F37)*N(H37) -> 5056 | K37: =+SUM(I37:J37) -> 5056
F38: =SUM(E38) -> 0 | H38: 0 | I38: =+N($F38)*N(G38) -> 0 | J38: =+N($F38)*N(H38) -> 0 | K38: =+SUM(I38:J38) -> 0
A39: =A37+0.1 -> 13.4 | B39: Supply of Recessed linear Luminaire with LED (Light Emitting Diode ) system power 26W / Meter ,230V, Direct Emission, Profile in Anodized Aluminum with Natural , Black , Champagne Light , Champagne Dark and Brown Anodizing , Pre-wired batten made of Anodized Aluminum , Snap-Fit System , Screw less End-caps, Halogen free internal wiring , PMMA Diamond Prism Diffuser for Homogenous Light distribution. | D39: Mtrs | E39: =45-45 -> 0 | F39: =SUM(E39) -> 0 | H39: 0 | I39: =+N($F39)*N(G39) -> 0 | J39: =+N($F39)*N(H39) -> 0 | K39: =+SUM(I39:J39) -> 0
F40: =SUM(E40) -> 0 | H40: 0 | I40: =+N($F40)*N(G40) -> 0 | J40: =+N($F40)*N(H40) -> 0 | K40: =+SUM(I40:J40) -> 0
A41: =A39+0.1 -> 13.5 | B41: Supply of Recessed linear Luminaire with LED (Light Emitting Diode ) system power 20 W / Meter , (with Dali dimmable driver) 230V, Direct Emission, Profile in Anodized Aluminum with Natural , Black , Champagne Light , Champagne Dark and Brown Anodizing , Pre-wired batten made of Anodized Aluminum , Snap-Fit System , Screw less End-caps, Halogen free internal wiring , PMMA Diamond Prism Diffuser for Homogenous Light distribution. | D41: Mtrs | E41: 45 | F41: =SUM(E41) -> 45 | H41: 271 | I41: =+N($F41)*N(G41) -> 0 | J41: =+N($F41)*N(H41) -> 12195 | K41: =+SUM(I41:J41) -> 12195
F42: =SUM(E42) -> 0 | H42: 0 | I42: =+N($F42)*N(G42) -> 0 | J42: =+N($F42)*N(H42) -> 0 | K42: =+SUM(I42:J42) -> 0
A43: =A41+0.1 -> 13.6 | B43: Supply, Installation, testing & commissioning of Recessed ceiling luminaire GENISO LED for LED(Light Emitting Diode ) 30W 230V, direct light emission, Sheet metal housing, powder coated white, opal diffuser in synthetic material, fixation with of support, halogen-free internal wiring, HF electronic control gear Protection class I, IP40 L = 595 mm B = 595 mm , H=60mm | D43: Nos | E43: =34-28 -> 6 | F43: =SUM(E43) -> 6 | H43: 226 | I43: =+N($F43)*N(G43) -> 0 | J43: =+N($F43)*N(H43) -> 1356 | K43: =+SUM(I43:J43) -> 1356
F44: =SUM(E44) -> 0 | H44: 0 | I44: =+N($F44)*N(G44) -> 0 | J44: =+N($F44)*N(H44) -> 0 | K44: =+SUM(I44:J44) -> 0
A45: =A43+0.1 -> 13.7 | B45: Supply, Installation, testing & commissioning of Recessed ceiling luminaire GENISO LED for LED(Light Emitting Diode ) 30W (with Dali dimmable driver) 230V, direct light emission, Sheet metal housing, powder coated white, opal diffuser in synthetic material, fixation with of support, halogen-free internal wiring, HF electronic control gear Protection class I, IP40 L = 595 mm B = 595 mm , H=60mm | D45: Nos | E45: 34 | F45: =SUM(E45) -> 34 | H45: 226 | I45: =+N($F45)*N(G45) -> 0 | J45: =+N($F45)*N(H45) -> 7684 | K45: =+SUM(I45:J45) -> 7684
F46: =SUM(E46) -> 0 | H46: 0 | I46: =+N($F46)*N(G46) -> 0 | J46: =+N($F46)*N(H46) -> 0 | K46: =+SUM(I46:J46) -> 0
A47: =A45+0.1 -> 13.8 | B47: Supply, Installation, testing & commissioning of Recessed ceiling luminaire GENISO LED for LED(Light Emitting Diode ) 30W. 230V, direct light emission, Sheet metal housing, powder coated white, opal diffuser in synthetic material, fixation with of support, halogen-free internal wiring, HF electronic control gear Protection class I, IP65 L = 595 mm B = 595 mm , H=60mm (For kitchen area) | D47: Nos | F47: =SUM(E47) -> 0 | H47: 0 | I47: =+N($F47)*N(G47) -> 0 | J47: =+N($F47)*N(H47) -> 0 | K47: =+SUM(I47:J47) -> 0
F48: =SUM(E48) -> 0 | H48: 0 | I48: =+N($F48)*N(G48) -> 0 | J48: =+N($F48)*N(H48) -> 0 | K48: =+SUM(I48:J48) -> 0
A49: =A47+0.1 -> 13.9 | B49: 4ft Linear LED Batten with a nominal system lumen output of 2000 lumens and a minimum system efficacy of 105 lm/W. System wattage should not exceed 19W. The luminaire housing should be made of CRCA with a PC glossy diffuser. | D49: Nos | E49: 12 | F49: =SUM(E49) -> 12 | H49: 136 | I49: =+N($F49)*N(G49) -> 0 | J49: =+N($F49)*N(H49) -> 1632 | K49: =+SUM(I49:J49) -> 1632
F50: =SUM(E50) -> 0 | H50: 0 | I50: =+N($F50)*N(G50) -> 0 | J50: =+N($F50)*N(H50) -> 0 | K50: =+SUM(I50:J50) -> 0
A51: =A49+0.1 -> 14 | B51: Supply, Installation, testing & commissioning of Recessed light with LED (Light Emitting Diode) System Power -12W with 6 inch diameter | D51: Nos | E51: =139-40+10 -> 109 | F51: =SUM(E51) -> 109 | H51: 226 | I51: =+N($F51)*N(G51) -> 0 | J51: =+N($F51)*N(H51) -> 24634 | K51: =+SUM(I51:J51) -> 24634
...

Sheet HVAC BOQ
A1: PROJECT | B1: PAYTM
A2: SUBJECT | B2: HVAC BOQ
A3: VERSION | B3: V0
A4: Sl.No. | B4: DESCRIPTION | C4: UNIT | D4: QNT | E4: RATE | G4: AMOUNT | I4: Total
E5: Supply | F5: Installation | G5: Supply | H5: Installation
B6: Note :Prices quoted in this tender shall be inclusive of cost of materials, labours, supervision, Supply ,installation, testing and commissioning, materials erection, tools, plant appliances, scaffolding, sleeves, cutting, patching, painting, storage of material, service connections, transport to site,
A7: PART -A | B7: AIR DISTRIBUTION WORKS
A9: 1 | B9: GI FACTORY FABRICATED SUPPLY AIR PLENUMS
B10: SITC of 50 mm thk double skin panel factory fabricated plenum as per shop drawing. Plenum shall be made of outer skin 20 G powder coated G.I sheet and inner skin shall be of with 22 G plain GSS with aluminium extrusions. Density of puf panel shall be 48 kg / cub mt. with 40mm thick puf insulation ,Plenum shall suitable size to handle the required cfm not exceeding 750 fpm velocity. The price quoted shall include MS supporting arrangement for suspending the plenum from the ceiling slab ,Canvas connection to be part of scope for AHU connection ,Access doors shall be not less than 60 cm x 60 cm in size.Appropriate cutout to be made to connecte the branch ducts with dampers as per approved drawing | C10: Sqmt | D10: 25 | E10: 3300 | F10: 350 | G10: =+N($D10)*N(E10) -> 82500 | H10: =+N($D10)*N(F10) -> 8750 | I10: =+SUM(G10:H10) -> 91250
D11: 0 | G11: =+N($D11)*N(E11) -> 0 | H11: =+N($D11)*N(F11) -> 0 | I11: =+SUM(G11:H11) -> 0
A12: 2 | B12: SITC of duct silencers / Sound attenuators in supply and return air path in AHU rooms as per the approved drawings. | D12: 0 | G12: =+N($D12)*N(E12) -> 0 | H12: =+N($D12)*N(F12) -> 0 | I12: =+SUM(G12:H12) -> 0
B13: Sound attenuator qty shall be on surface area basis. | D13: 0 | G13: =+N($D13)*N(E13) -> 0 | H13: =+N($D13)*N(F13) -> 0 | I13: =+SUM(G13:H13) -> 0
B14: COMPUTER SELECTION SHOULD BE ATTACHED | D14: 0 | G14: =+N($D14)*N(E14) -> 0 | H14: =+N($D14)*N(F14) -> 0 | I14: =+SUM(G14:H14) -> 0
B15: Sound Attenuators made dissipative type to be provided on the supply & Return air duct entering the AHU Room. | D15: 0 | G15: =+N($D15)*N(E15) -> 0 | H15: =+N($D15)*N(F15) -> 0 | I15: =+SUM(G15:H15) -> 0
B16: Sound Attenuators shall consist of outer casing, sound absorbing material and internal baffles, splitters and supports ,The sound attenuators shall be suitable for minimum 18dB reduction at 250Hz octave band. | D16: 0 | G16: =+N($D16)*N(E16) -> 0 | H16: =+N($D16)*N(F16) -> 0 | I16: =+SUM(G16:H16) -> 0
B17: Casing shall be of galvanized steel of not less than 20G in thickness. Casings shall be tested to 150mmwg and shall show no leakage or distortion in this condition. | D17: 0 | G17: =+N($D17)*N(E17) -> 0 | H17: =+N($D17)*N(F17) -> 0 | I17: =+SUM(G17:H17) -> 0
B18: Sound absorbing material shall be high density Fiber glass held in place with at least 5% compression to prevent voids due to settling. Absorption material density shall be minimum 48 kg/cum. Fiberglass faced with minimum 24 g perforated galvanized sheet metal of minimum 40% open area. | D18: 0 | G18: =+N($D18)*N(E18) -> 0 | H18: =+N($D18)*N(F18) -> 0 | I18: =+SUM(G18:H18) -> 0
B19: Supply, Installation & commissioning | C19: Sqm | D19: 15 | E19: 3450 | F19: 2350 | G19: =+N($D19)*N(E19) -> 51750 | H19: =+N($D19)*N(F19) -> 35250 | I19: =+SUM(G19:H19) -> 87000
D20: 0 | G20: =+N($D20)*N(E20) -> 0 | H20: =+N($D20)*N(F20) -> 0 | I20: =+SUM(G20:H20) -> 0
A21: 3 | B21: SITC of Motorised Fire dampers -Multi blade motorised 16G GI TDF flanges type Fire Dampers with necessary accessories for supply air ducts along with motorized actuator including fire damper control panel for supply air ducts . The fire rating of the damper shall be of 90min and shall be with 600 mm sleeves suitable for the wall mounting, CBRI approved.Fire Damper shall be complete with 240/24 transformer, damper on/off indicating lamps and distribution Price shall be inclusive of copper power cabling ,control wiring,actuator with control panel, sensor and inter-locking / wiring / connection for tripping of AHU fan motor , FA intergation. | C21: Sqm | D21: 6 | E21: 10800 | F21: 2200 | G21: =+N($D21)*N(E21) -> 64800 | H21: =+N($D21)*N(F21) -> 13200 | I21: =+SUM(G21:H21) -> 78000
B22: Actuators with Control Panel for above fire dampers- actuotors should have potential free contact to know the status of the actuator Fast acting actuators Should be of High Torque Type ( 20 sec closure max, 75sec opening max ) Spring return type : 10NM (up to 0.6sqm);16NM (up to 1.6 sqm);20NM (up to 3.2sqm) | C22: No's | D22: 12 | E22: 13500 | F22: 1250 | G22: =+N($D22)*N(E22) -> 162000 | H22: =+N($D22)*N(F22) -> 15000 | I22: =+SUM(G22:H22) -> 177000
D23: 0 | G23: =+N($D23)*N(E23) -> 0 | H23: =+N($D23)*N(F23) -> 0 | I23: =+SUM(G23:H23) -> 0
A24: 4 | B24: Fire dampers -Fusible link & confirm to UL listed. | D24: 0 | G24: =+N($D24)*N(E24) -> 0 | H24: =+N($D24)*N(F24) -> 0 | I24: =+SUM(G24:H24) -> 0
B25: Supply, Installation, Testing & Commissioning of Fusible link type fire damper. Should be UL (555) listed & CBRI approved. With one or 2 side flanges as per the site condition. Fire rating should be 90min as per the UL 555. Blades shall be held in position through fusible link of temp. of 74 deg. c. Gauge of blades & frame should be 16 G. Should supply with GI made Transition piece(22Gauge) & Back draft(Gravity) damper. | C25: Sqm | D25: 1 | E25: 7841 | F25: 1623 | G25: =+N($D25)*N(E25) -> 7841 | H25: =+N($D25)*N(F25) -> 1623 | I25: =+SUM(G25:H25) -> 9464
D26: 0 | G26: =+N($D26)*N(E26) -> 0 | H26: =+N($D26)*N(F26) -> 0 | I26: =+SUM(G26:H26) -> 0
D27: 0 | G27: =+N($D27)*N(E27) -> 0 | H27: =+N($D27)*N(F27) -> 0 | I27: =+SUM(G27:H27) -> 0
A28: 5 | B28: AIR DISTRIBUTION SYSTEM: | D28: 0 | G28: =+N($D28)*N(E28) -> 0 | H28: =+N($D28)*N(F28) -> 0 | I28: =+SUM(G28:H28) -> 0
B29: RECTANGULAR DUCT -FACTORY FABRICATED DUCTING - TDF /TDC FLANGES | D29: 0 | G29: =+N($D29)*N(E29) -> 0 | H29: =+N($D29)*N(F29) -> 0 | I29: =+SUM(G29:H29) -> 0
B30: Supply, Installation Testing & Commissioning of factory fabricated GSS Ducting with TDF /TDC flange with GI bolt & nuts (the cleat into the flange Used for C and G together with Bolt) and necessary supporting arrangement using GI full threaded rods and slotted rail. | G30: =+N($D30)*N(E30) -> 0 | H30: =+N($D30)*N(F30) -> 0 | I30: =+SUM(G30:H30) -> 0
B31: Ducting shall be designed for 500pa pressure, Galvanized steel sheet shall be of Class VIII – 120 gm /sqm zinc coating IS-277.All ducts above 1000 mm shall have Stiffener rod made of GI 1.6mm thick . | G31: =+N($D31)*N(E31) -> 0 | H31: =+N($D31)*N(F31) -> 0 | I31: =+SUM(G31:H31) -> 0
B32: Spacing between duct supports should not exceed 2m i.e GI rods with GI "C" channels. In case of duct sizes above 1800mm, MS angles duly painted with black enamel paint should be used along with neoprene pad in between the duct & MS angle. All duct support to be provided with check nuts (lock nuts). | G32: =+N($D32)*N(E32) -> 0 | H32: =+N($D32)*N(F32) -> 0 | I32: =+SUM(G32:H32) -> 0
B33: All duct construction and installation shall be as per SMACNA standards | G33: =+N($D33)*N(E33) -> 0 | H33: =+N($D33)*N(F33) -> 0 | I33: =+SUM(G33:H33) -> 0
B34: The scope shall include duct supports (including MS angle/channel arrangements for vibration-free installation), scaffolding charges, cleat joints, elbows, bends, shoe pieces, vanes, stripper rods, gaskets, bolts & nuts, end caps, Y-branches, cut ducts, droppers, offsets, mouth pieces, duct covers for transportation/installation/storage, and a 450x450 vertical trap door with handle in main ducts for servicing and cleaning | D34: 0 | G34: =+N($D34)*N(E34) -> 0 | H34: =+N($D34)*N(F34) -> 0 | I34: =+SUM(G34:H34) -> 0
B35: Pressure Testing of Ducts - Pressure testing of sheet metal ducts with necessary components like semi-rigid flexible ducts, fans and the measuring kit. Pressure testing shall be carried out for complete air distribution system excluding flexible ducts, diffuser box, diffusers and grilles. Pressure testing shall be carried out prior to thermal insulation and light test as per SMACNA standards and approval shall be obtained from PMC and consultants. , | D35: 0 | G35: =+N($D35)*N(E35) -> 0 | H35: =+N($D35)*N(F35) -> 0 | I35: =+SUM(G35:H35) -> 0
B36: Air Balancing of Air Distribution System - Third party Air balancing should be done for two times - Pre occupancy & Post occupancy along with client/PMC & Facility teams. Duct pressure testing should be with Duct leak testing machine and Air-balancing should be with Digital Hood method. All necessary tools(digital hood) should be consider in costing. Air Balancing of each individual supply air outlet to within +10% or -5% of the design air quantity and tabulating the same in a form of report and also the final air balancing figures to be indicated against each measured outlets in the as built drawings. Balancing also includes balancing of return air, supply air and outdoor fresh air quantity. Air flow hoods to be used for measuring the air flow across the Grill/diffusers. | D36: 0 | G36: =+N($D36)*N(E36) -> 0 | H36: =+N($D36)*N(F36) -> 0 | I36: =+SUM(G36:H36) -> 0
B37: Testing shall be coordinated through licensed Test and Balance supplier with the Commissioning Agent , All the duct work and equipment to be labelled with the direction of flow ,Duct system will be capable of air balancing at each floor and sub main by means of a manual damper, Adequate test ports to be provided for testing and commissioning ,Materials of construction welded galvanized steel . Note :- All the ducts laying in open ceiling has to be painted as per architect colour recomendation /specification. Painting to be considered as one coat primer and two coats of paints (Spray paint/ roller finishing). Paint cost should be part of the duct cost itself | G37: =+N($D37)*N(E37) -> 0 | H37: =+N($D37)*N(F37) -> 0 | I37: =+SUM(G37:H37) -> 0
B38: 0.50 mm (26 WG) | C38: Sqmt | D38: RO | G38: =+N($D38)*N(E38) -> 0 | H38: =+N($D38)*N(F38) -> 0 | I38: =+SUM(G38:H38) -> 0
B39: 0.63 mm (24 WG) | C39: Sqmt | D39: =150+20 -> 170 | E39: 840 | F39: 217 | G39: =+N($D39)*N(E39) -> 142800 | H39: =+N($D39)*N(F39) -> 36890 | I39: =+SUM(G39:H39) -> 179690
B40: 0.80 mm (22 WG) | C40: Sqmt | D40: 100 | E40: 940 | F40: 217 | G40: =+N($D40)*N(E40) -> 94000 | H40: =+N($D40)*N(F40) -> 21700 | I40: =+SUM(G40:H40) -> 115700
B41: 1.00 mm (20 WG) | C41: Sqmt | D41: 150 | E41: 1000 | F41: 217 | G41: =+N($D41)*N(E41) -> 150000 | H41: =+N($D41)*N(F41) -> 32550 | I41: =+SUM(G41:H41) -> 182550
...

Sheet FIRE & SAFETY
A1: PROJECT | B1: PAYTM
A2: SUBJECT | B2: LIFE SAFETY SYSTEM BOQ SUMMARY
A3: DATE | B3: 46113
A4: VERSION | B4: V0
B5: BILL OF QUANTITIES FOR FIRE AND LIFE SAFETY SYSTEMS
A6: Sl.No. | B6: DESCRIPTION | C6: UNIT | D6: QNT | E6: RATE | G6: AMOUNT
E7: Supply | F7: Installation | G7: Supply | H7: Installation | I7: Total
B8: PART-A
A9: I | B9: Analogue Addressable FA System
A10: 1 | B10: Supply Installation Testing and Commissioning of UL 864, 10th Edition and FM-approved 32-bit Microprocessor based Intelligent Addressable Peer-to-Peer networkable 2 Loop Fire Alarm Control Panel. The panel shall accommodate up to 2 nos. of 12V/50AH batteries in its housing and shall have a battery charging capacity of (up to) 2 nos. of 12V/100 AH housed externally, shall have an 8" Color Touch Screen Display to show 8 simultaneous events at a time and at least 10 custom-programmable soft and hard buttons for user-specific programmable functions. Each Detection Loop shall accommodate up to 250 detectors and devices in any flexible combination (suggested to have min. 200 detectors support per loop)and shall accommodate up to 3000 Addresses at 100% capacity in any combination. Scope includes the network card for panel-to-panel integration. Edwards Make Power supply should be tap from emergency UPS | C10: Set | D10: 1 | E10: 238870 | F10: 14219 | G10: =N($D10)*N(E10) -> 238870 | H10: =N($D10)*N(F10) -> 14219 | I10: =SUM(G10:H10) -> 253089
G11: =N($D11)*N(E11) -> 0 | H11: =N($D11)*N(F11) -> 0 | I11: =SUM(G11:H11) -> 0
A12: =+A10+1 -> 2 | B12: Supply Installation Testing and Commissioning of Modbus / BACnet over IP protocol for integrating FA panel with necessary hardware and accessories. | C12: Set | D12: 1 | E12: 148110 | F12: 9479 | G12: =N($D12)*N(E12) -> 148110 | H12: =N($D12)*N(F12) -> 9479 | I12: =SUM(G12:H12) -> 157589
G13: =N($D13)*N(E13) -> 0 | H13: =N($D13)*N(F13) -> 0 | I13: =SUM(G13:H13) -> 0
A14: =+A12+1 -> 3 | B14: Supply Installation Testing and Commissioning of Fire Graphic Software with real time fire system status and system control options. They all interface directly with the system network Gateway. System to be compatible for BMS System. | C14: Set | D14: 0 | G14: =N($D14)*N(E14) -> 0 | H14: =N($D14)*N(F14) -> 0 | I14: =SUM(G14:H14) -> 0
G15: =N($D15)*N(E15) -> 0 | H15: =N($D15)*N(F15) -> 0 | I15: =SUM(G15:H15) -> 0
A16: =+A14+1 -> 4 | B16: Supply Installation Testing and Commissioning of PC with the following configuration. • 8 GB of RAM • SATA hard disk drive • 1TBGB Storage • I7 3GHz Processor • XGA or higher video card PCI-Express, with OpenGL (v4.0 or above) hardware acceleration support, minimum 512 MB RAM • 1280 x 1024 pixel resolution and 65K colors • 10/100/1000 Ethernet Network Interface Card • Windows 10/11 Professional Licensed OS (64-bit) • 21'' Flat Screen Monitor • USB 3.0 • Gigabit TCP/IP Port with 100/1000Mbps network card with antivirus software, MS software with a sound card, mouse, keypad, etc. | C16: Set | D16: RO | G16: =N($D16)*N(E16) -> 0 | H16: =N($D16)*N(F16) -> 0 | I16: =SUM(G16:H16) -> 0
G17: =N($D17)*N(E17) -> 0 | H17: =N($D17)*N(F17) -> 0 | I17: =SUM(G17:H17) -> 0
A18: =+A16+1 -> 5 | B18: Supply Installation Testing and Commissioning of Intelligent Addressable Photoelectric smoke detector with a standard base and junction box. The optical sensor element shall have a sensitivity range of 0.53 to 3.94 %/ft. (1.7 to 12.35 %/m) obscuration, air velocity range from 0 to 4,000 ft./min (0 to 20 m/s), operating temperature range from -20°C to 60°C, and the operating environment from 0 to 49°C, 0 to 93% RH, Non-Condensing. | G18: =N($D18)*N(E18) -> 0 | H18: =N($D18)*N(F18) -> 0 | I18: =SUM(G18:H18) -> 0
A19: a | B19: Above Ceiling Detectors | C19: Nos. | D19: 62 | E19: 3039 | F19: 286 | G19: =N($D19)*N(E19) -> 188418 | H19: =N($D19)*N(F19) -> 17732 | I19: =SUM(G19:H19) -> 206150
A20: b | B20: Below Ceiling Detectors | C20: Nos. | D20: 38 | E20: 2812 | F20: 286 | G20: =N($D20)*N(E20) -> 106856 | H20: =N($D20)*N(F20) -> 10868 | I20: =SUM(G20:H20) -> 117724
A21: =+A18+1 -> 6 | B21: Supply Installation Testing and Commissioning of Intelligent Addressable Multi-Sensor (Optical Smoke + Heat) detector with a standard base and junction box. The optical sensor element shall have multiple selectable sensitivity levels from 0.2% Obs/ft to 3.7% Obs/ft. The ROR detection element shall have a selectable rate of rising setting of 8°C per minute and 11°C per minute (or close to this value not deviating more than 1°C). The fixed temp detection element shall have two selectable settings of 57°C and 68°C (or closer to this value not deviating by 1°C). Multi-sensor detectors shall have a configuration mode that gives separate alarms for smoke detection and heat detection and shall indicate the cause of the alarm (smoke or heat). Also, the multi-sensor shall have a combined configuration mode of smoke and heat detection that gives only one evaluated alarm from a multi-sensor detector in case of a fire event. The detector shall have an operating temperature range from -9°C to 50°C and a humidity tolerance range of up to 95% RH, Non-Condensing. | G21: =N($D21)*N(E21) -> 0 | H21: =N($D21)*N(F21) -> 0 | I21: =SUM(G21:H21) -> 0
A22: a | B22: Above Ceiling Detectors | C22: Nos. | D22: 5 | E22: 3215 | F22: 286 | G22: =N($D22)*N(E22) -> 16075 | H22: =N($D22)*N(F22) -> 1430 | I22: =SUM(G22:H22) -> 17505
A23: b | B23: Below Ceiling Detectors | C23: Nos. | D23: 5 | E23: 2987 | F23: 286 | G23: =N($D23)*N(E23) -> 14935 | H23: =N($D23)*N(F23) -> 1430 | I23: =SUM(G23:H23) -> 16365
A24: c | B24: False Floor Detectors | C24: Nos. | D24: 0 | G24: =N($D24)*N(E24) -> 0 | H24: =N($D24)*N(F24) -> 0 | I24: =SUM(G24:H24) -> 0
G25: =N($D25)*N(E25) -> 0 | H25: =N($D25)*N(F25) -> 0 | I25: =SUM(G25:H25) -> 0
A26: =+A21+1 -> 7 | B26: Supply Installation Testing and Commissioning of Intelligent Addressable Rate of Rising cum Fixed Temperature Heat Detector along with base and junction box. Rate-of-Rise temperature detection element shall have two selectable settings of 8° C and 11° C (or closer to this value not deviating by 1°C) and Fixed temperature sensing shall be independent of rate-of-rise sensing and shall have two selectable settings of 57° C and 68°C (or closer to this value not deviating by 1°C). The detector shall have an operating temperature range from 0°C to 50°C and a humidity tolerance range of up to 95% RH, Non-Condensing. | C26: Nos. | D26: 2 | E26: 3039 | F26: 286 | G26: =N($D26)*N(E26) -> 6078 | H26: =N($D26)*N(F26) -> 572 | I26: =SUM(G26:H26) -> 6650
G27: =N($D27)*N(E27) -> 0 | H27: =N($D27)*N(F27) -> 0 | I27: =SUM(G27:H27) -> 0
A28: =+A26+1 -> 8 | B28: Supply Installation Testing and Commissioning of Analogue Addressable Duct sensor detector with local housing and necessary hardware and accessories. | C28: Nos. | D28: 1 | E28: 10219 | F28: 286 | G28: =N($D28)*N(E28) -> 10219 | H28: =N($D28)*N(F28) -> 286 | I28: =SUM(G28:H28) -> 10505
G29: =N($D29)*N(E29) -> 0 | H29: =N($D29)*N(F29) -> 0 | I29: =SUM(G29:H29) -> 0
A30: =+A28+1 -> 9 | B30: Supply Installation Testing and Commissioning of Response indicator for all detectors located above false ceiling and below false flooring. | C30: Nos. | D30: 55 | E30: 106 | F30: 96 | G30: =N($D30)*N(E30) -> 5830 | H30: =N($D30)*N(F30) -> 5280 | I30: =SUM(G30:H30) -> 11110
G31: =N($D31)*N(E31) -> 0 | H31: =N($D31)*N(F31) -> 0 | I31: =SUM(G31:H31) -> 0
A32: =+A30+1 -> 10 | B32: Supply and Installation of Addressable Single action Manual call point as per OEM (Push/Breakglass/Pull Station) with necessary hardware and accessories. | C32: Nos. | D32: 3 | E32: 3585 | F32: 286 | G32: =N($D32)*N(E32) -> 10755 | H32: =N($D32)*N(F32) -> 858 | I32: =SUM(G32:H32) -> 11613
G33: =N($D33)*N(E33) -> 0 | H33: =N($D33)*N(F33) -> 0 | I33: =SUM(G33:H33) -> 0
A34: =+A32+1 -> 11 | B34: Supply Installation Testing and Commissioning of addressable type Horn / Strobe rated at 82 dBA @ 3m for Audible annunciation and 75cd flashing at 1 Hz for visual indication. | C34: Nos. | D34: =3+2 -> 5 | E34: 5495 | F34: 286 | G34: =N($D34)*N(E34) -> 27475 | H34: =N($D34)*N(F34) -> 1430 | I34: =SUM(G34:H34) -> 28905
G35: =N($D35)*N(E35) -> 0 | H35: =N($D35)*N(F35) -> 0 | I35: =SUM(G35:H35) -> 0
A36: =+A34+1 -> 12 | B36: Supply Installation Testing and Commissioning of addressable fault isolator module for isolating shorted dewired and lose circuits between two successive fault isolators with automatic resetting arrangement to protect the loop from short circuits, the rate shall include GI back box and Cu gland. | C36: Nos. | D36: 6 | E36: 2669 | F36: 286 | G36: =N($D36)*N(E36) -> 16014 | H36: =N($D36)*N(F36) -> 1716 | I36: =SUM(G36:H36) -> 17730
G37: =N($D37)*N(E37) -> 0 | H37: =N($D37)*N(F37) -> 0 | I37: =SUM(G37:H37) -> 0
A38: =+A36+1 -> 13 | B38: Supply Installation Testing and Commissioning of Addressable Control Relay modules for Monitoring/controlling Input or Output. | G38: =N($D38)*N(E38) -> 0 | H38: =N($D38)*N(F38) -> 0 | I38: =SUM(G38:H38) -> 0
B39: - Access control System | G39: =N($D39)*N(E39) -> 0 | H39: =N($D39)*N(F39) -> 0 | I39: =SUM(G39:H39) -> 0
B40: - Integration with Builder fire alarm system | G40: =N($D40)*N(E40) -> 0 | H40: =N($D40)*N(F40) -> 0 | I40: =SUM(G40:H40) -> 0
...

Sheet ACS & CCTV 
A1: PROJECT | B1: LIFE SAFETY SYSTEM BOQ SUMMARY
A2: SUBJECT | B2: ACCESS CONTROL & CCTV SYSTEM
A3: DATE | B3: 46113
A4: VERSION | B4: V0
A5: Sl.No. | B5: DESCRIPTION | D5: UNIT | E5: QNT | F5: RATE | H5: AMOUNT | K5: Remarks
F6: Supply | G6: Installation | H6: Supply | I6: Installation | J6: Total
B7: PART-B
A8: I | B8: ACCESS CONTROL | C8: Make / Model
A10: 1 | B10: Supply, Installation, Testing & Commissioning of 4 Door & 4 reader Controller (Oryggi 4 door 4 reader controller with encloser & PSU) Intelligent Controller capable of entry & exit control & battery backup to power the controller, EM Locks, Readers, etc. build-in ethernet connection, 32M memory on broad with 300,000 cards capability, 50,000 Log Capacity with TCP IP connectivity. Encloser box for controller Oryggi Controller with Licens | D10: Nos | E10: 3 | F10: 41400 | G10: 1500 | H10: =N($E10)*N(F10) -> 124200 | I10: =N($E10)*N(G10) -> 4500 | J10: =SUM(H10:I10) -> 128700
A11: 1 | B11: Supply, Installation, Testing & Commissioning of 2 Door Intelligent Controller capable of entry & exit control & battery backup to power the controller, EM Locks, Readers, etc. build-in ethernet connection, 32M memory on broad with 300,000 cards capability, 50,000 Log Capacity with TCP IP connectivity. | D11: Nos | E11: 0 | H11: =N($E11)*N(F11) -> 0 | I11: =N($E11)*N(G11) -> 0 | J11: =SUM(H11:I11) -> 0
H12: =N($E12)*N(F12) -> 0 | I12: =N($E12)*N(G12) -> 0 | J12: =SUM(H12:I12) -> 0
A13: 3 | B13: Supply, Installation, Testing & Commissioning of Multi-technology Card Readers as per specification | H13: =N($E13)*N(F13) -> 0 | I13: =N($E13)*N(G13) -> 0 | J13: =SUM(H13:I13) -> 0
B14: The readers shall have the following features:- a) Water resistance, high security, and high durability. b) Mounted directly on metal without affecting performance. c) Suitable for the Wiegand interface. d) Low power consumption. e) Audiovisual indication. f) Internal self-test routine checks and verifies setup configuration. g) Card read time less than .1 sec. h) I Class Smart Card reader (Acs card reader smart I SPR 501) i) Suprema Biometric reader for server room( BIO ENTRY P2) | D14: Nos | E14: 7 | F14: 37375 | G14: 1500 | H14: =N($E14)*N(F14) -> 261625 | I14: =N($E14)*N(G14) -> 10500 | J14: =SUM(H14:I14) -> 272125
H15: =N($E15)*N(F15) -> 0 | I15: =N($E15)*N(G15) -> 0 | J15: =SUM(H15:I15) -> 0
A16: 4 | B16: Supply Installation Testing and Commissioning of Pinpad + Reader with necessary hardware & accessories. | D16: Nos | E16: 1 | F16: 37375 | G16: 1500 | H16: =N($E16)*N(F16) -> 37375 | I16: =N($E16)*N(G16) -> 1500 | J16: =SUM(H16:I16) -> 38875
H17: =N($E17)*N(F17) -> 0 | I17: =N($E17)*N(G17) -> 0 | J17: =SUM(H17:I17) -> 0
