Workbook
Name \0: #REF!
Name \1: #REF!
Name \a: #REF!
Name \aq: #REF!
Name \b: #REF!
Name \C: #REF!
Name \c1: #REF!
Name \d: #REF!
Name \e: #REF!
Name \f: #REF!
Name \g: #REF!
Name \h: #REF!
Name \i: #REF!
Name \j: #REF!
Name \k: #REF!
Name \kl: #REF!
Name \l: #REF!
Name \m: #REF!
Name \n: #REF!
Name \o: #REF!
Name \P: #REF!
Name \P: #REF!
Name \Q: #REF!
Name \R: #REF!
Name \S: #REF!
Name \U: #REF!
Name \V: #REF!
Name \W: #REF!
Name \x: #REF!
Name \y: #REF!
Name \z: #REF!
Name _: #REF!
Name _???_PriceList2001?2002????_: #REF!
Name _???_PriceList2001?2002???_: #REF!
Name _???_PriceList2002?2001????_: #REF!
Name _???_PriceList2002?2001???_: #REF!
Name __???_PriceList2001?2002????_: #REF!
Name __???_PriceList2001?2002???_: #REF!
Name __???_PriceList2002?2001????_: #REF!
Name __???_PriceList2002?2001???_: #REF!
Name ________: #REF!
Name ___________: #REF!
Name ____________: #REF!
Name ____________________________________________________________________can430: 40.73
Name ____________________________________________________________________can435: 43.3
Name ___________________________________________________________________can430: 40.73
Name ___________________________________________________________________can435: 43.3
Name __________________________________________________________________b111121: #REF!
Name __________________________________________________________________can430: 40.73
Name __________________________________________________________________can435: 43.3
Name __________________________________________________________________Ki1: #REF!
Name __________________________________________________________________Ki2: #REF!
Name __________________________________________________________________MAN1: #REF!
Name __________________________________________________________________PB1: #REF!
Name __________________________________________________________________TB2: #REF!
Name _________________________________________________________________b111121: #REF!
Name _________________________________________________________________bla1: #REF!
Name _________________________________________________________________can430: 40.73
Name _________________________________________________________________can435: 43.3
Name _________________________________________________________________cur1: #REF!

Sheet SUMMARY 
A1: QUOTE SUMMARY
A2: TOTAL AREA (SQ.FT.) | C2: 15000
A3: USD RATE ( AVERAGE) | C3: 90
A4: Master Summary
A6: S.NO. | B6: Description | C6: Revised Amount (In INR)
A8: 1 | B8: C&I | C8: =+'C&I-BOQ '!H251 -> 0
A9: 2 | B9: System Furniture | C9: =+'SYSTEM FURNITURE'!G38 -> 0
A10: 3 | B10: Chair | C10: =+CHAIRS!G26 -> 0
A11: 4 | B11: Carpet | C11: =+'CARPET '!G60 -> 0
A12: 5 | B12: Loose furniture | C12: =+'LOOSE FURNITURE'!F42 -> 0
A13: 6 | B13: Broughtout Items | C13: =+'BROUGHTOUT ITEMS'!G58 -> 0
A14: 7 | B14: Cafe Plumbing work | C14: =+'CAFE PLUMBING WORK'!H46 -> 0
A15: 8 | B15: Electrical Work, Lighting | C15: =+Electrical!F314 -> 0
A16: 9 | B16: HVAC Work | C16: =+HVAC!C6 -> 0
A17: 10 | B17: NETWORKING - Passive | C17: =+Passive!I28 -> 0
A18: 11 | B18: FAS | C18: =+FAS!I25 -> 0
A19: 12 | B19: PAS | C19: =+PAS!I16 -> 0
A20: 13 | B20: Fire exinguishers | C20: =+'Fire Extinguisher'!H9 -> 0
A21: 14 | B21: CCTV | C21: =+CCTV!I17 -> 0
A22: 15 | B22: ACS | C22: =+ACS!I19 -> 0
A23: 16 | B23: Fire Sprinkler | C23: =+'Fire Sprinkler'!I23 -> 0
A24: 17 | B24: Toilet | C24: =+Toilet!F150 -> 0
B26: GRAND TOTAL (Excluding taxes) | C26: =SUM(C8:C25) -> 0
B29: EXCLUSION LIST: -
A30: 1 | B30: ABOVE SUB TOTAL COST IS EXCLUDING TAXES,
A31: 2 | B31: NETWORKING - ACTIVE PART COMPONENTS.
A32: 3 | B32: WHITE GOODS / /SHREDDERS / COMPACTORS/SAFES
A33: 4 | B33: ANY LIASONING ( MUNICIPAL CORPORATION / CFO)
A34: 5 | B34: ELECT. METER
A35: 6 | B35: SHAFT DOOR ( ANY SHUTTERS / DOOR AS ACCESS TO THE SHAFT )
A36: 7 | B36: STAIRCASE & STAIRCASE FIRE EXIT DOORS
A37: 8 | B37: ANY REPAIRS TO EXTERNAL GLAZING .
A38: 9 | B38: AIR CURTAIN
A39: 10 | B39: BUSBAR
A40: 11 | B40: HVAC - HIGH SIDE WORK AND AHU SUPPLY & INSTALLATION, AHU ROOM ACCOSTIC AND PLENUM WORK, STARTER PANEL, VFD SYSTEM.
A41: 12 | B41: UPS
... A46: 17 | B46: TOILET WATERPROOFING
B48: Note:
A49: 1 | B49: Owner/client to provide free of cost electricity/water/security during the due course of site execution works.
A50: 2 | B50: The working shift will be of 12 hours or as required basis of project time lines.
...

Sheet MAKE LIST
A1: LIST OF APPROVED MAKES FOR C&I WORK
A3: Sr. No. | B3: PRODUCT CATEGORIES | C3: APPROVED MAKE/BRAND
A4: 1 | B4: ADHESIVES FOR CARPENTARY WORKS
B5: Rubber based / Glue / Epoxy based adhesives | C5: Fevicol
A6: 2 | B6: ANCHORS & FASTENERS
B7: Mechanical / Chemical Anchors | C7: Hilti
B8: Screws | C8: GSK Or Netfold
A9: 3 | B9: CEILING / PARTITION
B10: Gypsum ceiling systems | C10: Gypsum India / USG Boral
B11: Gypsum Partition systems | C11: Gyproc Gypsum Board
B12: Fire retardant Partition systems | C12: Gyproc Gypsum Board
B13: Grid ceiling system | C13: 0.9NRC/0.7/ 0.5 NRC USG Boral
B14: Axiom Trim | C14: USG Boral
B15: Metal Plain Ceiling | C15: Techno ceiling
B16: Metal Perforated Ceiling | C16: Techno ceiling
B17: Sliding Folding partition systems | C17: OZONE / Doyal Asia
B18: Acoustic Baffle / Screen | C18: Techno ceiling/ Armstrong
A19: 4 | B19: BUILDING MATERIAL
B20: Gypsum Plaster | C20: Gyprock Elite
B21: Construction Blocks | C21: Siporex
B22: Ordinary Portland Cement | C22: ACC/Ultratech
B23: White Cement | C23: JK White
B24: Water Proofing | C24: PIDILITE
B25: Concealed Wall Angle guards | C25: USG Boral
A26: 5 | B26: CEILING/PARTITION ACCESSORIES & COMPONENTS
B27: Jointing Compound for Gypsum Partitions | C27: USG Boral
B28: Paper tapes for Gypsum Partitions | C28: USG Boral
B29: Dry wall top coat for Gypsum Partitions | C29: USG Boral
B30: G.I. Frames & Accessories for modular/false ceilings | C30: USG Boral
B31: Insulation | C31: Rock wool India
B32: Aluminium | C32: Jindal
A33: 6 | B33: FLOORINGS
B34: Entrance Mat/Anti Skid Strip | C34: 3M
B35: Vitrified Tile | C35: NITCO/SOMANY/Kajaria
B36: Marble | C36: Natural Stone
B37: Granite | C37: Natural Stone
B38: Vinyl floors | C38: NFL / LG/Amstrong
B39: Antistatic Vinyl floors | C39: NFL / LG/Amstrong
B40: Cavity floor systems | C40: Unitile / AET
B41: Self levelling Cementitious floors | C41: Ardex /
...

Sheet C&I-BOQ 
A1: C&I - BOQ
A2: SL.NO. | B2: ITEM | C2: DESCRIPTION | D2: Location | E2: Qty | F2: UNIT | G2: RATE | H2: AMOUNT | I2: Remark
A3: A | B3: Civil Works
A5: 1 | B5: DEMOLITION WORKS | C5: Dismantling and removal of existing partitions( gypsum or glass ), ceiling, flooring, wall finishes, furniture, and MEP items. Including protection of base structure, debris disposal, and handing over the site in clean bare shell condition ready for fit-out. | D5: Complete office | E5: 10750 | F5: Sqft | H5: =+$E5*G5 -> 0
A8: a | B8: REMOVAL OF DEBRIS | C8: All the items in Dismantling / Demolishing shall be cartig away the debris from the site and unloading at a approved location as per statutory rules and regulations.Care shall be taken not to damage other property while carrying dismantling and demolition otherwise cost of damage will be bourne by the contractor.All the safty precautions shall be taken while doing dismantling and demolition job. | D8: Complete office area | E8: 120 | F8: TRIP | H8: =+$E8*G8 -> 0
A10: 2 | B10: MASONRY & CIVIL WORKS
A12: a | B12: SIPHOREX BLOCK WALL CONSTRUCTION | C12: Providing and constructing 4/6/8 inch thick walls of siphorex block in cement mortar of ratio 1:4 and laying of rcc lintel after every 1.5 meter height in 1:2:4 concrete ratio (1unit-cement: 3unit- sand, 6unit- course aggregate); with 2no. Of 6mm diameter mild steel reinforcement & 2 no. Of hoop iron strips 25mm x 1.6mm, painted with anti-corrosive paint ,properly bent and bonded at the end ,inclusive of shuttering, scaffolding, hacking and proper curing etc complete. | D12: Front of Bain Marie, Hand wash & Dish wash Area
A13: i | B13: 6" THK | C13: Specs Same As above line Item a | E13: 819 | F13: Sqft | H13: =+$E13*G13 -> 0
A15: b | B15: CURVED SIPHOREX BLOCK WALL CONSTRUCTION - 6" THK | C15: Providing and constructing 6 inch thick walls of siphorex block in cement mortar of ratio 1:4 and laying of rcc lintel after every 1.5 meter height in 1:2:4 concrete ratio (1unit-cement: 3unit- sand, 6unit- course aggregate); with 2no. Of 6mm diameter mild steel reinforcement & 2 no. Of hoop iron strips 25mm x 1.6mm, painted with anti-corrosive paint ,properly bent and bonded at the end ,inclusive of shuttering, scaffolding, hacking and proper curing etc complete. | F15: Sqft | H15: =+$E15*G15 -> 0
A17: c | B17: LINTEL WORKS | C17: Providing and laying Lintel (4"/6"/8" x 8") (1:1-1/2:3) inclusive of all centering , shuttering , reinforcement and finishing work with complete required material to proper completion of work and to entire satisfaction of Architect. 4"/6"/8" thick | D17: Above door opening
A18: i | B18: 6" THK | C18: Specs Same As above line Item b | E18: 24 | F18: Rft | H18: =+$E18*G18 -> 0
A20: d | B20: PLASTERING | C20: Providing and applying in one coat, 12mm thick plaster on internal surface of RCC / brick/block walls in cement mortar 1:4, finished rough to take on POP punning. Rate shall include for scaffolding, making grooves, sills, pattas curing, surface preparation before the application of plaster, providing galvanized chicken mesh to a width of 150 mm at the junctions of masonry and concrete works including tying in position by using suitable nails / clamps / screws and as directed etc. complete at all levels. The contractor shall make good the grooves, pockets etc. after the scaffolding is removed. (Rate including chicken mesh jali.) | D20: New brick work area | E20: 1638 | F20: Sqft | H20: =+$E20*G20 -> 0
A22: e | B22: PCC FLOORING | C22: Providing & laying plain cement concrete 1:3:6 nominal mix (1 cement :3 coarse sand : 6 graded stone aggregate 25 mm nominal size) of approved quality with all lead & lift below/above the ground level as per drawing including the cost of cement, levelling of surface of concrete with al lead and lift, labour, material as per specifications and directed by Architect up to thickness of 75-100mm. | D22: Complete office area | E22: 11250 | F22: Sqft | H22: =+$E22*G22 -> 0
A24: f | B24: TRENCHING | C24: Trench cutting and Re-filling upto finish levelas required -REMOVING & FILLING OF EXISTING TRENCHES using base of compacted sand filling surfaced with 4" top P.C.C. surfacing ( as per instructions) including levelling & finishing the surface ready for receiving the new floor finish( 1 FEET WIDTH ) | D24: Complete office area | E24: 1850 | F24: Rft | H24: =+$E24*G24 -> 0
A26: g | B26: POP PUNNING | C26: Punning with POP 12mm thick layer of super fine plaster of paris applied over selected existing plastered surface on walls and columns finished smooth, surface prepared by hacking and applying a coat of cement slurry (Rate including Bondit chemical for surface) etc. complete | D26: Over existing walls & Columns were required | E26: 4576 | F26: Sqft | H26: =+$E26*G26 -> 0
A28: A | C28: Total Civil Works | H28: =SUM(H5:H27) -> 0
A30: B | B30: COUNTERS
A31: 1 | B31: PANTRY COUNTER | C31: Providing & fixing Under counter storages for pantry & basin as per drawing . The overall Structure made in 19mm thick BWP ply and approved colour Granite slab on top. Storages finished in 1 mm thick laminate from everywhere except outer back side of storages and also including all SS snap hinges, handles, locks, drawers with smoth closing chanels etc & all necessary hardware as required. PVC lipping on all edges with matching shade, including laminated skirting in approved shade with all hardware, magnetic catchers, tower bolts, etc complete as per detailed drawings. Rate excluding Granite stone work | D31: Pantry Area | E31: 62 | F31: Sqft | H31: =+$E31*G31 -> 0
A33: 1.1 | B33: WASH BASIN COUNTER | C33: Providing & fixing Counter ( 600deepx150-300 facia drop) with appropriate MS framework of counter top finished with BWP ply 19mm thk, including making holes for sink and dust bin including edge polishing around basin and edge moulding as per Drawing and approved sample of moulding. Counter made to recieve stone top/ facia (exclude stone finish / Corian Finish from the cost) | D33: Hand wash Area | E33: 109 | F33: Sqft | H33: =+$E33*G33 -> 0
C35: Counter Top
A36: a | C36: Granite in telephone black / Jet black | D36: Pantry & Wash Basin | E36: 193 | F36: Sqft | H36: =+$E36*G36 -> 0
A38: B | C38: Total for COUNTER Works | H38: =SUM(H31:H37) -> 0
A40: C | B40: FLOORING WORK
A42: 1 | B42: VITRIFIED FLOORING ( 4FT X 2FT) | C42: Providing and Laying Vitrified tiles (1200x600x10mm thk) flooring. Flooring to be laid in cement mortar 1:6 over a cement mortar bedding of avg. thickness upto 25mm as required to level and slopes required, rate included latecrete chemical. The flooring to be done as per design and pattern shown on the drawings inclusive of all joints to be grouted with matching color grout of BAL adhesive or equivalent.All work sites are required to be maintained in a debris-free condition and the Employers/Architects reserve the right to maintain the same, as so required, at the sole risk/cost of the concerned agency. cost to include covering entire flooring with good quality plastic / POP for as many time as required for protection of laid material above and removal before final cleaning handover. Basic Rate - 150/sqft | F42: Sqft | H42: =+$E42*G42 -> 0
A44: 2 | B44: Anti-Skid Handmade Tiles | C44: Providing and laying anti-skid handmade tiles of approved size, color, pattern, and thickness, having natural textured finish for slip resistance and slight variation in tone for a rustic appearance. Tiles to be laid on cement mortar bed of 35–45 mm thickness in 1:6 (cement:sand) ratio, with joints filled using matching grout. Surface to be properly leveled, aligned, and free from lippage. Including curing, cleaning, and all materials, labour, and tools required for complete installation as per approved samples and drawings.. cost to include covering entire flooring with good quality plastic / POP for as many time as required for protection of laid material above and removal before final cleaning handover. Basic Rate - 250/sqft | D44: Caféteria, Store, Hand wash & Dish Wash Area | E44: 5160 | F44: Sqft | H44: =+$E44*G44 -> 0
A46: 3 | B46: Decorative Handmade Tiles | C46: Providing and laying decorative handmade tiles of approved size, color, pattern, and thickness, having natural textured finish for slip resistance and slight variation in tone for a rustic appearance. Tiles to be laid on cement mortar bed of 35–45 mm thickness in 1:6 (cement:sand) ratio, with joints filled using matching grout. Surface to be properly leveled, aligned, and free from lippage. Including curing, cleaning, and all materials, labour, and tools required for complete installation as per approved samples and drawings.. cost to include covering entire flooring with good quality plastic / POP for as many time as required for protection of laid material above and removal before final cleaning handover. Basic Rate - 325/sqft | D46: High Seating Area, Bain Marie area & Pantry Area | E46: 3235 | F46: Sqft | H46: =+$E46*G46 -> 0
A48: 4 | B48: PLYWOOD RAISED FLOORING (150mm) | C48: Providing and Fixing PLYWOOD RAISED FLOORING (150MM) made out of MS section 50x50mm - Framework covered with 25mm thk block board finished with approved laminated wooden flooring as shown in details. Quoted rate includes all hardware, MS framing,block board, Laminated wooden flooring,adhesive,corner profile,skirting, covering with bubble sheet till handing over. etc. Mode of measurements; actual plan area to be measured & paid in this item,no additional cost payable for verticals - Finishwith 1mm thk laminate | D48: Misc. | E48: 860 | F48: Sqft | H48: =+$E48*G48 -> 0
A50: 5 | B50: LAMINATED WOODEN FLOORING | C50: Providing and fixing Laminated wooden flooring 10mm thk with underlay plastic and 4mm foam sheet laying. | D50: Café | E50: 618 | F50: Sqft | H50: =+$E50*G50 -> 0
A52: 6 | B52: ANTISTATIC FALSE FLOORING | C52: Providing & fixing stringer based raised access floor of approved make metal cladded system finished in Anti-Static laminate of approved shade consisting of : Panel Construction: Panels of size 600 mm X 600 mm are manufactured from pressed form corrosion resistant galvanized steel. The above hollow panel shall have an infill of light weight cementatious material. The entire panel shall be coated with epoxy coating on the exposed surface. Pedestal construction shall be all steel construction, zinc plated and consisting of anti vibration head cap with cruciform up stands and four panel locating studs, positively clipped to the steel top plate . Pedestal shall be screwed to floor. Uniformly distributed load shall be 12 kN/m2 Concentrate point load : 4.0 kN over 25 sqmm. Floor void should be 300 mm minimum from underside of raised floor pan to finish slab. Provision should made for satisfactory earthing for all floor tiles. ( Height-300mm) | D52: Hub Room | E52: 150 | F52: Sqft | H52: =+$E52*G52 -> 0
A54: 7 | B54: TRANSITION PROFILE | C54: Fabricating and fixing of SS transition profile at the junction of hard/soft flooring as per Architect's approval and design - Bottomline make | D54: Joint of hard and carpet flooring | E54: 55 | F54: RFt | H54: =+$E54*G54 -> 0
A56: 8 | B56: SKIRTING & DADO
A57: a | B57: ALUMINUM SKIRTING | C57: Providing and fixing Aluminum skirting of 50 mm of approved make with rubber beading fixed on screwing slot on partitions and walls etc. all complete as per architects instructions. There shall be 12 mm thk commercial Ply backing as approved by the architect. The rate to be inclusive of all accessories required for fixing of skirting complete. | D57: Complete office area | E57: 2110 | F57: Rft | H57: =+$E57*G57 -> 0
A59: b | B59: VITRIFIED TILE DADO CLADDING | C59: Providing and laying in position as per approved sample porcelain /ceramic /vitreous tiles (without warpage of approved make, shade, shape and colour) of size 600x300mm on walls laid on 12 mm thick cement mortar 1:3 ( 1 cement : 3 course sand ) the rate shall be inclusive of necessary preparation, 2mm spacer groove matching with floor tiles , cleaning, grouting open joints with epoxy grouts bal grout etc. complete as per drawing and Designer Instruction. | D59: Pantry, Hand Wash, Dish Wash | E59: 720 | F59: Sqft | H59: =+$E59*G59 -> 0
A61: c | B61: VIRTICAL MOSIAC TILE CLADDING | C61: Providing and fixing Kit Kat (finger mosaic) tiles of approved make, factory-mounted on mesh sheets of size 300×300 mm (or equivalent), comprising strips approx. 20×145 mm, thickness 6–9 mm, in required color, shade and finish, fixed with suitable tile adhesive, including cutting, grouting, finishing, and all complete. | D61: Café Columns | E61: 394 | F61: Sqft | H61: =+$E61*G61 -> 0
A63: d | B63: ALUMINIUM SECTIONS U/H/L/T/Flat PROFILE | C63: Supply & Installation of approved size & shape of aluminium transition section in black colour at the top & bottom of the Writing board & Fabric paneling as per the detail drawings complete and approval of Designer/PM (Sizes varies from 6mm to 50mm) | D63: complete office area | E63: 1540 | F63: Rft | H63: =+$E63*G63 -> 0
A65: C | C65: Total Flooring Works | H65: =SUM(H41:H64) -> 0
A67: D | B67: CEILING WORKS
A68: 1 | B68: GYPSUM CEILING | C68: Providing and fixing in position multi level GYPSUM board false-ceiling suspended on G.I. frame work in design as shown in the drawing. The G.I. frame work consist of Perimeter channel of size 27mm x 0.5mm. Intermediate channel of size 45mm x 0.5mm thick. Ceiling section of 0.5mm thickness. 12.5mm thick tapered edge gypsum plaster board fixed to ceiling channel with 25mm dry wall screws at 230mm centers Jointed and finished with requisite filler, paper tape, finisher and primer suitable for Gypsum plaster boards. Rate to include making necessary cut-outs/openings for light fittings. This item includes all vertical drops, niches in ceiling etc. Gypsum board to be of Boral / India Gypsum. | D68: Café, Cabins, Conference Room & MD cabin | E68: 6062 | F68: Sqft | H68: =+$E68*G68 -> 0
A70: 2 | B70: COVE CEILING IN GYPSUM | C70: Providing and Fixing Gypsum board cove ceiling as per detail drawing and direction of the architects. With provision and cutouts for fixing light fittings, cable, conduits etc running internally, AC grill fixing etc. 100mm front facia and 200mm back facia Mode of measurements:- Running meter Length, No wastage to be added | D70: MD Cabin, All Cabins & Conference Room | E70: 435 | F70: Rft | H70: =+$E70*G70 -> 0
A72: 3 | B72: MODULAR FALSE CEILING (600MM X 600MM) 0.5 NRC | C72: Providing & Fixing of Mineral Fibre Acoustical Suspended Ceiling System with Bevelled Tegular Edge Tiles With 15mm Silhouette GRID. The tiles should have Humidity Resistance (RH) of 99%, Light Reflectance <85%, Thermal Conductivity k = 0.052 - 0.057 w/m K, Colour White, Fire Performance UK Class 0 / Class 1 (BS 476 pt - 6 &7) in module size as specified by the architects , suitable for Green Building application, with Recycled content of 63%. 0.5 NRC of Tile. The tile shall be laid on Silhouette profile grid system with 15mm white flanges incorporating a 6mm central reveal in white/black colour and with a web height of 45mm and a load carrying capacity of minimum 15.68 Kgs/M2 & pull out strength of 100Kgs. Silhouette, Main Runners & Cross Tees to have mitred ends & “birdsmouth” notches to provide mitred cruciform junctions. The T Sections have a Galvanizing of 90 grams per M2 and need to be installed with Proprietary Suspension system. The Tile & Grid system used together should carry a 10 year warranty. | D72: 5 pax, 4 pax, 8 pax, Store, Above Bain Marie, Hand Wash & Dish Wash | E72: 2363 | F72: Sqft | H72: =+$E72*G72 -> 0
...

Sheet SYSTEM FURNITURE
A1: SYSTEM FURNITURE - BOQ
A2: S.No. | B2: Item Name | C2: Description | D2: Unit | E2: TOTAL | F2: Rate | G2: Amount | H2: Remarks
A4: 1 | B4: LINEAR STAFF | C4: SIZE:- 1200X650X 750 | D4: Nos | E4: 24 | G4: =E4*F4 -> 0
B5: WORKSTATION | C5: TABLE TOP :- 25mm thick PLPB E1 board with 2mm thick PVCedge banding finish with as per approved laminate color.
C6: LEGS :- 4X040 /50X50 powder coated straight leg finish with as per approved shade. Powder coating (AkzoNobel 60-80 Microns) are connected to Legs with Brackets for table support. The open table base should be assembled from the main beams, and end legs.
C7: BEAM :- 40mm x 40mm CRC square pipe with powder coated finish as per
C8: approved shade provided with die casted brackets to support top.
C9: MAIN SCREEN (400HT) :- Fabric Pin-up supported on table top with brackets.RETURN SCREEN (400HT) :- 30 mm fabric screen supported on table top with brackets. PASSAGE SIDE - 30 mm SCREEN HANG PANEL
C10: FLAPPER :- Wire management would be accessed by aluminium fliptops having soft closure with 3D cutouts for wire accessibility on the countertop which are 450mm(W) x 150mm(D) to access all the face plates comfortably.
C11: WIRE CARRIER :- Powder coated wire carrier to be provided for arranging
C12: wires for electricity & data.
C13: RISER LEG :- Powder coated wire riser to be provided for raising wires form floor. CENTER MODESTY (450HT) :- 18mm thick PLPB board with 2mm thick PVCedge banding finish with as per approved laminate color. Haworth - Make
A15: 2 | B15: LINEAR HEIGHT ADJUSTABLE TABLE | C15: LINEAR HEIGHT ADJUSTABLE TABLE -3 STAGE HAT System: HEIGHT ADJUSTABLE TABLE SIZE 1500LX 750DX1200HT Specification : Haworth - Make Table top : 25mm thick Pre-laminate particle board E1 norms finished with with 2mm pvc edge banding with Reversewaterfall Edge Considered . Screen 400ht From FFL -30mm Al screen with Soft Board Tile considered . Retaurn Side -30mm Al Screen with fabric Tile considered . Under-structure : Supported on ms powder coated motorized Height adjustable understructure. Wiremanagement: 450mm flipup with 175ht cable dump & vertebra and ms cable tray with vertical wire entry cover for wire taken through floor level Specifications of Height Adjustment mechanism - 3 stage 1)Motor : Dual Motor 2)Programmable Memory : 4 Preset memory 3)Max load (Capacity) : 100 Kg 4)Push load : 1600N (2 x 800N) 5)Speed : 36mm/s 6)Power type : DC 7)Decibel(db) : <50dBDuty Cycle 8)Height Range : 650-1200mm 9)Anti-collision Feature | D15: Nos | E15: 21 | G15: =+E15*F15 -> 0
A17: 3 | B17: PRELAM PEDESTAL | C17: Prelam Pedestal BBF [E1 Grade] 2D+1F Pedestal @ 400x450x621mm HT. on Castors. Top,Carcass&Fasia : 18mm Prelam Partical Board With PVC Lipping. Handle : Side chamfer handle With top cousining | D17: Nos | E17: 45 | G17: =+E17*F17 -> 0
C19: MEETING TABLE
A21: 1 | B21: 12 PAX | C21: 4050X1500X750 | D21: Nos | E21: 1 | G21: =E21*F21 -> 0
C22: Table top: Corian finish top with 6mm thick Under-structure: Supported on One Side MS powdercoated Switch 40 x 40 Angular Leg with supporting beams. Wire management: 450 mm Aluminium flipup with soft closure and provision to mount switches and sockets on MS Cable Dump & Wire Entry Cover For Wire Uptaking FFL. Haworth - MAke
A23: 2 | B23: 8 PAX | C23: 2700X1200X750 mm ht | D23: Nos | E23: 1 | G23: =E23*F23 -> 0
C24: Table top: Corian finish top with 6mm thick Under-structure: Supported on One Side MS powdercoated Switch 40 x 40 Angular Leg with supporting beams. Wire management: 450 mm Aluminium flipup with soft closure and provision to mount switches and sockets on MS Cable Dump & Wire Entry Cover For Wire Uptaking FFL. Haworth - MAke
A25: 3 | B25: 5 PAX | C25: 1800X1200X750 mm ht | D25: Nos | E25: 1 | G25: =E25*F25 -> 0
C26: Table top: 25 mm thick Pre-laminate particle board E1 norms finished with 2mm pvc edge band Finish . Under-structure: Supported on One Side MS powdercoated Switch 40 x 40 Angular Leg with supporting beams. Wire management: 450 mm Aluminium flipup with soft closure and provision to mount switches and sockets on MS Cable Dump & Wire Entry Cover For Wire Uptaking FFL. Haworth - MAke
A27: 4 | B27: 4 PAX | C27: 1050mm Dia.X750 mm | D27: Nos | E27: 2 | G27: =E27*F27 -> 0
C28: Table top: 25 mm thick Pre-laminate particle board E1 norms finished with 2mm pvc edge band Finish . Under-structure: Supported on One Side MS powdercoated Switch 40 x 40 Angular Leg with supporting beams. Wire management: 450 mm Aluminium flipup with soft closure and provision to mount switches and sockets on MS Cable Dump & Wire Entry Cover For Wire Uptaking FFL. Haworth - MAke
A30: 5 | B30: CABINS TABLE | C30: CABIN TABLES WITH Side Table Cum Storage
C31: Main Table Size :- 1500L x 750D x 750H Side Storage Table Size :- 1500L x 300D x 750H Description: Table Top: 25mm thick Pre-laminate particle board finished with 2mm PVC Edge Banding. Under Structure: Supported on MS Powder Coated Enrich Legs and Supporting MS beams. Modesty Panel : Prelaminated (PLT) modesty panel of 450mm ht on Main and Ailse side of cabin table. Wire Management: 350mm Aluminium Flip Up and provision to mount swicthes and sockets on PVC cable dump and Vertical wire entry cover for wire uptake from floor to cable dump. Side Storage : (Openable Shutter) The structure is made out of 18mm thick pre-laminated boards (PLT). The shelves are made out of 18mm(PLT), which are adjustable in height. The shutters are made out of 18mm(PLT), and fitted by hinges. Finger groove handles, locking unit and levelers are considered. Haworth - MAke | D31: Nos | E31: 4 | G31: =+E31*F31 -> 0
A33: 6 | B33: MD CABINS TABLE | C33: CABIN TABLES WITH Side Table Cum Storage
C34: Main Table Size :- 2100L x 750D x 750H Side Storage Table Size :- 1500L x 300D x 750H Description: Table Top: Corian finish top with 6mm thick Under Structure: Supported on MS Powder Coated Enrich Legs and Supporting MS beams. Modesty Panel : Prelaminated (PLT) modesty panel of 450mm ht on Main and Ailse side of cabin table. Wire Management: 350mm Aluminium Flip Up and provision to mount swicthes and sockets on PVC cable dump and Vertical wire entry cover for wire uptake from floor to cable dump. Side Storage : (Openable Shutter) The structure is made out of 18mm thick pre-laminated boards (PLT). The shelves are made out of 18mm(PLT), which are adjustable in height. The shutters are made out of 18mm(PLT), and fitted by hinges. Finger groove handles, locking unit and levelers are considered. Haworth - MAke | D34: Nos | E34: 1 | G34: =+E34*F34 -> 0
A36: 7 | B36: Metal Lockers | C36: Supply and installation fo metal numeric locker of side 400*450*450 | D36: Nos | E36: 75 | G36: =+E36*F36 -> 0
C38: Total without Taxes | F38: Total | G38: =SUM(G3:G36) -> 0

Sheet CHAIRS
B1: CHAIRS - BOQ
A2: Sr.No. | B2: Description | C2: Location | D2: Qty. | E2: Unit | F2: Rate | G2: Amount
A3: B | B3: CHAIRS
A5: 1 | B5: WORK STATIONS CHAIRS
B6: Medium Back Mesh Chair * AN 70 Mesh * Self Calibrating Multilock Mechanism * Adjustable Lumbar Support * One Way Adjustable Arms (Height) * Nylon Base * Fabric Upholstered Cushion Seat | D6: =SUM(D7:D10) -> 58 | E6: Nos. | G6: =$D6*F6 -> 0
C7: Workstation Area | D7: 45
C8: 8 pax | D8: 8
C9: 5 pax | D9: 5
A11: 2 | B11: MD CABIN HEAD CHAIR
B12: * Leatherette • High Back Chair • Seat & Back Leatherette • Multilock with Knee tilt Mechanism • Aluminum Fixed Arms • Aluminum Base with 60mm castors. | C12: MD room | D12: 1 | E12: Nos. | G12: =$D12*F12 -> 0
A14: 3 | B14: MD CABIN VISITOR CHAIR
B15: *-LEATHERETTE * Seat & Back Artificial Leatherette ( Medium) * Multilock Synchro Mechanism * Chrome Base (Steel) with 60mm Castors. | C15: MD room visitor chair | D15: 3 | E15: Nos. | G15: =$D15*F15 -> 0
A17: 4 | B17: CABIN HEAD CHAIR
B18: * LEATHERETTE * Seat & Back Artificial Leatherette (High) * Multilock Synchro Mechanism * Chrome Base (Steel) with 60mm Castors. | D18: =SUM(D19) -> 4 | E18: Nos. | G18: =$D18*F18 -> 0
C19: Cabin Head Chair | D19: 4
A21: 4 | B21: CABIN VISITOR CHAIR
B22: * Fabric * Seat & Back Fabric ( Medium) * Multilock Synchro Mechanism * Chrome Base (Steel) with 60mm Castors. | D22: =SUM(D23:D24) -> 16 | E22: Nos. | G22: =$D22*F22 -> 0
C23: Cabin Visitor chair | D23: =2*4 -> 8
C24: 4 pax | D24: =2*4 -> 8
B26: TOTAL OF CHAIRS | G26: =SUM(G6:G25) -> 0

Sheet CARPET 
A3: Note:-
B4: * | D4: The quoted rates should be exclusive of GST & it would be extra as applicable.
B5: * | D5: The quoted rates should be F.O.R at site including all freight,packaging, installation etc.
B6: * | D6: It will be the vendors responsibility to hand-over the Carpet to clients/owner free of defects.
B7: * | D7: Any material found to be defective shall be replaced free of cost.
B8: * | D8: Vendor shall rectify all snags before handing over of the completed project.
B9: * | D9: Storing, safe guarding of the supplied material shall be the scope of the vendor till handing over.
B10: * | D10: Availability of material & timelines be confirmed along with submission of bids.
B11: * | D11: Before placing the final order, Quantities to be strictly rechecked with the latest approved layout from client/architect.
A12: CARPET - BILL OF QUANTITIES
A13: SL.NO | D13: DESCRIPTION
A14: I | D14: Carpet : ( Tiles)
D15: Providing, supplying & installing carpet in the specified areas as per patterns specifications as below :
A16: - | D16: Style | F16: Laser Cut , “ Free Form ” Carpet Tile
D17: Construction | F17: Multi Hi / Lo Loop
D18: Pile Fibre | F18: nexlon™ Premium Solution Dyed Nylon with Stain and Soil Resist Technology
D19: Tufted Machine Gauge | F19: 1/10 gauge
D20: Pile Height | F20: 5.0~3.0mm
D21: Total Thickness | F21: 8.9 mm max
D22: Tile size | F22: As per design and selection (450x450mm, 600x600mm, 800x800mm, 1000x1000mm, 1200x200mm)
D23: Total Weight | F23: 6250 gm/m2
D24: Wear Warranty | F24: Lifetime – product is warranted not to lose more than 10% pile fibre by weight in normal commercial use
D25: Colour Fastness | F25: 15 Year Warranty ASTM 16-04. Grade 4 – Little or no change
D26: Static Electricity | F26: Permanent Lifetime Protection – less than 2.0kv
D27: Stain Resistance | F27: nexlon™ Stain Shield Treatment
D28: Soil Resistance | F28: nexlon™ Soil Guard Treatment
... D31: Installation | F31: Pressure Sensitive Adhesive
A32: - | D32: Sustainability | F32: All yarns used are Solution dyed to minimise use of water and exclude any effluent production.
D33: ISO | F33: ISO 14001 and ISO 9001
D34: CRI Label | F34: CRI Green Label Plus Certified for Indoor Air Quality
D35: EPD | F35: Environmental Product Declaration (EPD) by UL
D36: v.HPD | F36: Health Product Declaration (HPD) Third Party verified by U.S. GreenCircle Certified
D37: Fire rating | F37: Fire Rating EN 13501 Cfl s1
A38: - | D38: Wear Rating | F38: Wear Rating EN1307 Class 33
D39: Auns
A40: 2 | D40: Adhesive system
D41: approved adhesive-VOC free
D42: Installation method
A43: - | D43: Direct stick method using water base approved adhesive applied to 100% of the backing surface
A44: - | D44: Completed carpet to be smooth and free of bubbles, puckers and other defects
...

Sheet LOOSE FURNITURE
A1: LOOSE FURNITURE
A3: S.No | B3: Description | C3: Qty. | D3: Unit | E3: Rate | F3: Total | G3: Remarks
A5: A | B5: DISCUSSION AREA & WORKSTATION AREA
A7: 1 | B7: Lounge Chairs | C7: 2 | D7: Nos | F7: =C7*E7 -> 0 | G7: As per Drawing
A8: 2 | B8: Center Coffee Round Tables - 1100mm Dia. | C8: 1 | D8: Nos | F8: =C8*E8 -> 0 | G8: As per Drawing
A9: 3 | B9: Puffys | C9: 12 | D9: Nos | F9: =C9*E9 -> 0 | G9: As per Drawing
A11: B | B11: WAITING LOUNGE AREA
A13: 1 | B13: Lounge Chairs | C13: 2 | D13: Nos | F13: =C13*E13 -> 0 | G13: As per Drawing
A14: 2 | B14: Center Coffee Round Tables - 550mm Dia. | C14: 2 | D14: Nos | F14: =C14*E14 -> 0 | G14: As per Drawing
A15: 3 | B15: Puffys | C15: 5 | D15: Nos | F15: =C15*E15 -> 0 | G15: As per Drawing
A17: C | B17: MD CABIN
A19: 1 | B19: Lounge Chairs | C19: 2 | D19: Nos | F19: =C19*E19 -> 0 | G19: As per Drawing
A20: 2 | B20: Center Coffee Round Tables - 550mm Dia. | C20: 2 | D20: Nos | F20: =C20*E20 -> 0 | G20: As per Drawing
A21: 3 | B21: Two Seater Sofa | C21: 1 | D21: Nos | F21: =C21*E21 -> 0 | G21: As per Drawing
A22: 4 | B22: Singler Seater Sofa | C22: 1 | D22: Nos | F22: =C22*E22 -> 0 | G22: As per Drawing
A24: C | B24: CAFETERIA & COLLAB AREA
A26: 1 | B26: TABLE TOP : Table top to be made of 25mm plywood finished with approved shade of laminate and edges to be finished with 2mm thick PVC edge banding matching to the laminate shade.
B27: UNDERSTRUCTURE : Legs to be made of 40mm x 40mm x 1.6mm MS tube finished with approved shade of powder coating.
A28: 1.1 | B28: Café Tables : 2050 X 900 X 750mm - 6 Pax | C28: 16 | D28: Nos | F28: =C28*E28 -> 0 | G28: As per Drawing
A29: 1.2 | B29: Café Tables : 2700 X 900 X 750mm - 8 Pax | C29: 3 | D29: Nos | F29: =C29*E29 -> 0 | G29: As per Drawing
A30: 1.3 | B30: Café Round Table : 900 X 750 mm - 4 Pax | C30: 8 | D30: Nos | F30: =C30*E30 -> 0 | G30: As per Drawing
A31: 1.4 | B31: Café Round Table : 800 X 750 mm - 2 Pax | C31: 4 | D31: Nos | F31: =C31*E31 -> 0 | G31: As per Drawing
A32: 1.5 | B32: Café Round Table : 950 X 750 mm - 3 Pax | C32: 2 | D32: Nos | F32: =C32*E32 -> 0 | G32: As per Drawing
A33: 1.6 | B33: Café High Running Table : 450mm depth | C33: 24 | D33: Rft | F33: =C33*E33 -> 0 | G33: As per Drawing
A34: 1.4 | B34: Café Chair | C34: 166 | D34: Nos | F34: =C34*E34 -> 0 | G34: As per Drawing
B35: Providing and placing premium café chairs with solid hardwood / powder-coated metal frame, upholstered seat and back using high-density foam and approved fabric/leatherette/leather. Finished with melamine/PU polish for wood or powder coating for metal in approved shade.
A36: 1.5 | B36: High Table : 3150 X 1050 X 1250 mm - 10 Pax | C36: 1 | D36: Nos | F36: =C36*E36 -> 0 | G36: As per Drawing
B37: TABLE TOP : Table top to be made of 18mm thick granite with proper finish. UNDERSTRUCTURE : Legs to be made of 40mm x 40mm x 1.6mm MS tube finished with approved shade of powder coating.
A38: 1.6 | B38: High Table : 3400 X 1000 X 1250 mm - 12 Pax | C38: 2 | D38: Nos | F38: =C38*E38 -> 0 | G38: As per Drawing
B39: TABLE TOP : Table top to be made of 18mm thick granite with proper finish. UNDERSTRUCTURE : Legs to be made of 40mm x 40mm x 1.6mm MS tube finished with approved shade of powder coating.
A40: 1.7 | B40: High Stools | C40: 31 | D40: Nos | F40: =C40*E40 -> 0 | G40: As per Drawing
B41: Providing and placing premium café high chairs with solid hardwood / powder-coated metal frame, upholstered seat and back using high-density foam and approved fabric/leatherette/leather. Finished with melamine/PU polish for wood or powder coating for metal in approved shade.
B42: TOTAL OF LOOSE FURNITURE ITEMS | F42: =SUM(F4:F40) -> 0

Sheet BROUGHTOUT ITEMS
A1: Sr.No. | B1: Description | C1: Location | D1: Qty. | E1: Unit | F1: Rate | G1: Amount | H1: Remarks
A2: D | B2: BROUGHT OUT FURNITURE
A4: 1 | B4: Sick Room Single Bed with Mattress | E4: Nos | G4: =$D4*F4 -> 0
B5: Angle iron support shall be at equal distance. Strips in angle iron frame gap between two strips not more than 50mm of 25x1.0mm minimum.Head bow and foot bow pipe. Head bow/Foot bow pipe support in width wise , one in each side. Height of the head bow from support pipe –300mm.Height of the foot bow from support pipe
A7: 2 | B7: Supply and installation of chair for Lactation room | E7: Nos. | G7: =D7*F7 -> 0
A9: 3 | B9: METAL LOCKER 1 NOS -400X450X300 MM HT (1- Tower 1200X450X1850 MM HT =18 nos) & ( 1- Tower 900X450X1850 MM = 12 nos) | E9: Nos. | G9: =D9*F9 -> 0
A11: 4 | B11: CHESS TABLE WITH CHAIRS | E11: Nos. | G11: =D11*F11 -> 0
B12: Supply and Installation of Chess Table with chairs
A14: 5 | B14: CARROM TABLE WITH STAND AND CHAIRS | E14: Nos. | G14: =D14*F14 -> 0
B15: Supply and Installation of Carrom Table with stand and chairs
A17: =A14+1 -> 6 | B17: AIR Hockey Table (2100x1200mm) - Xpeed | E17: Nos. | G17: =D17*F17 -> 0
B18: Supply and Installation of Air hockey Table
A20: =A17+1 -> 7 | B20: Foose Ball (1800x1200mm) - Signature Pro | E20: Nos. | G20: =D20*F20 -> 0
B21: Supply and Installation of Foose ball Table
A23: 8 | B23: TABLE TENIS | E23: Nos. | G23: =D23*F23 -> 0
B24: Supply and Installation of Table Tenis
A26: 9 | B26: POOL Table | E26: Nos. | G26: =D26*F26 -> 0
B27: Supply and installation of Pool Table
A29: 10 | B29: FRIDGE | D29: 1 | E29: Nos. | G29: =D29*F29 -> 0
B30: Supply and Installation of Fridge of make Elanpro ECG 515 Single Door Refrigerator
A32: =A29+1 -> 11 | B32: WATER Purifier / Dispenser | C32: Pantry Area | D32: 2 | E32: Nos. | G32: =D32*F32 -> 0
B33: Supply and Installation of WAE VAR 150 Drinking Water Stations 400 Mm(W) X 1470 Mm (H) X 647 Mm(D) Ss 304 With Frp Dispensing Construct, Galvanized Iron Powder Coated, 5 Stage Purification @ 50 Litres Per Hour with Kent Elite 2 Plus Purifier
A35: =A32+1 -> 12 | B35: MICROWAVE | D35: 1 | E35: nos. | G35: =D35*F35 -> 0
B36: Supply and Installation of LG All In One 28 Litres Convection Microwave Oven (Charcoal Lighting Heater, MJEN286UI, Black)
A38: 13 | B38: MONITOR STAND | E38: nos. | G38: =D38*F38 -> 0
B39: Supply and Installation of Providing & Fixing Monitor stand single arm
A41: 14 | B41: DISH WASHER | E41: nos. | G41: =D41*F41 -> 0
B42: Supply and Installation of IFB Make (Hood Type)
A44: 15 | B44: Bainmerry - S.S. Drop In Five Container Hot Bain Marie water based Size : 2950 x 660 x 240 | D44: 4 | E44: nos. | G44: =D44*F44 -> 0
A46: 16 | B46: Induction Live Counter Top | E46: nos. | G46: =D46*F46 -> 0
A48: 17 | B48: Commercial Sandwich Grillers | D48: 1 | E48: nos. | G48: =D48*F48 -> 0
A50: 18 | B50: DUST BINS - Café | D50: 2 | E50: nos. | G50: =D50*F50 -> 0
B51: SUPPLY OF SS SWING BIN - SS 202 ECONOMY GRADE SIZE 12"X28" - 50L GRAPHICS PRINT
A53: 19 | B53: DUST BINS - Kitchen | D53: 2 | E53: nos. | G53: =D53*F53 -> 0
B54: SUPPLY OF SS SOLID OPEN BIN - SS 202 ECONOMY GRADE SIZE 12"X28" - 50L SUPPLY OF SS WASTE OPEN CHUTE - SS 304 GRADE 1.2MM THICK - 250MM INNER DIA X 300MM OUTER DIA X 100MM RAISING
A56: 20 | B56: High speed Hand drier – café handwash area | C56: Handwash - café. | D56: 2 | E56: nos. | G56: =D56*F56 -> 0
B58: TOTAL OF BROUGHT OUT FURNITURE ITEMS | G58: =SUM(G3:G57) -> 0

Sheet CAFE PLUMBING WORK
A1: Sl. No. | C1: DESCRIPTION | D1: MAKE | E1: UNIT | F1: QTY | G1: RATE | H1: Total Amount | I1: REMARKS
A3: 1 | B3: 995479 | C3: SS SINK - SINGLE BOWL - NIRALI MAKE | D3: Nirali
C4: Single bowl SS sink Single Bowl with drain board - Supply & fixing of sink with all accessories, necessary supports and sealing the edges with Sealant. Provision for fixing 32mm Dia waste coupling and bottle trap to be given. model - nirali elegance medium Note : Cost to include for Faucet, waste coupling, angle cock, inlet connection pipe, bottle trap & waste coupling. | E4: Nos. | F4: 1 | H4: =+F4*G4 -> 0
A6: 2 | C6: WASH BASIN | D6: Jaquar | E6: Nos. | F6: 10 | H6: =+F6*G6 -> 0
C7: Supply and Installing washbasin (INCLUDING piller cock, basin mixer, waste coupling, bottle trap , angle cock and supports for fixing) for Handwash of approved make & model - JAQUAR
C9: T O T A L - PART I | H9: =SUM(H3:H8) -> 0
A11: II | B11: 995479 | C11: INTERNAL SEWERAGE SYSTEM - SOIL, WASTE, VENT, PIPES
C12: Please note all the pipes should be low noise pipes
A13: 1 | C13: Supply and fixing, of PVC soil, waste and vent pipes (SWR) confirming to IS13592 : 1990, type B with rubber ring (confirming to IS 5382) 6kg/sqcm with solvent joint inclusive of all necessary specials like bends, tees, offsets, doorbends, junctions, screw type caps with rubber rings for cleanout pipe ends, etc., suspended under floor slabs/fixed on walls or on pipe racks in shafts. All suspenders, saddles, pipe packs are to be quoted separately under relevant items.( Inclusive of verticals & horizontals at Internal Toilets ) ,
C15: 75mm dia , | D15: Astral / Ajay / Ashirwad | E15: Rmt | F15: 35 | H15: =+F15*G15 -> 0
C16: 110mm dia | D16: Astral / Ajay / Ashirwad | E16: Rmt | F16: 25 | H16: =+F16*G16 -> 0
A18: 2 | C18: Supply and fixing, of PVC pressure pipes (6Kg/sqcm) confirming to IS 4985 for waste connection from wash basin, kitchen sinks to floor trap, antisyphonage/vent pipe with solvent cement joints, including all the fittings, suspended under floor slabs/concealed in wall etc, the work shall include wall chase and making good the same in cement mortar. All suspenders, saddles , pipe packs are to be quoted separately under relevant items.
C19: 40mm dia (I.D.) | E19: Rmt | F19: 45 | H19: =+F19*G19 -> 0
C20: 50mm dia (I.D.) | E20: Rmt | F20: 35 | H20: =+F20*G20 -> 0
A23: 4 | C23: Supplying, installing,testing and commissioning pipe clean outs fabricated from heavy duty PVC pipe for waste and soil lines for effective maintenance, laid at the dead end side of header pipe pluged and opening type ., complete
C24: 75mm dia | E24: Nos | F24: 15 | H24: =+F24*G24 -> 0
A26: 7 | C26: Supply and fixing, of MS slotted angle iron brackets, MS threaded hangers and supports with necessary drilling holes to suit the insertion of pipe clamps, as per approved fabrication drawings, for supporting soil, waste and rain water pipes and water supply pipes in shafts with suitable MS clamps, bolts, anchor bolts nuts and washers fixed on shaft walls and suspended under floors. The quoted rate shall include painting all steel members with one coat of primer and two coats of enamel paint etc complete. | E26: Kgs. | F26: 8 | H26: =+F26*G26 -> 0
C27: T O T A L - PART II | H27: =SUM(H13:H26) -> 0
A29: III | B29: 995479 | C29: INTERNAL WATER SUPPLY SYSTEM
C30: Please note all the pipes should be low noise pipes
A31: 1 | C31: Supplying, installing, fixing, jointing, testing and commissioning of approved make Chlorinated Polyvinyl Chloride pipes (CPVC) SDR.11 pipes confirming to ASTM standards with necessary fittings, and above 50mm dia pipe fitting shall be schedule 40 ASTM IPS. The fittings and specials such as tees, elbows,couplers, bends, enlargers etc.,m with CPVC brass threaded combination / transition specials such as male adapters brass threaded female adapters, brass FPT Tee, Brass FPT elbow etc., where connection with metal is to be made including necessary drilling holes, chasing walls and making the same good in cement martor 1:1 restore the same original condition neately as directed by the Engineer in-charge.Joints to be made with CPVC solvent cement up to 50mm dia as per ASTM D-2846 and above 50mm dia primer P-70, and solvent confirming to ASTM F-4931 / 724 (internal piping)
C32: c) 25 mm dia | D32: Astral / Ajay / Ashirwad | E32: Rmt | F32: 25 | H32: =+F32*G32 -> 0
C33: d) 32 mm dia | D33: Astral / Ajay / Ashirwad | E33: Rmt | F33: 30 | H33: =+F33*G33 -> 0
A35: 2 | C35: Supplying, and fixing, GM ball valves conforming to IS 1703 with necessary connecting fittings like flanges, nuts and bolts etc., complete.
C36: 25 mm dia (Screwed ends) | D36: NVR / Zoloto / DRP/SANT | E36: Nos. | F36: 1 | H36: =+F36*G36 -> 0
C37: 32 mm dia (Screwed ends) | D37: NVR / Zoloto / DRP/SANT | E37: Nos. | F37: 1 | H37: =+F37*G37 -> 0
A39: 3 | C39: Supplying, and fixing, GM non return valves conforming to IS 1703 with necessary connecting fittings like flanges, nuts and bolts etc., complete. Dia of 40mm | D39: NVR / Zoloto / DRP/SANT | E39: Nos. | F39: 2 | H39: =+F39*G39 -> 0
A41: 5 | C41: Supplying, installing, testing and commissioning of GI Class C Pipe heavy grade with threaded fittngs for hot water supply confirming to ASTM standard including all GI fittings like tees, elbows, bends, unions, coupling, reducer tees, collars, etc. Also insulation for hot water pipes. Insulation of GI Pipe with Elastomeric tube for insulation with 9mm thick Class O material The work shall include making holes, including chasing in solid block masonry walls with groove cutting machine to required width and depth, making opening in walls, , making good the walls and bores in CC or CM 1:3 as applicable clearing the debris, grouting of concealed pipes, MS hooks for fixing pipes and making good the walls and floors.
C42: a) 20 mm dia | D42: Tata / Jindal (Hissar) / apollo | E42: Rmt | F42: 35 | H42: =+F42*G42 -> 0
C44: T O T A L - PART III | H44: =SUM(H31:H43) -> 0
C46: Grand Total ( I + II + III ) | H46: =+H9+H27+H44 -> 0

Sheet Electrical
A3: BOQ For Electrical Work
A4: Sr. Nos | B4: Description | C4: Qty. | D4: Unit | E4: Rate | F4: Amount
A6: 1 | B6: Supply, Installation, Testing, Commissioning of MAIN L.T & HVAC PANEL - MCCB INCOMER AND MCCB / MCB OUTGOING. with fire suppression systems | C6: 1 | D6: Nos | F6: =C6*E6 -> 0
A8: 2 | B8: Supply, Installation, Testing, Commissioning of UPS POWER O/P PANEL - with fire suppression systems | C8: 1 | D8: Nos | F8: =C8*E8 -> 0
A10: A | B10: DISTRIBUTION BOARDS
B11: Supply, installation, testing, tagging, (Circuit numbering) and commissioning of following IP43,double door readymade recessed type MCB, DB, fabricated out of CRCA sheet and painted with powdercoating process OR made out of scratch proof polycarbonate body, and concealed in wall or on surface with necessary frame complete as required.
A12: 1.1 | B12: MAIN DB | C12: 0 | D12: Set | F12: =C12*E12 -> 0
B13: 8way , VTPN MCB Double Door DB
B14: Incomer :-
B15: 160A TPN MCCB, 25KA : 1Nos
B16: Outgoing :-
B17: 63A TP MCB, 10KA : 3Nos.
B18: 40A TP MCB, 10KA : 3Nos.
B19: 32A TP MCB, 10KA : 1Nos.
B20: 25A SP MCB, 10KA : 3Nos.
A22: 1.2 | B22: UPS OUTPUT MAIN DB | C22: 0 | D22: Set | F22: =C22*E22 -> 0
B23: 4way , VTPN MCB Double Door DB
B24: Incomer :-
B25: 63A TPN MCB, 10KA : 1Nos
B26: Outgoing :-
B27: 63A TP MCB, 10KA : 2Nos.
B28: 40A TP MCB, 10KA : 1Nos.
B29: 25A SP MCB, 10KA : 3Nos.
A31: 1.2 | B31: LIGHTING DISTRIBUTION BOARD (LPDB) | C31: 1 | D31: Set | F31: =C31*E31 -> 0
B32: FLEXI TIER DB DOUBLE DOOR 4 TIER 32 MODULE
B33: Incomer :-
B34: 40A TPN MCB, 10KA : 1Nos
B35: 25A/30mA DP RCCB : 3Nos
B36: Outgoing :-
B37: 6/32A SP MCB, 10KA : 18Nos.
A39: 1.3 | B39: RAW POWER DISTRIBUTION BOARD (RPDB) | C39: 1 | D39: Set | F39: =C39*E39 -> 0
B40: FLEXI TIER DB DOUBLE DOOR 4 TIER 56 MODULE
B41: Incomer :-
B42: 40A TPN MCB, 10KA : 1Nos
B43: 25A/30mA DP RCCB : 3Nos
B44: Outgoing :-
B45: 6/32A SP MCB, 10KA : 30Nos.
A47: 1.4 | B47: UPS DISTRIBUTION BOARD (UDB) | C47: 1 | D47: Set | F47: =C47*E47 -> 0
B48: FLEXI TIER DB DOUBLE DOOR 4 TIER 56 MODULE
B49: Incomer :-
...

Sheet HVAC
A1: Sr. No. | B1: SUMMERY SHEET | C1: Amount
A2: Part A | B2: VRF SYSTEM (High side Supply part) | C2: =F43 -> 0
A3: Part B | B3: Low Side ancillary SITC Work | C3: =F97 -> 0
A4: Part C | B4: Fresh air for VRV System | C4: =F116 -> 0
A5: Part D | B5: Toilet Ventilation | C5: =F151 -> 0
B6: SUB TOTAL PART A+B | C6: =SUM(C2:F5) -> 0
B7: GST EXTRA @ 18 %
A8: HVAC | E8: ECO GREEN
A9: Sr. No | B9: Description | C9: Total Qty | D9: UM | E9: Supply Rate | F9: Supply Amount
A10: A | B10: VRF SYSTEM (High side Supply part)
A11: 1 | B11: Outdoor Units (with 410 A Gas)
B12: Supply of Out Door Units suitable for VRF System Outdoor units suitable for the following capacities :
A13: =A11+0.1 -> 1.1 | B13: 28HP Outdoor Units | C13: 3 | D13: Nos. | F13: =C13*E13 -> 0
A14: =A13+0.1 -> 1.2 | B14: 16HP Outdoor Units | C14: 1 | D14: Nos. | F14: =C14*E14 -> 0
A16: 2 | B16: VRF Indoor Comapct Cassettes Type Unit
A17: =A16+0.1 -> 2.1 | B17: 1.5 TR Compact Cassette Units | C17: 1 | D17: Nos. | F17: =C17*E17 -> 0
A18: =A17+0.1 -> 2.2 | B18: 1.3 TR Compact Cassette Units | C18: 4 | D18: Nos. | F18: =C18*E18 -> 0
A19: =A18+0.1 -> 2.3 | B19: 1.0 TR Compact Cassette Units | C19: 2 | D19: Nos. | F19: =C19*E19 -> 0
A20: =A19+0.1 -> 2.4 | B20: 0.8 TR Compact Cassette Units | C20: 3 | D20: Nos. | F20: =C20*E20 -> 0
A22: 3 | B22: VRF Indoor Large Cassettes Type Unit
A23: =A22+0.1 -> 3.1 | B23: 3.2 TR Cassette Units | C23: 8 | D23: Nos. | F23: =C23*E23 -> 0
A24: =A23+0.1 -> 3.2 | B24: 2.8 TR Cassette Units | C24: 12 | D24: Nos. | F24: =C24*E24 -> 0
A25: =A24+0.1 -> 3.3 | B25: 2.0 TR Cassette Units | C25: 3 | D25: Nos. | F25: =C25*E25 -> 0
A27: 4 | B27: VRF Indoor One Way Cassettes Type Unit
A28: =A27+0.1 -> 4.1 | B28: 2.0 TR Cassette Units | C28: 1 | D28: Nos. | F28: =C28*E28 -> 0
A30: 5 | B30: VRF Indoor Hiwall Type Unit
A31: =A30+0.1 -> 5.1 | B31: 1.3 TR Cassette Units | C31: 1 | D31: Nos. | F31: =C31*E31 -> 0
A33: 6 | B33: Supply of Dx hiwall units.
A34: =A33+0.1 -> 6.1 | B34: 1.0 TR Hi-wall Units Server Room (1W+ 1S) | C34: 1 | D34: Nos. | F34: =C34*E34 -> 0
A36: 7 | B36: Supply of Centralized Controller, Remote Controllers
A37: =A36+0.1 -> 7.1 | B37: Cordless Remote For Cassette, Hiwall Indoor Units | C37: 35 | D37: Nos. | F37: =C37*E37 -> 0
A38: =A37+0.1 -> 7.2 | B38: Centrallized Wifi Controller | C38: 1 | D38: Nos. | F38: =C38*E38 -> 0
A40: 8 | B40: REFNET/Y JOINTS
A41: =A40+0.1 -> 8.1 | B41: Refnet for Indoor unit | C41: 34 | D41: Nos. | F41: =C41*E41 -> 0
A42: =A41+0.1 -> 8.2 | B42: Refnet for Outdoor unit | C42: 3 | D42: Nos. | F42: =C42*E42 -> 0
B43: SUB TOTAL WITHOUT TAX | F43: =SUM(F13:F42) -> 0
A45: B | B45: LOW SIDE ANCILLARY SITC WOTK | C45: Total Qty | D45: UM | E45: Supply Rate | F45: Supply Amount
A47: 1 | B47: Installation of outdoor units (Loading unloading, Lifting shifting, Alignment with all ancillary material)
A48: =A47+0.1 -> 1.1 | B48: 28HP Outdoor Units | C48: 3 | D48: Nos. | F48: =C48*E48 -> 0
A49: =A48+0.1 -> 1.2 | B49: 16HP Outdoor Units | C49: 1 | D49: Nos. | F49: =C49*E49 -> 0
...

Sheet Summary
A1: Master Summary
A2: S.NO. | B2: Description | C2: Amount (In INR)
E3: Summary | F3: Make
A4: 1 | B4: NETWORKING - Passive | C4: =+Passive!I28 -> 0 | E4: PASSIVE | F4: Commscope Netconnect
A5: 2 | B5: CCTV | C5: =+CCTV!I17 -> 0 | E5: CCTV | F5: CP Plus
A6: 3 | B6: Access Control System | C6: =+ACS!I19 -> 0 | E6: ACS | F6: Essl
A7: 4 | B7: FAS | C7: =+FAS!I25 -> 0 | E7: FAS | F7: Ravel
A8: 5 | B8: PAS | C8: =+PAS!I16 -> 0 | E8: PAS | F8: Bosch+Ahuja
A9: 6 | B9: Fire exinguishers | C9: =+'Fire Extinguisher'!H9 -> 0 | E9: Fire Extinguishers | F9: Safex/ Excellent
B11: GRAND TOTAL (Excluding taxes) | C11: =SUM(C4:C9) -> 0 | F11: Total

Sheet Passive
B2: Passive
A3: Sr.No | B3: Description (cable average 50m per node)(Total nodes 150) | C3: Part Code | D3: UOM | E3: Qty | F3: Supply Rate | G3: Installation Rate | H3: Supply Amount | I3: Installation Amount
B4: Passive Network Data
A6: 1 | B6: 4 Pair UTP Cat 6a Cable | C6: Commscope | D6: 305m/Box | E6: 32 | H6: =F6*E6 -> 0 | I6: =SUM(G6*E6) -> 0
A7: 2 | B7: UTP CAT 6a I/O User End & Data End | C7: Commscope | D7: NOS | E7: 375 | H7: =F7*E7 -> 0 | I7: =SUM(G7*E7) -> 0
A8: 3 | B8: Single\Dual Port FACEPLATE | C8: Commscope | D8: NOS | E8: 132 | H8: =F8*E8 -> 0 | I8: =SUM(G8*E8) -> 0
A9: 4 | B9: Quad Port FACEPLATE | C9: Commscope | D9: NOS | E9: 0 | H9: =F9*E9 -> 0 | I9: =SUM(G9*E9) -> 0
A10: 5 | B10: CAT 6a UTP PATCH CORD 2M - USER END & RACK END | C10: Commscope | D10: NOS | E10: 375 | H10: =F10*E10 -> 0 | I10: =SUM(G10*E10) -> 0
A11: 6 | B11: CAT 6a 24 Port Unloaded Patch Panel | C11: Commscope | D11: NOS | E11: 9 | H11: =F11*E11 -> 0 | I11: =SUM(G11*E11) -> 0
A12: 7 | B12: CAT 6a UTP PATCH CORD 2M -UPLINK | C12: Commscope | D12: NOS | E12: 9 | H12: =F12*E12 -> 0 | I12: =SUM(G12*E12) -> 0
B13: Fiber Uplink MDF to IDF
A14: 1 | B14: OFC Multimode Mode OM4-12F armoured cable (APPROX QTY) | C14: Commscope | D14: RMT | E14: 255 | H14: =F14*E14 -> 0 | I14: =SUM(G14*E14) -> 0
A15: 2 | B15: 24 port Loaded LIU with splice trey/Adaptors with all accessories | C15: Commscope | D15: NOS | E15: 2 | H15: =F15*E15 -> 0 | I15: =SUM(G15*E15) -> 0
A16: 3 | B16: LC to LC Ofc fiber patch cords -SMF-OS2-DPX-LCLC-3MTR | C16: Commscope | D16: NOS | E16: 24 | H16: =F16*E16 -> 0 | I16: =SUM(G16*E16) -> 0
A17: 4 | B17: Splicing of LC pigtails | C17: Commscope | D17: NOS | E17: 24 | H17: =F17*E17 -> 0 | I17: =SUM(G17*E17) -> 0
B18: Rack Components
A19: 1 | B19: 42 U 800x1000 | C19: Netrack | D19: Nos | E19: 1 | H19: =F19*E19 -> 0 | I19: =SUM(G19*E19) -> 0
A20: 2 | B20: Server /IT Rack mount power distribution unit, 1Ph, 230V, 16A, 50/60Hz, 2U standard with 6 X Indian Round Pin 5/15A, Inlet Plug type 16A Indian Round Pin, 16A MCB - PDU Rating 3.6KVA/Side feed-1.5Mt/ Black | C20: Netrack | D20: Nos | E20: 2 | H20: =F20*E20 -> 0 | I20: =SUM(G20*E20) -> 0
A21: 3 | B21: 2U Horizontal Cable manager Chnl on Front | C21: Netrack | D21: Nos | E21: 9 | H21: =F21*E21 -> 0 | I21: =SUM(G21*E21) -> 0
A22: 4 | B22: Mounting Hardware/OR/Pk-20 | C22: STD | D22: Nos | E22: 20 | H22: =F22*E22 -> 0 | I22: =SUM(G22*E22) -> 0
A23: 5 | B23: Rack Dressing Charges | C23: STD | D23: Nos | E23: 1 | H23: =F23*E23 -> 0 | I23: =SUM(G23*E23) -> 0
B24: Testing & Certification
A25: 1 | B25: Cable Segrigation/Bunching /Dressing/Feruling/Termination of Infomration outlets Both Side (User side & Rack side)/ complete Rack dressing/ Jack panel and Faceplate Labling/ LAN testing (Using Lan Tester)/Patch cord labling and Dressing/ Fluke Testing & Certification | C25: Job | D25: Nos | E25: 150 | H25: =F25*E25 -> 0 | I25: =SUM(G25*E25) -> 0
A26: 2 | B26: Project Management Charges | C26: Job | D26: Nos | E26: 1 | H26: =F26*E26 -> 0 | I26: =SUM(G26*E26) -> 0
B27: Total | H27: =SUM(H6:H26,) -> 0 | I27: =SUM(I6:I26,) -> 0
B28: Grand Total | I28: =H27+I27 -> 0

Sheet CCTV
A2: CCTV - NVR - CP Plus
A3: Sr.No | B3: Descirption | C3: Part Code | D3: UOM | E3: Qty | F3: Supply Rate | G3: Installation Rate | H3: Supply Price | I3: Installation Price
A5: 1 | B5: Dome Camera - 2 MP | C5: CP-UNC-DA21L3C-Q | D5: Nos | E5: 16 | H5: =F5*E5 -> 0 | I5: =SUM(G5*E5) -> 0
A6: 2 | B6: 24 Port POE Switch | C6: D-Link DGS-1100-24PV2 | D6: Nos | E6: 1 | H6: =F6*E6 -> 0 | I6: =SUM(G6*E6) -> 0
A7: 3 | B7: 32 Channel NVR 4 Slot | C7: CP-UNR-4K5324-V3 | D7: Nos | E7: 1 | H7: =F7*E7 -> 0 | I7: =SUM(G7*E7) -> 0
A8: 4 | B8: 10 TB Hardisk Drive for NVR | C8: SEGATE | D8: Nos | E8: 2 | H8: =F8*E8 -> 0 | I8: =SUM(G8*E8) -> 0
A9: 5 | B9: Camera Stand | C9: STD | D9: Nos | E9: 16 | H9: =F9*E9 -> 0 | I9: =SUM(G9*E9) -> 0
A10: 6 | B10: PVC Back Box | C10: STD | D10: Nos | E10: 16 | H10: =F10*E10 -> 0 | I10: =SUM(G10*E10) -> 0
A11: 7 | B11: 27" LCD Screen for CCTV Monitoring | C11: Samsung | D11: Nos | E11: 1 | H11: =F11*E11 -> 0 | I11: =SUM(G11*E11) -> 0
A12: 8 | B12: Testing & Certification | D12: Nos | E12: 1 | H12: =F12*E12 -> 0 | I12: =SUM(G12*E12) -> 0
A13: 9 | B13: Conduit & Saddle | C13: STD | D13: MTR | E13: 1050 | H13: =F13*E13 -> 0 | I13: =SUM(G13*E13) -> 0
B16: Total | H16: =SUM(H4:H13) -> 0 | I16: =SUM(I4:I13) -> 0
B17: Grand Total | I17: =SUM(H16:I16) -> 0

Sheet ACS
B1: ACS - ESSL
A2: Sr.No | B2: Description | C2: Part Code | D2: UOM | E2: Qty | F2: Supply Rate | G2: Installation Rate | H2: Supply Amount | I2: Installation Amount
A3: 1 | B3: 4 Door Controller | C3: C3-400 | D3: Nos | E3: 1 | H3: =F3*E3 -> 0 | I3: =SUM(G3*E3) -> 0
A4: 2 | B4: Entry Reader - ( Facial + RFID) | C4: FACE - AIFACE MAGNUM LITE eSSL | D4: Nos | E4: 1 | H4: =F4*E4 -> 0 | I4: =SUM(G4*E4) -> 0
A5: 3 | B5: Exit Reader - ( Facial + RFID) | C5: FACE - AIFACE MAGNUM LITE eSSL | D5: Nos | E5: 1 | H5: =F5*E5 -> 0 | I5: =SUM(G5*E5) -> 0
A6: 4 | B6: Entry Reader - (RFID+Biometric) | C6: Essl Fr1200 | D6: Nos | E6: 2 | H6: =F6*E6 -> 0 | I6: =SUM(G6*E6) -> 0
A7: 5 | B7: Exit Reader - (RFID+Biometric) | C7: Essl Fr1200 | D7: Nos | E7: 2 | H7: =F7*E7 -> 0 | I7: =SUM(G7*E7) -> 0
A8: 6 | B8: Push Button | C8: HF-S86 | D8: Nos | E8: 3 | H8: =F8*E8 -> 0 | I8: =SUM(G8*E8) -> 0
A9: 7 | B9: Single Leaf EM LOCK | C9: ESSL | D9: Nos | E9: 1 | H9: =F9*E9 -> 0 | I9: =SUM(G9*E9) -> 0
A10: 8 | B10: Double Leaf EM LOCK | C10: ESSL | D10: Nos | E10: 2 | H10: =F10*E10 -> 0 | I10: =SUM(G10*E10) -> 0
A11: 9 | B11: U or L Bracket HI FOCUS 280 | C11: HI FOCUS 280 | D11: Nos | E11: 3 | H11: =F11*E11 -> 0 | I11: =SUM(G11*E11) -> 0
A12: 10 | B12: 8core 0.75 sq.mm Shielded, PVC Sheathed Copper Flexible Cable with 1.6mm thick, 25mm MS conduit. | C12: Polycab | D12: MTR | E12: 375 | H12: =F12*E12 -> 0 | I12: =SUM(G12*E12) -> 0
A13: 11 | B13: 4core 0.75 sq.mm Shielded, PVC Sheathed Copper Flexible Cable with 1.6mm thick, 25mm MS conduit. | C13: Polycab | D13: MTR | E13: 375 | H13: =F13*E13 -> 0 | I13: =SUM(G13*E13) -> 0
A14: 12 | B14: 2core 0.75sq.mm Shielded, PVC Sheathed Copper Flexible Cable with 1.6mm thick, 25mm MS conduit. | C14: Polycab | D14: MTR | E14: 188 | H14: =F14*E14 -> 0 | I14: =SUM(G14*E14) -> 0
... A17: 15 | B17: Testing & Certification | C17: Job | D17: Nos | E17: 1 | H17: =F17*E17 -> 0 | I17: =SUM(G17*E17) -> 0
B18: Total | H18: =SUM(H3:H17) -> 0 | I18: =SUM(I3:I17) -> 0
B19: Grand Total | I19: =SUM(G18:I18) -> 0

Sheet FAS
A1: Sr.No | B1: PARTICULARS. | C1: SIZE/MAKE. | D1: UNIT. | E1: QTY. | F1: Supply Rate | G1: Installation Rate | H1: Supply Amount | I1: Installation Amount
B3: FIRE ALARM SYSTEM ( RAVEL)
A4: 1 | B4: 8 LOOP ADDRESSABLE FIRE CONTROL PANEL Microprocessor designed to meet all requirements of IS – 2189,indication for open, short , sounder fault , power supply fault , battery low, fault buzzer mute facility, space for SMF batteries, compact stylish design, user friendly controls,With 24V battery backup(Exide Make), UL& CE approved | C4: Ravel | D4: Nos | E4: 1 | H4: =F4*E4 -> 0 | I4: =SUM(G4*E4) -> 0
A5: 2 | B5: Photoelectric type smoke detector (Addressable) BFC Plug in type optical smoke detector placed above false ceiling, with red lamp type for indication,LPCB,Vds, UL& CE approved | C5: Ravel | D5: Nos | E5: 35 | H5: =F5*E5 -> 0 | I5: =SUM(G5*E5) -> 0
A6: 3 | B6: Photoelectric type smoke detector (Addressable) AFC Plug in type optical smoke detector placed above false ceiling, with red lamp type for indication,LPCB,Vds, UL& CE approved | C6: Ravel | D6: Nos | E6: 35 | H6: =F6*E6 -> 0 | I6: =SUM(G6*E6) -> 0
