Workbook
Name Excel_BuiltIn_Print_Area_1: #REF!
Name Excel_BuiltIn_Print_Area_1: #REF!

Sheet Gerenal Notes
A1: GENERAL NOTES
A3: 1 | B3: The items given in this schedule are provisional. The Tenderer shall be paid for the actual quantity of work executed as measured at the site at the rates tendered. The Client reserves the right to increase or decrease any of the quantities, or to ommit totally any item of work. Any claim by the Tenderer on these accounts will not be entertained.
A4: 2 | B4: All the items of work given in this schedule of quantities shall be executed strictly in accordance with the latest Indian Standard Specifications and the requirements of the Electricity Supply Authority read in conjunction with the relevant drawings and Specifications.
A5: 3 | B5: The Tenderer shall visit the site and shall satisfy himself as to the conditions under which the work is to be performed. He shall also check and ascertain the location of any existing structure or equipment or any other situation which may affect the work. No extra claim as a consequence of ignorance or on ground of insufficient description will be allowed at a later date.
A6: 4 | B6: All equipment and material shall be IS approved.
A7: 5 | B7: All approvals shall be obtained from Client / Consultant
A8: 6 | B8: All equipment and material shall be inspected at manufacturer’s works as per relevant IS by the Client or his representative before despatch to site.
A9: 7 | B9: All vendor drawings shall be approved by the Client /Consultant before fabrication work starts.
A10: 8 | B10: All Testing and Commissioning shall be as per relevant IS for equipment and S:732:1999 and amendanent upto date, for the installation. All testing records are to be maintained and submitted for Client’s representative. The rate shall include the wastage on material & Labour..
A11: 9 | B11: No alteration whatsoever is to be made to the text or quantities of this Schedule unless such alteration is authorised in writing by Services Consultant or Client. Any such alterations, notes or additions shall, unless authorized in writing, be disregarded when tender documents are considered.
A12: 10 | B12: In the event of an error occurring in the amount of the Schedule, as a result of wrong extension of the unit rate and quantity, the unit rate quoted by the tenderer shall be regarded as firm and the extensions shall be amended on the basis of rates.
A13: 11 | B13: Any error in totaling in the amount column and in carrying forward total shall be corrected. Any error, in description or in quantity, omission of items from this Schedule shall not vitiate this Contract but shall be corrected and deemed to be variation required by the Services Consultant/Project Manager.
A15: A. | B15: CIRCUIT CUM POINT WIRING
B16: The rates for all point wiring items shall also include supplying and fixing of the following:
A17: 1 | B17: Conduits, conduit specials, brass bushes and other fittings.
A18: 2 | B18: Approved GI saddles and grouting the same for exposed conduit work.
A19: 3 | B19: 1.2 mm thick Outlet boxes and junction box.
A20: 4 | B20: All fixing accessories such as clips, brass screws etc.
A21: 5 | B21: All work necessary for wiring a point circuit of any length from the Final Distribution Board to connector via switch and shall include the circuit wiring also except where identified.
A22: 6 | B22: Embedding conduits and accessories in walls and floors etc. during construction and / or cutting chases (with chase cutting machine) and making good the same as necessary in the case of concealed conduit work.
A23: 7 | B23: Switch, socket outlet and necessary blank plates wherever required.
A24: 8 | B24: FRLS copper conductor stranded flexible FRLS wire of Green colour or Green colour with yellow band for earthing of fixtures, outlet boxes and third pin of socket outlet.
A25: 9 | B25: Repainting of outlet boxes and juction boxes where ever damaged.
A26: 10 | B26: All wires shall be IS approved, 1100 volt grade, stranded flexible FRLS.
A27: 11 | B27: All sockets shall be shuttered type with earth terminal.
A28: 12 | B28: Suitable rating of plugs top shall also be provided within the quoted rates for all metal clad splash proof socket outlets.
... A30: 14 | B30: Lighting and power circuit to be kept separate.

Sheet SUMMARY
A2: INTERNAL ELECTRICAL WORKS, KSM 66 OFFICE, HYDERABAD
A4: S. No. | B4: Description | C4: Amount (In Rupees)
A6: A | B6: ='ELECT BOQ'!B7 -> CIRCUIT CUM POINT WIRING | C6: ='ELECT BOQ'!F71 -> 0
A7: B | B7: ='ELECT BOQ'!B73 -> CABLES & CABLE TRAYS | C7: ='ELECT BOQ'!F142 -> 0
A8: C | B8: ='ELECT BOQ'!B144 -> FINAL DISTRIBUTION BOARDS | C8: ='ELECT BOQ'!F161 -> 0
A9: D | B9: ='ELECT BOQ'!B163 -> UPS SYSTEM | C9: ='ELECT BOQ'!F167 -> 0
A10: E | B10: ='ELECT BOQ'!B169 -> EARTHING SYSTEM | C10: ='ELECT BOQ'!F200 -> 0
A11: F | B11: ='ELECT BOQ'!B202 -> LIGHTNING PROTECTION SYSTEM | C11: ='ELECT BOQ'!F234 -> 0
A12: G | B12: ='ELECT BOQ'!B236 -> INSTALLATION OF EXTERNAL/ LANDSCAPE LIGHTING | C12: ='ELECT BOQ'!F278 -> 0
A13: H | B13: ='ELECT BOQ'!B280 -> ELECTRIC VEHICLE CHARGER | C13: ='ELECT BOQ'!F292 -> 0
A14: I | B14: ='ELECT BOQ'!B294 -> HV INSTALLATION | C14: ='ELECT BOQ'!F352 -> 0
A15: J | B15: ='ELECT BOQ'!B354 -> SUPPLY & INSTALLATION OF LT PANELS | C15: ='ELECT BOQ'!F915 -> 0
A16: K | B16: ='ELECT BOQ'!B918 -> EXTERNAL PIPE WORK | C16: ='ELECT BOQ'!F927 -> 0
B18: TOTAL | C18: =SUM(C6:C17) -> 0
B20: Exclusion
A21: 1 | B21: Supply of external light fixtures
A22: 2 | B22: Supply of Internal lighting fixtures
A23: 3 | B23: Elevators
A24: 4 | B24: eLV/ CCTV/ ACS / AV system
A25: 5 | B25: Civil work

Sheet ELECT BOQ
A1: DETAILED BOQ FOR INTERNAL ELECTRICAL WORKS
A3: S. No. | B3: Description | C3: Unit | D3: Qty. | E3: Rate | F3: Amount
A5: 1 | B5: INTERNAL ELECTRICAL WORK
A7: A | B7: CIRCUIT CUM POINT WIRING
A8: 1 | B8: Wiring for the following light/ceiling fan/exhaust fan points with 1.5 sq.mm (including circuit wiring) PVC insulated FRLS copper conductor 1100 volts grade stranded flexible wires of approved make in concealed/ surface 25 mm dia heavy duty PVC conduit including providing and fixing of 6 amps single pole rocker operated flush mounted modular switch of approved quality, colour, make and design in 1.2 mm thick GI box and earthing of fixtures and the outlet box with 1.5 sq.mm PVC insulated FRLS copper conductor stranded flexible wire.
A9: a | B9: Primary points | C9: Pts | D9: 30 | F9: =E9*D9 -> 0
A10: b | B10: Loop points | C10: Pts | D10: 10 | F10: =E10*D10 -> 0
F11: =E11*D11 -> 0
A12: 2 | B12: Wiring for the following dimmer module controlled light points with 1.5 sq.mm (including circuit wiring) PVC insulated FRLS copper conductor 1100 volts grade stranded flexible wires of approved make in concealed/surface FRLS heavy duty PVC conduit with approved quality, colour, make and design and earthing of fixtures 1.5 sq.mm PVC insulated FRLS copper conductor stranded flexible wire. (Includes DALI and analogue circuits) | C12: Pts | D12: RO
F13: =E13*D13 -> 0
A14: 3 | B14: Wiring for following 250 volts single phase and neutral 20 amps switched socket outlet and one light point (bulkhead) for lift shafts with 4 sq.mm PVC insulated FRLS copper conductor 1100 volts grade stranded flexible wires in concealed 25 mm dia stove enamled black MS conduit including providing and fixing of 16 amps 3 pin switched socket of approved make and design in 1.2 mm thick GI boxes with grid plates and earthing of third pin of socket outlet and GI box with 4 sq.mm PVC insulated FRLS copper conductor stranded flexible wire for following sets(point for lift shaft): (Cost of MCB/ bulk head light fixture not to be included) | F14: =E14*D14 -> 0
A15: a | B15: Three sets of above controlled by one 20 A SP MCB in DB | C15: Pts. | D15: 2 | F15: =E15*D15 -> 0
A16: b | B16: Four sets of above controlled by one 20 A SP MCB in DB | C16: Pts. | D16: 2 | F16: =E16*D16 -> 0
F17: =E17*D17 -> 0
A18: 4 | B18: Wiring for light point as in item No. A-1 above but controlled by SPMCB provided in the DB. (Cost of MCB not to be included here). | F18: =E18*D18 -> 0
A19: a | B19: Primary points | C19: Pts | D19: 30 | F19: =E19*D19 -> 0
A20: b | B20: Loop points | C20: Pts | D20: 300 | F20: =E20*D20 -> 0
F21: =E21*D21 -> 0
A22: 5 | B22: Wiring for the twin control light points with 1.5 sq. mm PVC insulated FRLS copper conductor 1100 volts grade stranded flexible wires in concealed 25mm dia heavy duty PVC conduit including providing and fixing 2 No. 6 amps 2 way rocker operated flush mounted modular switches of approved quality & colour make and design in 1.2 mm thick GI box and earthing of fixture & the outlet box with 1.5 Sq.mm PVC insulated FRLS copper conductor stranded flexible wire. | F22: =E22*D22 -> 0
A23: a | B23: Primary point | C23: Pts. | D23: RO
A24: b | B24: Loop point | C24: Pts. | D24: RO
F25: =E25*D25 -> 0
A26: 6 | B26: Wiring for 250 volt single phase and neutral 6 amps switch socket outlet with 2.5 sq.mm PVC insulated FRLS copper conductor 1100 volts grade stranded flexible wires in concealed/ surface 25 (including circuit wiring) mm dia heavy duty PVC conduit, including providing and fixing of 6 amps 3 pin switched socket of approved make colour and design in 1.2 mm thick GI box with grid plate and earthing of third pin of the socket outlet and the GI box with 2.5 Sq.mm FRLS copper conductor stranded flexible wire. | C26: Pts. | D26: 90 | F26: =E26*D26 -> 0
F27: =E27*D27 -> 0
A28: 7 | B28: Wiring for 250 volt single phase and neutral 6/13 amps universal switch socket outlet with 2.5 sq.mm PVC insulated FRLS copper conductor 1100 volts grade stranded flexible wires in concealed/ surface 25 (including circuit wiring) mm dia heavy duty PVC conduit, including providing and fixing of 6 amps 3 pin switched socket of approved make colour and design in 1.2 mm thick GI box with grid plate and earthing of third pin of the socket outlet and the GI box with 2.5 Sq.mm FRLS copper conductor stranded flexible wire. | C28: Pts. | D28: 275 | F28: =E28*D28 -> 0
F29: =E29*D29 -> 0
A30: 8 | B30: Wiring for 250 volts single phase and neutral 6/16 amps switched socket outlet with 4 sq.mm (including circuit wiring) PVC insulated FRLS copper conductor 1100 volts grade stranded flexible wires in concealed/ surface 25 mm dia heavy duty PVC conduit, including providing and fixing of 6/16 amps 5 pin switched socket of approved make and design in 1.2 mm thick GI boxes with grid plates and earthing the third pin of socket outlet with 2.5 Sq. mm PVC insulated FRLS copper conductor stranded flexible wire. | C30: Pts. | D30: 26 | F30: =E30*D30 -> 0
F31: =E31*D31 -> 0
A32: 9 | B32: Wiring for 250 volts single phase and neutral 6/16 amps weather proof switched socket outlet with 4 sq.mm (including circuit wiring) PVC insulated FRLS copper conductor 1100 volts grade stranded flexible wires in concealed/ surface 25 mm dia heavy duty PVC conduit, including providing and fixing of 6/16 amps 5 pin switched socket of approved make and design in 1.2 mm thick GI boxes with grid plates and earthing the third pin of socket outlet with 2.5 Sq. mm PVC insulated FRLS copper conductor stranded flexible wire. | C32: Pts. | D32: 2 | F32: =E32*D32 -> 0
F33: =E33*D33 -> 0
A34: 10 | B34: Wiring for 250 volts single phase and neutral 16 amps switched socket outlet with 4 sq.mm (including circuit wiring) PVC insulated FRLS copper conductor 1100 volts grade stranded flexible wires in concealed/ surface 25 mm dia heavy duty PVC conduit, including providing and fixing of 16 amps 3 pin switched socket of approved make and design in 1.2 mm thick GI boxes with grid plates and earthing the third pin of socket outlet with 2.54 Sq. mm PVC insulated FRLS copper conductor stranded flexible wire. Switch to be installed at +1050mm FFL and socket to be provided at +2200mm FFL. (For AC Split unit) | C34: Pts. | D34: 2 | F34: =E34*D34 -> 0
F35: =E35*D35 -> 0
A36: 11 | B36: Wiring for 250 volts single phase and neutral 16 amps switched socket outlet with 4 sq.mm (including circuit wiring) PVC insulated FRLS copper conductor 1100 volts grade stranded flexible wires in concealed/ surface 25 mm dia heavy duty PVC conduit, including providing and fixing of 16 amps 3 pin switched socket of approved make and design in 1.2 mm thick GI boxes with grid plates and earthing the third pin of socket outlet with 2.5 Sq. mm PVC insulated FRLS copper conductor stranded flexible wire. . | C36: Pts. | D36: 38 | F36: =E36*D36 -> 0
F37: =E37*D37 -> 0
A38: 12 | B38: Wiring for 250 volts single phase and neutral 20 amps Industrial type polycarbonate switched socket outlet with 4 sq.mm (including circuit wiring) PVC insulated FRLS copper conductor 1100 volts grade stranded flexible wires in concealed/ surface 25 mm dia heavy duty PVC conduit/ cable tray/ raceway, including providing and fixing of 20 amps 3pin switched socket of approved make and design in 1.2 mm thick GI boxes with grid plates and earthing the third pin of socket outlet with 2.5 Sq. mm PVC insulated FRLS copper conductor stranded flexible wire. (For EV charger for 2 wheelers) | C38: Pts. | D38: 7 | F38: =E38*D38 -> 0
F39: =E39*D39 -> 0
A40: 13 | B40: Wiring for 250 volts single phase and neutral 25 amps Industrial type polycarbonate switched socket outlet with 6 sq.mm (including circuit wiring) PVC insulated FRLS copper conductor 1100 volts grade stranded flexible wires in concealed/ surface 25 (including circuit wiring) mm dia heavy duty PVC conduit, including providing and fixing of 25 amps 3pin switched socket of approved make and design in 1.2 mm thick GI boxes with grid plates and earthing the third pin of socket outlet with 4 Sq. mm PVC insulated FRLS copper conductor stranded flexible wire. (For IT main Server Rack) | C40: Pts. | D40: 4 | F40: =E40*D40 -> 0
F41: =E41*D41 -> 0
A42: 14 | B42: Supply, installation, testing and commissioning of following PVC insulated FRLS copper conductor 1100 volt grade stranded flexible wire in heavy duty PVC conduit for circuit wiring including providing and fixing of conduits concealed or surface mounted including green colour with yellow band copper wire for earthing and making connections complete. (Submain/Circuit wiring required other than the items mentioned in BOQ) | F42: =E42*D42 -> 0
A43: a | B43: 2 X 1.5 sq. mm + 1 X 1.5 sq. mm earth wire | C43: RM | D43: RO
...
