Workbook

Sheet Master Summary
A1: Category | B1: Amount (in INR)
A2: C&I | B2: ='C&I BOQ'!$F$346 -> 0
A3: HVAC | B3: ='HVAC Summary'!$D$9 -> 0
A4: MV | B4: ='MV Summary'!$C$11 -> 0
A5: LV | B5: ='LV Summary'!$C$5 -> 0
A6: Sub - Total | B6: =SUM(B2:B5) -> 0
A7: GST @ 18% | B7: =B6*18% -> 0
A8: Labor Cess @ 1% | B8: =B6*1% -> 0
A9: Grand Total | B9: =B6+B7+B8 -> 0

Sheet C&I BOQ
A1: C&I BOQ FOR CINEPOLIS
A2: PROJECT NAME & CITY - K MALL, JODHPUR | C2: ID - Sand ID
A4: Notes: 1. Unless otherwise specified in the item description all Plywood for furniture, carpentry & associated works shall be Powder Free, Termite & Borer Resistant, BWP Grade Marine Plywood conforming to IS:710:1976 standards and list of approved makes. 2. All flooring to be protected with 3mm thk MDF of size 8' x 4' of with tape on joints not leaving any surface exposed. No extra item to be considered for protection of all flooring area. In case of any wear and tear this has to be redone. Flooring should be protected at all times. 3. Contractor to submit detailed rate analysis of all items once order confirmed. 4. All wooden and ply surfaces whose finishes have not been prescribed are to be painted in anti corrosive paint black Japan along with anti-termite treatment. 5. For items supplied by Cinepolis - The contractor shall be provided with 10% extra quantity of the material than needed as per the quantity area. Any material required above it shall be provided to the contractor at his own cost. The contractor has to make his own queries regarding the same before finalizing the contract. 6. Quality Assessment / Quality Check System: The Contractor shall allow for providing and implementing a QA/QC system to meet international standards and to the approval of Cinepolis. 7. Works at all heights / depths or floor levels and constrained locations should be considered in the item rates, it includes necessary framing and MS scaffolding required to execute all items as per BOQ. 8. Any addition in quantities from BOQ needs to be certified by Cinepolis before execution and maximum six weeks after site mobilization. 9. Measurements for billing shall be made for finished dimensions as per actual execution specified for the work and not as per quantities mentioned in the BOQ. 10. Supply of well seasoned timber, free from knots, cracks and other defects must be considered in item rate. 11. Submission of shop drawings wherever required should be considered within 5-7 days for approval from Cinépolis. Once the shop drawings is approved, it will be considered that site conditions were verified by GC. 12. Contractor should submit all the material samples (to be supplied by him) for approval from Cinepolis before procurement and maximum two weeks after site mobilization. 13. Vendor should submit all RFI's for any queries regarding the design within maximum two weeks from RFP being floated. 14. All screws visible on final finished surface must be with duco paint matching to the surface. 15. Protection for flooring (with MDF sheet), wall finishes, chairs etc. must be considered at all time. No extra item to be considered for protection. In case of any wear and tear this has to be redone without any additional cost. 16. For all the dismantling activities, contractor must consider disposal of unserviceable material and cleaning up site. 17. Rates for all items in this BOQ must be quoted with reference to relevant tender drawings. 18. General lighting to be considered in all areas in all times without any additional cost. 19. For any request of Specification change, GC to consider 10-15 days for approval from Cinepolis. 20. Carting away debris at area designated by Cinepolis site team and cleaning up site to be considered. 21. All areas which are to be retained must be protected at all times without any additional cost.
A6: S. No. | B6: ITEM DESCRIPTION | C6: UNIT | D6: QUANTITY | E6: RATE | F6: AMOUNT
A8: 1 | B8: DISMANTLING WORKS
A9: 1.01 | B9: Dismantling of masonry including interior finishes on walls Dismantling of existing brickwork/ block work (all thickness) inclusive of dado/ wall/ and cement plaster, wall panelling, decorative element, LED screens, Poster cases, signages, door with frames, etc. till the structural member. This also includes protection of all retained elements (adjoining surfaces, base structure and MEP services), carting away debris, cleaning up site and termination of MEP services as applicable, etc. complete. Refer drawing. | C9: Sqm | D9: 10 | F9: =E9*D9 -> 0
B10: MEASUREMENT METHOD : Shall be measured along the surface area (one side).
A12: =A9+0.01 -> 1.02 | B12: Dismantling of existing wall tile Dismantling of existing wall tile till the structural member or masonry wall as applicable, including the removal of base mortar etc. This also includes protection of all retained elements (adjoining surfaces, base structure and MEP services), carting away debris, cleaning up site and termination of MEP services as applicable, etc. complete. Refer drawing. | C12: Sqm | D12: RO | E12: 0 | F12: 0
B13: MEASUREMENT METHOD : Shall be measured along the surface area.
A16: =A12+0.01 -> 1.03 | B16: Dismantling of False Ceiling Dismantling of existing lobby false ceiling and ceiling sections till the structural member including light fixtures, speakers, beam detectors, fire sprinklers, grills, diffuser, cassette AC, etc. This also includes protection of all retained elements (adjoining surfaces, base structure and MEP services), carting away debris, cleaning up site and termination of MEP services as applicable, etc. complete. Refer drawing. | C16: Sqm | D16: RO | E16: 0 | F16: 0
B17: MEASUREMENT METHOD : Shall be measured along the surface area in plan.
A20: =A16+0.01 -> 1.04 | B20: Dismantling of existing tile flooring Dismantling of existing tile flooring and skirting without damaging the structural slab or the PCC underlay. This also includes protection of all retained elements (adjoining surfaces, base structure and MEP services), carting away debris, cleaning up site and termination of MEP services as applicable, etc. complete. Refer drawing. | C20: Sqm | D20: RO | E20: 0 | F20: 0
B21: MEASUREMENT METHOD : Shall be measured along the surface area in plan
A24: 2 | B24: CIVIL WORKS
A25: 2.01 | B25: 115mm thick Brickwork Providing and laying 115mm thick partition wall with well burnt good quality of first class designation 75 in cement mortar 1:4 (1cement: 4 coarse sand) including providing 2 Nos of 6mm dia MS round bars at every IV th course, including curing rubbing the surface, racking out joints at all levels/ height, including chicken mesh at the junction of RCC & masonry, trowelling, finishing smooth. This item also includes 12 - 15 mm thick plaster 1:4:2 (1cement : 4 fine sand : 2 coarse sand) on both sides in etc. complete. Refer drawings. | C25: Sqm | D25: RO | E25: 0 | F25: 0
B26: MEASUREMENT METHOD : Shall be measured along the surface area (one side).
A28: =A25+0.01 -> 2.02 | B28: 230mm thick Brickwork Providing and laying 230mm thick brick wall with well burnt good quality, class designation 75 in cement mortar 1:4 (1cement : 4 coarse sand) including, curing, rubbing the surface, racking out the joints at all levels/ height, including chicken mesh at the junction of RCC & masonry, trowelling, finishing smooth. This item also includes 12 - 15 mm thick plaster 1:4:2 (1cement : 4 fine sand : 2 coarse sand) on both sides in etc. complete. Refer drawings. | C28: cum | D28: 5 | F28: =E28*D28 -> 0
B29: MEASUREMENT METHOD : Shall be measured the along the volume (combined with wall thickness).
A31: =A28+0.01 -> 2.03 | B31: 200mm thick AAC Block Providing and laying 200mm thk AAC blocks with cement mortar 1:4 (1cement:4 coarse sand) including RCC lintel with necessary reinforcement at every 1.0mtr level. including, curing, rubbing the surface, racking out the joints at all levels/ height, including chicken mesh at the junction of RCC & masonry, trowelling, finishing smooth. The plaster shall be adequately cured. This item also includes 12 - 15 mm thick plaster 1:4:2 (1cement : 4 fine sand : 2 coarse sand) on both sides, etc. complete. Refer drawings. | C31: cum | D31: RO | E31: 0 | F31: 0
B32: MEASUREMENT METHOD : Shall be measured the along the volume (combined with wall thickness).
A34: =A31+0.01 -> 2.04 | B34: Cement Plaster Providing & applying 12-15 mm thick Plaster in plum, line and level to internal walls, columns etc at all levels/ height, in cement sand mortar 1:4 using screened sand, including scaffolding, stagging, curing, trowelling, finishing smooth, etc. complete. Refer drawings. | C34: Sqm | D34: 20 | F34: =E34*D34 -> 0
B35: MEASUREMENT METHOD : Shall be measured along the surface area.
A37: =A34+0.01 -> 2.05 | B37: Lintel for opening Providing and laying in position Reinforced cement concrete work in lintels, including the cost of centring, shuttering, finishing and reinforcement with M25 grade concrete and 12mm dia steel bar. Size of lintel should be 150mm high and width should be as per wall thickness and length should be the width of opening and 150mm bearing on both sides. The item includes laying of lintel in existing blockwork as well, etc. complete. Refer drawings. | C37: cum | D37: 1 | F37: =E37*D37 -> 0
B38: MEASUREMENT METHOD : Shall be measured the volume (combined with RCC thickness).
A40: =A37+0.01 -> 2.06 | B40: Screeding (20 to 50mm thick) Providing and laying M10 PCC floor screeding of general level to lay floor tiles/stones above with an approximate thickness of 20mm to 50mm using cement concrete 1:3:6 (1cement : 3coarse sand : 6 graded stone,down gauge), including tamped, spaded , trowelled and top finished neat. Top surface should be finished neat and smooth and laid to water levels or proper slopes as directed, curing, etc. complete. Refer drawings. | C40: Sqm | D40: 840 | F40: =E40*D40 -> 0
B41: MEASUREMENT METHOD : Shall be measured along the surface area in plan
A43: =A40+0.01 -> 2.07 | B43: Screeding (50 to 75mm thick) Providing and laying M10 PCC floor screeding of general level to lay floor tiles/stones above with an approximate thickness of 50mm to 75 mm using cement concrete 1:3:6 (1cement : 3coarse sand : 6 graded stone,down gauge), including tamped, spaded , trowelled and top finished neat. Top surface should be finished neat and smooth and laid to water levels or proper slopes as directed, curing etc, complete. Refer drawings. | C43: Sqm | F43: =E43*D43 -> 0
B44: MEASUREMENT METHOD : Shall be measured along the surface area in plan
A46: =A43+0.01 -> 2.08 | B46: Waterproofing Providing and laying in situ 25mm thick (average) seven course water proofing treatment with APP (Atactic poly-propylene) modified Polymeric membranes over roof consisting of first coat of bitumen primer @ 0.40 Kg per sqm, 2nd, 4th & 6th courses of bonding material @ 1.20 Kg/sqm, which shall consist of blown type bitumen of grade 85/25 conforming to IS : 702, 3rd and 5th layers of roofing membrane APP modified Polymeric membrane 1.5 mm thick of 2.25 Kg/sqm weight consisting of five layers prefabricated with centre core as 20 micron HMHDPE film sandwiched on both sides with polymeric mix and the polymeric mix is protected on both side with 20 micron HMHDPE film. 7th, the top most layer shall be finished with cement mortar 1:3 (1cement : 3 fine sand) mixed with 2% integral water proofing compound by weight of cement over a 12 mm layer of cement mortar 1:3 (1 cement : 3 fine sand) and finished neat, etc. complete. Refer drawings. | C46: Sqm | D46: =[1]TOS!R42*1.05 -> 321.3 | F46: =E46*D46 -> 0
B47: MEASUREMENT METHOD : Shall be measured along the surface area.
A49: =A46+0.01 -> 2.09 | B49: Cement based levelling compound Providing and laying of cement based levelling compound Ardex CL 11 with primer T-51 in two coats of 2mm as per ardex specification. Rate to include for all necessary tools & tackles, labour etc all complete. Refer drawings. | C49: Sqm | D49: 20 | F49: =E49*D49 -> 0
B50: Brand: Ardex Code: CL 11 with primer T-51
B51: MEASUREMENT METHOD : Shall be measured along the surface area in plan.
A53: 3 | B53: FLOORING WORKS
A54: 3.01 | B54: Vitrified Tile Flooring Providing and fixing vitrified tiles over 20 mm thick bed of cement mortar 1:4 (1 cement : 4 coarse sand) and jointing with grey cement slurry @3.3kg per sqm including pointing in white cement mixed with pigment of matching shade to tile. Tile joints to be finished in white cement mixed with pigment of matching shade of tile. Tile to be layed as per pattern/ design and multiple start points as shown in the drawing. In case of any damage to tiles due to other construction activities or removal of protection; contractor must replace the affected tiles at his own cost. Rate to include cutting, wastage, cost of all materials and all necessary activities, etc. complete. Refer drawings.
A55: 3.01.01 | B55: Database Code: C010827 Brand: AGL Model: Tropic Brown (Double glazed tile) Finish: Glossy Size :600 x 600mm Thickness: 8.5 mm | C55: Sqm | D55: 99 | F55: =E55*D55 -> 0
A56: 3.01.02 | B56: Database Code: C000103 / C2030.20/G/0208 Brand: Somany Model: FB Dusky S&P Crema Colour: Matt Finish: anti- skid Size : 600x600mm Thickness: 10mm | C56: Sqm | D56: =[1]TOS!R730*1.05 -> 117.6 | F56: =E56*D56 -> 0
A57: 3.01.03 | B57: Database Code: C010778 Brand: Orient Bells Model: CN Armani Grey LT Color : Dark Grey Finish: Glossy Size : 600 X 1200mm Thickness: 10mm | C57: Sqm | D57: RO | E57: 0 | F57: 0
A58: 3.01.04 | B58: Database Code: C000236 Brand: Kajaria Model: Toronto blanco Finish: Glossy Size: 300 x 450mm Thickness: 10mm | C58: Sqm | D58: =[1]TOS!$R$734 -> 4 | F58: =E58*D58 -> 0
A59: 3.01.05 | B59: Database Code: C000138 Brand: Kajaria Model: Kajaria pvt K6306 Finish: Glossy Size : 600 X 600mm | C59: Sqm | D59: =[1]TOS!R737*1.05 -> 93.45 | F59: =E59*D59 -> 0
...

Sheet HVAC Summary
A1: SUMMARY OF COSTS FOR HVAC WORKS FOR CINEPOLIS AT K MALL-JODHPUR
A3: Sr.No. | B3: Description | C3: Unit | D3: Amount
A5: 1 | B5: TOTAL FOR AIR DISTRIBUTION SYSTEM | C5: Rs. | D5: ='HVAC BOQ'!$K$127 -> 0
A7: 2 | B7: TOTAL FOR INSULATION | C7: Rs. | D7: ='HVAC BOQ'!$K$146 -> 0
B9: TOTAL | C9: Rs. | D9: =SUM(D5:D8) -> 0

Sheet HVAC BOQ
A1: SCHEDULE OF QUANTITIES FOR LOW SIDE HVAC WORKS FOR CINEPOLIS AT K MALL,JODHPUR
A2: SR. NO. | B2: DESCRIPTION | C2: Area 1 Qty | D2: Area 2 Qty | E2: Area 3 | F2: Total Qty | G2: UNIT | H2: Rate Supply | I2: Rate Install | J2: Total Rate | K2: AMOUNT (Rs)
A3: [B] | B3: AIR DISTRIBUTIONS SYSTEM
A4: 1 | B4: GSS SHEET METAL DUCT: FACTORY FABRICATED
B5: Supply, Fabrication, Installation and Testing of GSS metal ducts as per IS-277 (120 GSM both sides, LFQ & confirming to Class VIII) for GS Sheets and IS-655 for fabrication of following thicknesses including necessary G.I. hangers / supports, volume control duct dampers, accessories, vanes, 3mm neoprene rubber gasket etc. complete as per specifications in accordance with the approved shop drawings. (Ducts to be sent in Prefabricated form at the jobsite. Site work will include assembly, installation and suit to site pieces and collars/droppers.)
B6: No slip joints shall be allowed. Flanges shall be MS angle flnges / Rolamate with fire retardant gasket 5mm thk. All ducts shall be with rigid supports as per technical specifications.
B7: a) GI sheet ducts with reinforcement/Strengthening
B8: b) Air tight joints
B9: c) Accessories such as splitter damper, guide vane etc.
B10: d) Hangers and supports
B11: e) 2 coats of black paint for sa ducts after insulation
A12: a | B12: 24 gauge (0.63mm) | D12: 510 | G12: sqm | J12: 0 | K12: =J12*D12 -> 0
A13: b | B13: 22 gauge (0.8mm) | D13: 1950 | G13: sqm | J13: 0 | K13: =J13*D13 -> 0
A14: c | B14: 20 gauge (1.0mm) | D14: 110 | G14: sqm | J14: 0 | K14: =J14*D14 -> 0
A15: 1.2 | B15: Supply, Fixing & welding works required additional for duct support in MS frame work duly painted with 2 or more coat of enamal paint, as required complete in all respect (for Theatres) | D15: RO | G15: Kg | J15: 0
A17: =A4+1 -> 2 | B17: FLEXIBLE DUCTS (for Projection Exhaust)
B18: Supply, Installation, Testing and Commissioning of insulated flexible ducts. The insulated flexible duct shall have inner core made of double lamination of metalized polyster film permenantly bonded to a coated spring stel wire helix. Fibreglass insulation of minimum 14 kg.cu.m. density having a R-value 4.2oF-Ft2-hr/btu and 25 mm thk shall be wrapped over the inner core and covered with stronger outer jacket cum vapor barrier made of fibreglass reinforced metalized polyester film laminate. The insulated flexible duct should be fire retardant type.
B19: The insulated flexible duct should be fire retardant type. Limit Flexible Duct to not more than 3 Ft Length
A20: a | B20: Insulated Flexible ducts of 200 mm dia | D20: 0 | G20: RMT | J20: 0 | K20: =D20*J20 -> 0
A21: b | B21: Insulated Flexible ducts of 300 mm dia | D21: 0 | G21: RMT | J21: 0 | K21: =D21*J21 -> 0
A23: =A17+0.1 -> 2.1 | B23: FLEXIBLE CONNECTION:
B24: Supply, fabrication & installation of double canvass (fire retardant) flexible connection as per drawings & specifications. [for Fans & AHUs] | D24: 25 | G24: sqm | J24: 0 | K24: =J24*D24 -> 0
A26: =A17+1 -> 3 | B26: VOLUME CONTROL DAMPER:
B27: Supply, Installation and adjusting of GSS Volume Control Damper within ducts complete with suitable links, levers. Blades should be double skinned aerofoil construction and opposed blades should be at 50mm pitch centres. The blades should be mounted in nylon bushes operated by an interior wheel gear system. Manual quadrant control with position indicator to be provided to enable adjust volume of air as required. | D27: 15 | G27: sqm | J27: 0 | K27: =J27*D27 -> 0
A29: 3.1 | B29: Back Draft Dampers
B30: Supply, installation, testing and commissioning of 16 G GSS Back draft dampers models shall be designed to allow exhaust airflow but prevent airflow in the reverse direction & shall be of counterweight type & normally in shut-off position. | D30: 15 | G30: sqm | J30: 0 | K30: =J30*D30 -> 0
A32: =A26+1 -> 4 | B32: FIRE AND SMOKE DAMPERS:
A33: 4.1 | B33: Fire & Smoke Dampers with Fusible Link
B34: Fire and Smoke Dampers (FSD) shall be installed in supply air duct when they pass through AHU room walls as shown in the drawings and as per specfications.The Fire Dampers shall be operated with atleast 90 minutes fire rating as per UL 555S - Class II for fire and smoke management rated for 90 min. & tested at CBRI Roorkee, India.
B35: Fusible Link should be rated for 72oC. Each FSD shall be of multi leaf type, low leakage and shall be tested in the factory and will be certified by the manufacturer in form of the test certificate.
B36: Each FSD shall be supplied with matching sleeve (factory supply) and set of retaining angles for installation on wall / slab as indicated on drawings.
B37: (To be installed in Supply air duct tapping to projection room-site measured) | D37: 0 | G37: sqm | J37: 0
A39: =A33+0.1 -> 4.2 | B39: Fire & Smoke Dampers with same specifications as above item 4.1 but suitable for motorised operation. (Motorised fire and smoke damper FSD is to be installed in SA & RA for all Cinema & Lobby AHU's) | D39: 20 | G39: sqm | J39: 0 | K39: =J39*D39 -> 0
A41: 4.3 | B41: Motorised Actuator
B42: The Actuator shall be direct coupled spring return type and motorised.
B43: The Actuator shall be in line with the Technical Specifications and shall be maintenance free direct coupled spring return type suitable to work on 24 V electric supply. The torque rating of the actuator shall exceed at least by 15% over torque required to open / close the damper. Shall have manual over ride facility. The selection of actuator size shall be the responsibility of the manufacturer. Power on indicating lamps with 230 V / 24 V transformer,damper close & open indication, reset push button, push button for manual running of actuator for periodic inspection, auxiliary contacts 24V & 230 V, contact points to receive signal from smoke detector / fire alarm panel etc. should be provided. | D43: 20 | G43: nos | J43: 0 | K43: =J43*D43 -> 0
A45: =+A32+1 -> 5 | B45: GRILLS & DIFFUSERS
B46: (All Grill & Diffuser Samples Shall be Approved by Services Consultants & Architects prior to procurement)
A47: =A45+0.1 -> 5.1 | B47: For Theatres (All Grills / Diffusers should be Black Mat Finish)
A48: 6.1.1 | B48: Supply Air Ceiling Distributor
...

Sheet MV Summary
A1: SECTION | B1: Description | C1: Amount
B2: RENOVATION
A3: A | B3: WIRING SYSTEM (POINT WIRING) | C3: ='Wiring System'!$F$64 -> 0
A4: B | B4: L.V.CABLES & WIRES | C4: ='Cables & Wires'!$F$132 -> 0
A5: C | B5: LT PANELS AND DISTRIBUTION BOARDS | C5: ='LT Panels and DB'!$F$100 + 'LT Panels and DB'!$F$215 -> 0
A6: D | B6: EARTHING SYSTEM | C6: ='Earthing System'!$F$46 -> 0
A7: E | B7: INSTALLATION OF LIGHT FIXTURES. | C7: ='Light Fixtures'!$F$40 -> 0
A8: F | B8: COMMUNICATION DATA AND VOICE | C8: ='Data & Voice'!$F$36 -> 0
A9: G | B9: AUDI SPEAKER SYSTEM WIRING | C9: ='Audi Speaker System Wiring'!$F$20 -> 0
A10: H | B10: TEMPORARY WORK | C10: ='Temporary Work'!$F$10 -> 0
B11: Total | C11: =SUM(C3:C10) -> 0

Sheet Wiring System
A1: PROJECT: MULTIPLEX FOR CINEPOLIS INDIA PVT. LTD
A2: 4 SCREEN MULTIPLEX AT K. MALL JODHPUR
A3: BILL OF QUANTITIES FOR ELECTRICAL WORKS
A4: SR. | B4: DESCRIPTION | C4: UNIT | D4: QTY | E4: RATE | F4: AMOUNT
A5: A | B5: WIRING SYSTEM (POINT WIRING)
B6: The following light points are done with 2R x 2.5Sqmm+ 1x1.5Sqmm FRLS wires. The cost to include - PVC LHSFT conduits, inspection bends, junction boxes with cover plates, FRLS wires, wire connectors, angle holders, flexible pipe etc inclusive of all accessories, as required for final installation of light fixtures.
A8: 1.01 | B8: Primary light point (Local control) - One light point controlled by one single way 6 A switch - length upto 8.00 mtrs. | C8: No's | D8: 30 | E8: 0 | F8: =+E8*D8 -> 0
A10: 1.02 | B10: Secondary Light point - One light point controlled by one single way 6 A switch looped from above and subsequnet loops - length upto 5.00 mtrs without switch. | C10: No's | D10: 20 | E10: 0 | F10: =+E10*D10 -> 0
A12: 1.03 | B12: Primary Light point (DB Controlled) One light point controlled by MCB directly from DB - length upto 30.00 mtrs. | C12: No's | D12: 40 | E12: 0 | F12: =+E12*D12 -> 0
A14: 1.04 | B14: Secondary Light Point One light point controlled by MCB directly from DB - looped from above and subsequent loops - length upto 5.0 mtrs. | C14: No's | D14: 180 | E14: 0 | F14: =+E14*D14 -> 0
A16: 2 | B16: POWER POINTS
B17: The following power points are done with 2R x 2.5 sq.mm + 1x1.5 Sqmm FRLS Wires. The cost to include PVC LHSFT conduits, inspection bends, junction boxes, with cover plates, FRLS wires, MS switch boxes (surface mounted/concealed), switch plates (of colours white/grey/black), switches (of colours white/grey/black) and sockets (of colours white/grey/black) as per drawings and instructions of the site incharge.
A19: 2.1 | B19: Primary Power Point - One 6 A x 5 pin 230 volt socket outlet point controlled by one 6 A switch located on switch board length upto 10.0 mtrs. | C19: No's | D19: 35 | E19: 0 | F19: =+E19*D19 -> 0
A21: 2.2 | B21: Secondary Power point One 6 A x 5 pin 230 volt socket outlet point controlled by one 6 A switch located on switch board length upto 5.0 mtrs. | C21: No's | D21: 75 | E21: 0 | F21: =+E21*D21 -> 0
A23: 2.3 | B23: Two 6 A x 5 pin 230 volt socket outlet point controlled by Two 6 A switch located on switch board length upto 10.0 mtrs. | C23: No's | D23: RO | E23: 0
A25: 3 | B25: The following power points are done with 2R x 4.0 sq.mm + 1x2.5 Sqmm FRLS Wires. The cost to include PVC LHSFT conduits, inspection bends, junction boxes, with cover plates, FRLS wires, MS switch boxes (surface mounted/concealed), switch plates (of colours white/grey/black), switches 6/16A (of colours white/grey/black) and sockets 6/16A (of colours white/grey/black) as per drawings and instructions of the site incharge.
A27: 3.01 | B27: Primary Power point One 6/16 A x 5 pin 230 volt socket outlet point controlled by one 16 A switch located on switch board length upto 10.0 mtrs. | C27: No's | D27: 55 | E27: 0 | F27: =+E27*D27 -> 0
A29: 3.02 | B29: Secondary Power point One 6/16 A x 5 pin 230 volt socket outlet point controlled by one 16 A switch located on switch board length upto 5.0 mtrs. | C29: No's | D29: =60+30+20 -> 110 | E29: 0 | F29: =+E29*D29 -> 0
A31: 3.03 | B31: Two 16 A x 5 pin 230 volt socket outlet point controlled by Two 16 A switch located on switch board - primary - length upto 15.0 mtrs. | C31: No's | D31: 20 | E31: 0 | F31: =+E31*D31 -> 0
A33: 3.04 | B33: Three 16 A x 5 pin 230 volt socket outlet point controlled by Two 16 A switch located on switch board - primary - length upto 15.0 mtrs. | C33: No's | D33: RO | E33: 0
A35: 3.05 | B35: Four 16 A x 5 pin 230 volt socket outlet point controlled by Two 16 A switch located on switch board - primary - length upto 15.0 mtrs. | C35: No's | D35: RO | E35: 0
A37: 3.06 | B37: Supply & Installation of 16A, 3 pin, Industrial plug top & socket (Male/Female) PVC couplers, Single Phase with 1 Neutral & 1 Earth, & 16A IP-44 weatherproof connectors (Kitchen area) | C37: No's | D37: 18 | E37: 0 | F37: =+E37*D37 -> 0
A39: 4 | B39: CIRCUIT WIRNG - MAINS & SUB MAINS
B40: Providing and drawings mains of the following sizes of Cu. FRLS PVC insulated flexible wires with ISI and FIA approval for 650 V / 1100 V with all necessary accessories in existing/prelaid conduits and raceways.
A42: 4.01 | B42: 2x16Sqmm +1x6Sqmm | C42: mtr | D42: 0 | E42: 0 | F42: =+E42*D42 -> 0
A44: 4.02 | B44: 2x10Sqmm +1x6Sqmm | C44: mtr | D44: 0 | E44: 0 | F44: =+E44*D44 -> 0
A46: 4.03 | B46: 2x6Sqmm + 1x4Sqmm | C46: mtr | D46: 180 | E46: 0 | F46: =+E46*D46 -> 0
A48: 4.04 | B48: 2x4Sqmm + 1x2.5Sqmm | C48: mtr | D48: 550 | E48: 0 | F48: =+E48*D48 -> 0
A50: 4.05 | B50: 2x2.5Sq.mm + 1x1.5 Sq.mm | C50: mtr | D50: 600 | E50: 0 | F50: =+E50*D50 -> 0
A52: 4.06 | B52: 4x6Sqmm + 2x4Sqmm | C52: mtr | D52: 90 | E52: 0 | F52: =+E52*D52 -> 0
A54: 4.07 | B54: 4x4Sqmm + 2x2.5Sqmm | C54: mtr | D54: 90 | E54: 0 | F54: =+E54*D54 -> 0
A56: 5 | B56: Supply and Installation of Conduits with juntion boxes, bends, elbows and coupler's including metal back box for data and telephone point etc., with saddle base's, saddle's etc. fixed on the surface/concealed inside the masonry walls and surface mounted on ceiling soffits, laid over false framing etc. ( For data, voice and speaker cable)
A58: 5.01 | B58: 32mm dia, 2 mm thick PVC LHSFT conduit | C58: mtr | D58: 0 | E58: 0 | F58: 0
A60: 5.02 | B60: 25mm dia, 2 mm thick PVC LHSFT conduit | C60: mtr | D60: 3500 | E60: 0 | F60: =+E60*D60 -> 0
A62: 5.03 | B62: 19mm dia, 2 mm thick PVC LHSFT conduit | C62: mtr | D62: 5500 | E62: 0 | F62: =+E62*D62 -> 0
B64: Total cost of Section 'A' Point wiring | F64: =SUM(F6:F63) -> 0

Sheet Cables & Wires
A1: PROJECT: MULTIPLEX FOR CINEPOLIS INDIA PVT. LTD
A2: 4 SCREEN MULTIPLEX AT K. MALL JODHPUR
A3: BILL OF QUANTITIES FOR ELECTRICAL WORKS
A4: SR. | B4: DESCRIPTION | C4: UNIT | D4: QTY | E4: RATE | F4: AMOUNT
A6: B | B6: L.V.CABLES & WIRES
A8: 1 | B8: Providing, laying, testing and commissioning of 1100V grade PVC insulated PVC sheathed steel wire/ tape armoured aluminium conductor cable for mains and sub mains as per specifications and drawings. The cables shall be laid in concrete trenches or buried directly underground or on cable trays. The concrete trenches will be measured separate. The cost of the cable trays or ladders, excavation and back filling of trenches will be measured separate. the unit cost of the cable shall include clamps, fasteners etc. as required for proper installation.
B10: ALUMINIUM ARMOURED CABLE
A12: 1.01 | B12: 3.5C x 240 Sqmm A2XFY | C12: mtr's | D12: =+'[2]Cable schedule'!D94 -> 40 | E12: 0 | F12: =+E12*D12 -> 0
A14: =+A12+0.01 -> 1.02 | B14: 3.5C x 150 Sqmm A2XFY | C14: mtr's | D14: RO | E14: 0
A16: =+A14+0.01 -> 1.03 | B16: 3.5C x 95 Sqmm A2XFY | C16: mtr's | D16: =+'[2]Cable schedule'!D95+3 -> 65 | E16: 0 | F16: =+E16*D16 -> 0
A18: =+A16+0.01 -> 1.04 | B18: 3.5C x 70 Sqmm A2XFY | C18: mtr's | D18: =+'[2]Cable schedule'!D96+4 -> 35 | E18: 0 | F18: =+E18*D18 -> 0
A20: =+A18+0.01 -> 1.05 | B20: 3.5C x 50Sqmm A2XFY | C20: mtr's | D20: RO | E20: 0
A22: =+A20+0.01 -> 1.06 | B22: 3.5C x 35Sqmm A2XFY | C22: mtr's | D22: RO | E22: 0
F23: =+E23*D23 -> 0
A24: =+A22+0.01 -> 1.07 | B24: 4C x 25Sqmm A2XFY | C24: mtr's | D24: =+'[2]Cable schedule'!D98 -> 190 | E24: 0 | F24: =+E24*D24 -> 0
A26: =+A24+0.01 -> 1.08 | B26: 4C x 16Sqmm A2XFY | C26: mtr's | D26: =+'[2]Cable schedule'!D99 -> 614 | E26: 0 | F26: =+E26*D26 -> 0
B28: COPPER ARMOURED CABLE
A30: =+A26+0.01 -> 1.09 | B30: 4C x 16 Sqmm 2XWY Cable | C30: mtr's | D30: RO | E30: 0
A32: =+A30+0.01 -> 1.1 | B32: 4C x 10 Sqmm 2XWY Cable | C32: mtr's | D32: RO | E32: 0
A34: =+A32+0.01 -> 1.11 | B34: 4C x 6 Sqmm 2XWY Cable | C34: mtr's | D34: =+'[2]Cable schedule'!D101+4 -> 35 | E34: 0 | F34: =+E34*D34 -> 0
A36: =+A34+0.01 -> 1.12 | B36: 4C x 4 Sqmm 2XWY Cable | C36: mtr's | D36: =+'[2]Cable schedule'!D102 -> 595 | E36: 0 | F36: =+E36*D36 -> 0
A38: =+A36+0.01 -> 1.13 | B38: 4C x 2.5 Sqmm 2XWY Cable | C38: mtr's | D38: =+'[2]Cable schedule'!D105+4 -> 150 | E38: 0 | F38: =+E38*D38 -> 0
A40: =+A38+0.01 -> 1.14 | B40: 3C x 6 Sqmm 2XWY Cable | C40: mtr's | D40: =+'[2]Cable schedule'!D103 -> 18 | E40: 0 | F40: =+E40*D40 -> 0
A42: =+A40+0.01 -> 1.15 | B42: 3C x 4 Sqmm 2XWY Cable | C42: mtr's | D42: =+'[2]Cable schedule'!D104+7 -> 180 | E42: 0 | F42: =+E42*D42 -> 0
A44: =+A42+0.01 -> 1.16 | B44: 3C x 2.5 Sqmm 2XWY Cable | C44: mtr's | D44: RO | E44: 0
A46: =+A44+0.01 -> 1.17 | B46: 1C x 50 Sqmm YY Cable | C46: mtr's | D46: =+'[2]Cable schedule'!D106 -> 60 | E46: 0 | F46: =+E46*D46 -> 0
A48: =+A46+0.01 -> 1.18 | B48: 1C x 6 Sqmm YY Cable | C48: mtr's | D48: =+'[2]Cable schedule'!D107 -> 160 | E48: 0 | F48: =+E48*D48 -> 0
A50: =+A48+0.01 -> 1.19 | B50: PRIMARY POINT 2C X 4 Sq. mm - LED DRIVER | C50: mtr's | D50: 550 | E50: 0 | F50: =+E50*D50 -> 0
A52: =+A50+0.01 -> 1.2 | B52: SECONDARY POINT 2C X 2.5 Sq. mm - LED DRIVER | C52: mtr's | D52: 450 | E52: 0 | F52: =+E52*D52 -> 0
A54: 2 | B54: Supply & Installing cable terminations for the below cables including Double compression suitable glands and lugs(crimping type), PVC taping as required and all accessories complete. (For aluminium cable, Aluminium Glands & lugs to be used. For copper cables, glands & lugs will be copper) ( The rate shall include gland earthing also.)
B55: ALUMINIUM ARMOURED CABLE | F55: 0
A56: 2.01 | B56: 3.5C x 240 Sqmm A2XFY | C56: Nos | D56: 4 | E56: 0 | F56: =+E56*D56 -> 0
A58: =+A56+0.01 -> 2.02 | B58: 3.5C x 150 Sqmm A2XFY | C58: Nos | D58: 8 | E58: 0 | F58: =+E58*D58 -> 0
A60: =+A58+0.01 -> 2.03 | B60: 3.5C x 95 Sqmm A2XFY | C60: Nos | D60: 2 | E60: 0 | F60: =+E60*D60 -> 0
A62: =+A60+0.01 -> 2.04 | B62: 3.5C x 70 Sqmm A2XFY | C62: Nos | D62: RO | E62: 0
A64: =+A62+0.01 -> 2.05 | B64: 3.5C x 50Sqmm A2XFY | C64: Nos | D64: 2 | E64: 0 | F64: =+E64*D64 -> 0
A66: =+A64+0.01 -> 2.06 | B66: 3.5C x 35Sqmm A2XFY | C66: Nos | D66: 2 | E66: 0 | F66: =+E66*D66 -> 0
A68: =+A66+0.01 -> 2.07 | B68: 4C x 25Sqmm A2XFY | C68: Nos | D68: RO | E68: 0
A70: =+A68+0.01 -> 2.08 | B70: 4C x 16Sqmm A2XFY | C70: Nos | D70: 44 | E70: 0 | F70: =+E70*D70 -> 0
B72: COPPER ARMOURED CABLE
...

Sheet LT Panels and DB
A1: PROJECT: MULTIPLEX FOR CINEPOLIS INDIA PVT. LTD
A2: 4 SCREEN MULTIPLEX AT K. MALL JODHPUR
A3: BILL OF QUANTITIES FOR ELECTRICAL WORKS
A4: SR. | B4: DESCRIPTION | C4: UNIT | D4: QTY | E4: RATE | F4: AMOUNT
A6: C | B6: LT PANELS AND DISTRIBUTION BOARDS
B7: Supply, installation, testing and commissioning of M.V.Distribution Boards suitable for 415V, 3 ph, 4 wire, 50Hz distribution system. The panel shall be free standing, floor mounting, sheet metal enclosed, flush front with aluminium busbars, separate earth bus shall be provided throughout the length of the panel. The incoming and the outgoing feeder breakers, switch fuse units, change over switches, indicating lamps, meters etc. shall be accommodated in a modular multi tier arrangement. A minimum of 400mm clearance shall be given from the floor level to the bottom most termination point. The painting shall be done in conformity with IS code. Adequate size cable alley shall be provided all round the panel and at the back for easy bending and terminations. The outgoing feeders inside the panel shall be connected through solid busbars. Flexible cable links are not acceptable. Busbars shall be provided with PVC heat shrinkable sleeves or heat resistant insulated paint. The panels shall be suitable for cable entry from top. The copper earth strip of minimum 25mm x 3mm shall run throught out the length of the top / bottom of the panel ( All MCCB'c are Thermal magnetic released MCCB'S), All the MCCB,s should have rotary handle ( RHOM))
B9: General Notes:
A10: a | B10: The construction of the panel shall comply to latest standards of IEC 61439.
A11: b | B11: The Panel shall be fully as per the requirement of Electrical Inspectorate/ CEIG authorities.
A12: c | B12: Auxilliary contactor to be provided along with auto-manual switch .
A13: d | B13: All doors to have double rubber gasket with shutter assembly & door seating frame.
A14: e | B14: Any panel if more than 2.5 mts width should be made in parts each part not exceeding 2.5mts
A15: f | B15: All UPS outgoing panels shall have neutral busbars double the size of phase.
A16: g | B16: Breaker terminal connections from the dropper bus shall be through only Al/Cu. bus to be used.
A17: h | B17: The Bus bars and connectors should have extruded insulation
A18: i | B18: Base frame shall be with each panel. The size will be equal to each section.
A19: j | B19: Bi-metallic tape / washers to be used where ever copper & Aluminium are joined.
A20: k | B20: Auto-Manual switch shall be provided for all motorised breakers.
A21: l | B21: All the DB's should be installed with suitable cable end boxes or suitable frames.
... A26: q | B26: Prior ordering any items contractor has to take approval from Cinepolis Site/Project incharge.
A28: 1.1 | B28: MAIN DISTRIBUTION PANEL-MDB ( Refer SLD 1 ) Indoor | C28: SET | D28: 1 | E28: 0 | F28: =IFERROR(+E28*D28,0) -> 0
B29: Incommer -1 / Incommer - 2
B30: 1000A TPN 50 kA ACB microprocessor based O/L, S/C and E/F release-2 Set
B31: Breaker ON / OFF / TRIP indicating lamps with suitable rating control SP MCB - 2 Set
B32: RYB phase indicating lamps with suitable rating control SP MCB - 2 Set
B33: CT 1000/5A 15 VA, CL.1- 3 Nos+ 1 No. 1000/5A CT for RTPFC panel (Provision)
B34: MFM with RS-485 port- 2 Set (parameters V, I, Hz, KWH, PF, KW, KVAR, max. demand KW)
B35: Incomer 1 & 2 to be interlocked electromechanically.
B36: Outgoing
B37: 630A FP MCCB, 25kA Thermal magnetic based O/L, S/C release- 1 Set with CT & KWH meter
B38: 160A FP MCCB, 25kA thermal magnetic based O/L, S/C release- 3 Set with CT & KWH meter
B39: 125A FP MCCB, 25kA thermal magnetic based O/L, S/C release- 1Set with CT & KWH meter
B40: 63A FP MCB, 10kA-10 Nos with KWH meter
B41: 40A FP MCB, 10kA-4 Nos with KWH meter
A43: 1.4 | B43: UPS OUTPUT PANEL (60KVA) ( Refer SLD 2) Indoor type | C43: SET | D43: 1 | E43: 0 | F43: =IFERROR(+E43*D43,0) -> 0
B44: Incomer:-
B45: 160A FP Changeover switch- 1Set
B46: 160A FP MCCB,25kA thermal magnetic based O/L, S/C release - 1Set
B47: Metering & Protection:-
B48: Breaker ON / OFF / TRIP indicating lamps with suitable rating control SP MCB - 1Set
...

Sheet Earthing System
A1: PROJECT: MULTIPLEX FOR CINEPOLIS INDIA PVT. LTD
A2: 4 SCREEN MULTIPLEX AT K. MALL JODHPUR
A3: BILL OF QUANTITIES FOR ELECTRICAL WORKS
A4: SR. | B4: DESCRIPTION | C4: UNIT | D4: QTY | E4: RATE | F4: AMOUNT
A7: D | B7: EARTHING SYSTEM
A9: 1 | B9: Providing & fixing of earth conductor, dressing as per following sizes including its necessary end connections complete. | F9: 0
A11: 1.01 | B11: 50 x 6mm GI strip | C11: mtr | D11: 40 | E11: 0 | F11: =+E11*D11 -> 0
A13: 1.02 | B13: 50 x 3mm Cu. strip | C13: mtr | D13: 0 | E13: 0 | F13: =+E13*D13 -> 0
A15: 1.03 | B15: 50 x 3mm GI strip | C15: mtr | D15: 0 | E15: 0 | F15: =+E15*D15 -> 0
A17: 1.04 | B17: 25 x 6mm GI strip | C17: mtr | D17: 0 | E17: 0 | F17: =+E17*D17 -> 0
A19: 1.05 | B19: 25 x 3mm GI strip | C19: mtr | D19: 60 | E19: 0 | F19: =+E19*D19 -> 0
A21: 1.06 | B21: 8 S.W.G GI wire | C21: mtr | D21: 300 | E21: 0 | F21: =+E21*D21 -> 0
A23: 1.07 | B23: 1C x 70 Sqmm Cu. Ar. Cable | C23: mtr's | D23: 0 | E23: 0 | F23: =+E23*D23 -> 0
A25: 1.08 | B25: 1C x 35 Sqmm Cu.Ar. Cable | C25: mtr's | D25: 140 | E25: 0 | F25: =+E25*D25 -> 0
A27: 1.09 | B27: 1C x 25 Sqmm Cu.Ar. Cable | C27: mtr's | D27: 0 | E27: 0 | F27: =+E27*D27 -> 0
A29: 1.1 | B29: 1C x 16 Sqmm Cu. Ar.cable | C29: mtr's | D29: 0 | E29: 0 | F29: =+E29*D29 -> 0
A31: 1.11 | B31: 1C x 10 Sqmm Cu. Ar.cable | C31: mtr's | D31: 150 | E31: 0 | F31: =+E31*D31 -> 0
A33: 1.12 | B33: 1C x 95 Sqmm CU Flexible cable | C33: mtr's | D33: 0 | E33: 0 | F33: =+E33*D33 -> 0
... A45: 3 | B45: Earth Busbar Box : 300mm x 150mm x 100mm Potential Free Box with required number of earthing bushings and insulation for earth terminals | C45: No's | D45: 8 | E45: 0 | F45: =+E45*D45 -> 0
B46: Total cost of Section 'D' Earthing | F46: =SUM(F9:F45) -> 0

Sheet Light Fixtures
A1: PROJECT: MULTIPLEX FOR CINEPOLIS INDIA PVT. LTD
A2: 4 SCREEN MULTIPLEX AT K. MALL JODHPUR
A3: BILL OF QUANTITIES FOR ELECTRICAL WORKS
A4: SR. | B4: DESCRIPTION | C4: UNIT | D4: QTY | E4: RATE | F4: AMOUNT
A6: E | B6: INSTALLATION OF LIGHT FIXTURES.
B7: Installation of lighting fixtures is excluded from the scope of this tender.
A8: 1 | B8: RECESSED LED PANEL ANKUR XPERTZ ANKUR XRL (592 X 592MM); COLOUR: WHITE LIGHT ; 40W; FINISH: WHITE; 2900 LF, Code in drawing D00955 | C8: Nos | D8: 5 | E8: 0 | F8: =+E8*D8 -> 0
A10: =+A8+1 -> 2 | B10: TUBE 18W LED 6500K. SUPPLY OF LED TUBE LIGHT; 4FT; WHITE ALUMINIUM ALLOY BODY WITH PMMA COVER; BEAM ANGLE: 120°, C.R.I. >80; LIFE SPAN : 50,000 HRS. Code in drawing D011164 | C10: Nos | D10: 30 | E10: 0 | F10: =+E10*D10 -> 0
A12: =+A10+1 -> 3 | B12: LED 9W TUBE LIGHT, 6500K, WHITE SHAPE, 2FT (609.6MM), 80LUX. BEAM ANGLE: 170°. IP20. C.R.I.>80. LIFESPAN 50.000H. Code in drawing D008611 | C12: Nos | D12: 8 | E12: 0 | F12: =+E12*D12 -> 0
A14: =+A12+1 -> 4 | B14: DOWNLIGHT LED FOR AUDI, 2700K, BLACK SHAPE, 6W. IP20. C.R.I.>85. DIAMETER 85MM AND 97MM HEIGHT. LIFESPAN 50.000H. Code in drawing D008615 | C14: Nos | D14: 19 | E14: 0 | F14: =+E14*D14 -> 0
A16: =+A14+1 -> 5 | B16: Recessed downlight LED, LED make OSRAM/LT 3000K, White aluminium die cast diameter 89 mm Height 55 mm 15 W, Beam angle 360 IP 20, CRI>80 Lifespan 50,000Hrs. code in drawing D009255 | C16: Nos | D16: 13 | E16: 0 | F16: =+E16*D16 -> 0
A18: =+A16+1 -> 6 | B18: RECESSED DOWNLIGHT LED, LED MAKE: OSRAM/LT, 3000K, WHITE ALUMINUM DIE-CAST, DIAMETER 74mm, HEIGHT 55mm. 7W. BEAM ANGLE: 36°, IP20, C.R.I.>80. LIFESPAN 50.000H., Code in drawing D011140 | C18: Nos | D18: 8 | E18: 0 | F18: =+E18*D18 -> 0
A20: =+A18+1 -> 7 | B20: LED STRIP, CEILING/WALL MOUNT, 3000°K, COPPER AND PCB, DOT FREE (WITH MILKY PVC COVER). 60 LED/M, 10W/M, IP20, C.R.I.>80. LIFESPAN: 3,000H. (5.4 Meter each length) Code in drawing D011168 | C20: Nos | D20: 5 | E20: 0 | F20: =+E20*D20 -> 0
A22: =+A20+1 -> 8 | B22: PENDANT LED, 3000K, BLACK EXTRUDED ALUMINIUM SHAPE, 4W, 300LUX. BEAM ANGLE: 24°. IP20. C.R.I.>85. DIMENSIONS: 12000X38MM AND 75MM HEIGHT. LIFESPAN 50.000H. Code in drawing D011141 | C22: Mtrs | D22: 36 | E22: 0 | F22: =+E22*D22 -> 0
A24: =+A22+1 -> 9 | B24: PENDANT LED, 3000K, BLACK EXTRUDED ALUMINIUM SHAPE, 4W, 300LUX. BEAM ANGLE: 24°. IP20. C.R.I.>85. DIMENSIONS: 12000X38MM AND 75MM HEIGHT. LIFESPAN 50.000H. Code in drawing D011142 | C24: Mtrs | D24: 12 | E24: 0 | F24: =+E24*D24 -> 0
A26: =+A24+1 -> 10 | B26: RECESSED DOWNLIGHT LED, LED MAKE: OSRAM/LT, 3000K, WHITE ALUMINUM DIE-CAST, DIAMETER 56mm, HEIGHT 38mm. 3W. BEAM ANGLE: 36°, IP20, C.R.I.>80. LIFESPAN 50.000H. Code in drawing D011143 | C26: Mtrs | D26: 10 | E26: 0 | F26: =+E26*D26 -> 0
A28: =+A26+1 -> 11 | B28: LED STRIP, CEILING/WALL MOUNT, 4000°K, COPPER AND PCB, DOT FREE (WITH MILKY PVC COVER). 60 LED/M, 10W/M, IP20, C.R.I.>80. LIFESPAN: 3,000H. Code in drawing D0118614 | C28: Mtrs | D28: 18 | E28: 0 | F28: =+E28*D28 -> 0
A30: =+A28+1 -> 12 | B30: EMERGENCY LIGHT WITH EXIT TEXT, WALL MOUNTED, LED MAKE OSRAM/LT, 6500K, MS BODY WHITE/BLACK, 6W. BEAM ANGLE: 120°, IP20, C.R.I. >85. LIFE SPAN: 50,000. FIXTURE DIMENSION: LENGTH 300mm, HEIGHT 272mm, WIDTH 10mm Code in drawing D009971 Exit Signage | C30: Nos | D30: 6 | E30: 0 | F30: =+E30*D30 -> 0
A32: =+A30+1 -> 13 | B32: EMERGENCY LIGHT WITHOUT EXIT TEXT, WALL MOUNTED, LED MAKE OSRAM/LT, 6500K, MS BODY WHITE/BLACK, 6W. BEAM ANGLE: 120°, IP20, C.R.I. >85. LIFE SPAN: 50,000. FIXTURE DIMENSION: LENGTH 300mm, HEIGHT 272mm, WIDTH 10mm | C32: Nos | D32: 6 | E32: 0 | F32: =+E32*D32 -> 0
A34: =+A32+1 -> 14 | B34: LED TUBE LIGHT 900MM LONG TO ILLUMINATE CONCESSIONS' BACK WALL. TO BE DEFINED. Code in drawing LT 26 | D34: 6 | E34: 0 | F34: =+E34*D34 -> 0
A36: =+A34+1 -> 15 | B36: Maintenance 1X28 W LED luminary | C36: Nos | D36: 65 | E36: 0 | F36: =+E36*D36 -> 0
A38: =+A36+1 -> 16 | B38: MAINTENANCE AUDI LIGHT: FLOODLIGHT WITH U-CLAMP; 30W; BLACK IN COLOUR; COLOR TEMPERATURE: 3000K; LIFE SPAN: 50,000 HRS ; LUMINOUS EFFICACY 120LM/W. ALL COMPONENT LIKE CONTROL GEAR, STEP DOWN TRANSFORMERS, ETC., INTERNAL WIRING BETWEEN ACCESSORIES Code in drg : D000 865 | C38: Nos | D38: 24 | E38: 0 | F38: =+E38*D38 -> 0
B40: Total cost of Section 'E' Lighting fixtures | F40: =SUM(F8:F39) -> 0

Sheet Data & Voice
A1: PROJECT: MULTIPLEX FOR CINEPOLIS INDIA PVT. LTD
A2: 4 SCREEN MULTIPLEX AT K. MALL JODHPUR
A3: BILL OF QUANTITIES FOR ELECTRICAL WORKS
A4: SR. | B4: DESCRIPTION | C4: UNIT | D4: QTY | E4: RATE | F4: AMOUNT
A6: F | B6: COMMUNICATION DATA AND VOICE
A8: 1 | B8: 20 pair jelly filled Armoured Cu telephone cable | C8: mtr | D8: 100 | E8: 0 | F8: =+E8*D8 -> 0
A10: 2 | B10: TAG Box suitable for 50pair armoured cu tel cable with crown | C10: No's | D10: 1 | E10: 0 | F10: =+E10*D10 -> 0
A12: 3 | B12: TAG Box suitable for 20pair armoured cu tel cable with crown | C12: Sets | D12: 2 | E12: 0 | F12: =+E12*D12 -> 0
A14: 4 | B14: Supply and wiring for telephone system using 2 pair telephone cable in existing conduit. | C14: mtr | D14: 90 | E14: 0 | F14: =+E14*D14 -> 0
A16: =+A14+1 -> 5 | B16: Supply and installation of CAT 6A cable in existing conduit | C16: mtr | D16: 5025 | E16: 0 | F16: =+E16*D16 -> 0
A18: 5 | B18: Supply and installation of CAT 6 S/FTP cable in existing conduit | C18: Mtrs | D18: =478+2 -> 480 | E18: 0 | F18: =+E18*D18 -> 0
A20: =+A16+1 -> 6 | B20: Supply and installation of CAT 7 ( TMS to each proj Rm ) cable in existing conduit | C20: mtr | D20: 380 | E20: 0 | F20: =+E20*D20 -> 0
A22: 7 | B22: Supply, laying, testing and commissioning of 12 Core Single Mode Optical Fibre Cable, conforming to ITU-T G.652D / G.657A1 standard, comprising colour-coded fibres housed in a loose tube / tight buffered construction, with FR / LSZH outer sheath suitable for indoor installation. | C22: Mtrs | D22: 165 | E22: 0 | F22: =+E22*D22 -> 0
A24: 8 | B24: Supply, installation, testing and commissioning of High-Speed HDMI Cable, compliant with HDMI 2.0 / 2.1 standards, capable of supporting Full HD / 4K / 8K video resolution, HDR, Ethernet and Audio Return Channel (ARC/eARC) as applicable. Cable shall be factory-terminated with gold-plated HDMI Type-A connectors at both ends, with high-quality copper conductors, multi-layer shielding for EMI protection, and durable PVC / LSZH outer jacket. (Considering length 5 Mtrs) | C24: Mtrs | D24: 5 | E24: 0 | F24: =+E24*D24 -> 0
A26: 9 | B26: Supply and installation of RG 6 cable in existing conduit | C26: mtr | D26: 4 | E26: 0 | F26: =+E26*D26 -> 0
A28: =+A26+1 -> 10 | B28: Supply, installation, testing and commissioning of clip on telephone type outlet mounted on a GI outlet box with front plate and all necessary accessories complete as required including the termination of wires.(RJ11) | C28: No's | D28: 4 | E28: 0 | F28: =+E28*D28 -> 0
A30: =+A28+1 -> 11 | B30: Supply, installation, testing and commissioning of clip on Data outlet mounted on a GI outlet box with front plate and all necessary accessories complete as required including the termination of wires.(RJ45) | C30: No's | D30: 95 | E30: 0 | F30: =+E30*D30 -> 0
A32: =+A30+1 -> 12 | B32: Supply and ,installation of Novar/ Steelways make floor mounted Ega box 250 mm by 250 mm for housing 2Nos 6A socket with 1Nos 6A switch on UPS and 1Nos 6A socket with 1Nos 6A switch on Raw power and 2Nos data/voice boxes complete as required. ( For QR code scanner) | C32: No's | D32: 1 | E32: 0 | F32: =+E32*D32 -> 0
A34: =+A32+1 -> 13 | B34: Supply and ,installation of Novar/ Steelways make floor mounted Ega box 100 mm by 100 mm for housing 6/16A switch and socket complete as required. (For DFMD) | C34: No's | D34: 1 | E34: 0 | F34: =+E34*D34 -> 0
B36: Total cost of Section 'F' Communication, Data & Voice | F36: =SUM(F8:F35) -> 0

Sheet Audi Speaker System Wiring
A1: PROJECT: MULTIPLEX FOR CINEPOLIS INDIA PVT. LTD
A2: 4 SCREEN MULTIPLEX AT K. MALL JODHPUR
A3: BILL OF QUANTITIES FOR ELECTRICAL WORKS
A4: SR. | B4: DESCRIPTION | C4: UNIT | D4: QTY | E4: RATE | F4: AMOUNT
A6: G | B6: AUDI SPEAKER SYSTEM WIRING
B7: Audi speaker wiring in medium gauge PVC conduit
A8: 3.1 | B8: Supply and installation of following sizes of FRLS Medium gauge PVC conduit recess /Surface in Floor/ wall including all accessories, GI fish wire, fixing hardware etc. including chasing the wall / floor and plastering the chased portion and making the good the damages etc. complete as required for PA & Music system wiring as required.
A9: a | B9: Medium gauge PVC conduit 20 mm dia | C9: Mtr | D9: 1500 | E9: 0 | F9: =D9*E9 -> 0
A10: b | B10: Medium gauge PVC conduit 25 mm dia | C10: Mtr | D10: 750 | E10: 0 | F10: =D10*E10 -> 0
A11: c | B11: Medium gauge PVC conduit 32 mm dia | C11: Mtr | D11: RO | E11: 0
A12: d | B12: Medium gauge PVC conduit 40 mm dia | C12: Mtr | D12: RO | E12: 0
A13: e | B13: Medium gauge PVC conduit 50 mm dia | C13: Mtr | D13: RO | E13: 0
A14: f | B14: Medium gauge PVC conduit 65 mm dia | C14: Mtr | D14: RO | E14: 0
A16: 3.2 | B16: Supply, installation, testing & commissioning of audi speaker wiring using 2 Nos. 4 Sq.mm multistranded flexible FRLS PVC wire in already laid FRLS medium guage PVC conduit with accessories for auditorium speakers laying on surface / concealed as required. | C16: Mtr | D16: 12100 | E16: 0 | F16: =D16*E16 -> 0
A18: =A16+0.1 -> 3.3 | B18: Supply, installation, testing & commissioning of audi speaker wiring using 2 Nos. 6 Sq.mm multistranded flexible FRLS PVC wire in already laid FRLS medium guage PVC conduit with accessories for auditorium speakers laying on surface / concealed as required. | C18: Mtr | D18: 4378 | E18: 0 | F18: =D18*E18 -> 0
B20: TOTAL OF AUDI SPEAKER SYSTEM | F20: =SUM(F9:F19) -> 0

Sheet Temporary Work
A1: PROJECT: MULTIPLEX FOR CINEPOLIS INDIA PVT. LTD
A2: 4 SCREEN MULTIPLEX AT K. MALL JODHPUR
A3: BILL OF QUANTITIES FOR ELECTRICAL WORKS
A4: SR. | B4: DESCRIPTION | C4: UNIT | D4: QTY | E4: RATE | F4: AMOUNT
A6: H | B6: Temporary Electrical Works
A8: 11 | B8: Providing temporary construction lighting and power for the Floors including Project Managers office area by using required 20nos. 1 x 20 Watt LED fixtures with cover (minimum 250 Lux), required flexible double insulated FRLS copper wiring, distribution board, minimum 25 nos. 40 W LED flood light , earthing, throught the duration of the project. It will be the responsibility of Electrical Contractor to distribute power to all the contractors working at site. The rates shall be all inclusive. (All item mentioned above, shall be new and of good quality by considering site safety parameter.Old and repaired item shall never be allowed to used at site.) Wall chipping for utility sockets, safety glasses for UPS and Battery room, Hand gloves 1100V grade for electrical rooms, shall also be included. | C8: LS | D8: 1 | E8: 0 | F8: =+E8*D8 -> 0
B10: Total cost of Section 'G' Safety & Miscilanious | F10: =SUM(F8:F9) -> 0

Sheet LV Summary
A1: SECTION | B1: Description | C1: Amount
A2: A | B2: CCTV | C2: =CCTV!$F$32 -> 0
A3: B | B3: Public Addressal System | C3: =PA!$F$26 -> 0
A4: C | B4: Access Control | C4: ='Access control'!$F$52 -> 0
B5: Total | C5: =SUM(C2:C4) -> 0

Sheet CCTV
A1: PROJECT : CINEPOLIS INDIA PVT LTD, K-MALL, JODHPUR
A2: BILL OF QUANTITIES FOR CCTV SYSTEM | E2: ='[3]Summary Sheet'!C3 -> R0 - 06.11.2025
A3: SR. NO. | B3: SHORT TEXT (Character limit 40 only) | C3: UNIT | D3: Qty | E3: RATE | F3: AMOUNT (Rs.)
A4: A | B4: IP CCTV
B5: Supply, Installation, Testing & Commissioning of Network (IP) Based CCTV Surveillance System comprising of following:
A6: 1 | B6: IP Fixed Dome camera
B7: IP Fixed Dome camera with 1/3" CCD/CMOS, Progressive/De-interlace, Very High Definition resolution (1920 x 1080), min. Dual streaming, 25 FPS, H.264 / JMPEG compression support, 2.8 mm fixed focal lens, 0 lux with IR, Tamper detection, Wide dynamic Range, PoE power input, IP 43, as per detailed specifications. | C7: EA | D7: =[3]TOS!D7 -> 33 | E7: 0 | F7: =D7*E7 -> 0
A8: 2 | B8: IP Fixed Dome camera (with audio recording)
B9: IP Fixed Dome camera (in-buit microphone) with 1/3" CCD/CMOS, Progressive/De-interlace, Very High Definition resolution (1920 x 1080), min. Dual streaming, 25 FPS, H.264 / JMPEG compression support, 2.8 mm fixed focal lens, 0 lux with IR, Tamper detection, Wide dynamic Range, PoE power input, IP 43, as per detailed specifications. | C9: EA | D9: =[3]TOS!D9 -> 4 | E9: 0 | F9: =D9*E9 -> 0
A10: 3 | B10: Outdoor type IP Bullet camera
B11: Outdoor type IP Bullet camera with 1/2.8" CMOS, Progressive Scan, Day/Night, 2.8 mm - 12 mm motorised zoom lens, Support H.264 & MJPEG, 25/30 FPS @ 1080p (1920×1080), Smart Detection - Tripwire detection, Intrusion detection, Abandoned/Missing Object detection, Scene Change detection, Audio Detection, Face Detection, Support Corridor Mode, Digital WDR, Day/Night (ICR), 3D DNR, AWB, AGC, BLC, Multiple network monitoring: Web viewer, CMS & Mobile App, 1/1 Alarm in/out, 1/1 audio in/out, 30 Mtr IR Range, Micro SD memory support upto 128 GB, Support ONVIF, PSIA, CGI, IP67, PoE as per detailed specifications. | C11: EA | D11: =[3]TOS!D11 -> 6 | E11: 0 | F11: =D11*E11 -> 0
A12: 4.1 | B12: 64 Ch Smart Network Video Recorder
B13: Smart Network Video Recorder: 64 channel IP camera license enabled input, H.264/MJPEG dual codec decoding, 320 Mbps incoming bandwidth, 4k/HDMI/VGA/TV support video output, 8/16 channel synchronous realtime preview, GRID interface, Two-way Talk, Support up to 12 Megapixel Recording, Support Multi-brand network cameras, ONVIF Version conformance, 16/4 Alarm i/o, Including 8 SATA HDDs suitable for 30 days backup, Support 1 eSATA port, 2 USB 2.0, 2 RJ-45 ports (10/ 100/ 1000 Mbps), 1 RS 485 Port, 1 RS 232 Port, Multiple network monitoring: Web viewer, CMS & Mobile App, support ANPR camera, as per detailed specifications | C13: EA | D13: =[3]TOS!D13 -> 0 | E13: 0 | F13: =D13*E13 -> 0
A14: 4.2 | B14: 32 Channel Smart NVR
B15: 32 channel IP camera license enabled input & (SAME AS ABOVE) | C15: EA | D15: =[3]TOS!D15 -> 1 | E15: 0 | F15: =D15*E15 -> 0
A16: 4.3 | B16: 16 Channel Smart NVR
B17: 16 channel IP camera license enabled input & (SAME AS ABOVE) | C17: EA | D17: =[3]TOS!D17 -> 1 | E17: 0 | F17: =D17*E17 -> 0
A18: 4.4 | B18: 12 Channel Smart NVR
B19: (SAME AS ABOVE) | C19: EA | D19: RO
A20: 5 | B20: 32" colour, HD monitor
B21: 32" colour, Flat Screen Type Professional CCTV Surveillance HD monitor 100-230 VAC 50 Hz, 24x7 with wall mounted swivel stand | C21: EA | D21: =[3]TOS!D21 -> 1 | E21: 0 | F21: =D21*E21 -> 0
A22: 6 | B22: SURVILLANCE HARD DISC
B23: SURVILLANCE HARD DISC SUITABLE FOR 30 DAYS BACKUP (min 4 TB) (1+1) | C23: EA | D23: =[3]TOS!D23 -> 2 | E23: 0 | F23: =D23*E23 -> 0
A24: 7.1 | B24: POE Switch 24 port
B25: Independent LAN for IP CCTV System: 24 port layer 2 switch with 10/100/1000 POE Web Semi-Managed Switches, mounted in 4 U Rack and with 2 combo SFP ports and all related termination accessories as per site specific System requirement. (Rack price also to be included) | C25: EA | D25: =[3]TOS!D25 -> 2 | E25: 0 | F25: =D25*E25 -> 0
A26: 7.2 | B26: 16 port
B27: 16 Port layer 2 switch (SAME AS ABOVE) | C27: EA | D27: 0
A28: 8 | B28: Cat-6 cable
B29: Cat-6 cable with required terminations as required with Cable tie's including PVC conduit & accessories | C29: M | D29: =[3]TOS!D29 -> 3500 | E29: 0 | F29: =D29*E29 -> 0
A30: 9 | B30: Additional Item
B31: Any additional items required to complete fully functional system to meet detailed specifications. | C31: EA | D31: RO
B32: TOTAL OF IP CCTV | F32: =SUM(F7:F31) -> 0

Sheet PA
A1: PROJECT: MULTIPLEX FOR CINEPOLIS INDIA PVT. LTD
A2: REFURBISHMENT OF 4 SCREEN MULTIPLEX AT P&M MALL PATNA | B2: 4 SCREEN MULTIPLEX AT K. MALL JODHPUR
A3: BILL OF QUANTITIES FOR PUBLIC ADDRESS SYSTEM WORK
A4: SR. | B4: Description | C4: UNIT | D4: QTY | E4: RATE | F4: AMOUNT
A5: B | B5: MUSIC AND PUBLIC ADDRESS SYSTEM
A7: 1 | B7: 5 Zone Call Station with goose neck Microphone with zone selection & all call selection to be connected peer to peer with the network controller | D7: 1 | E7: 0 | F7: =D7*E7 -> 0
A9: 2 | B9: Supply, installation, Testing, & commissioning of the Message Tone genetaror for pre-recorded message.Shall be an EN54-16 certified user interface. | D9: 1 | E9: 0 | F9: =D9*E9 -> 0
A11: 3 | B11: Network controller + Amplifire - 5 zone with following features 1. Microcontroller based with builtin 240 Watt Amplifier 2. Accomodates 5 set of zones 3. Accomadates 5 Zone Call stations peer to peer 4. Automated Evacuation message facility | D11: 1 | E11: 0 | F11: =D11*E11 -> 0
A13: 3 | B13: Rack for mounting the entire system. (All above components of the system to be rack mountable. | C13: Set | D13: 1 | E13: 0 | F13: =D13*E13 -> 0
A15: 4 | B15: SPEAKERS
A16: 3.1 | B16: Supply, installation, testing & commissioning of 15 to 30W ceiling mounted speakers complete. | C16: Nos | D16: RO | E16: 0
A18: 3.2 | B18: Supply, installation, testing & commissioning of 15 to 30W wall mounted speakers complete. | C18: Nos | D18: RO | E18: 0
A20: 3.3 | B20: Supply, installation, testing & commissioning of 6 W RMS 4 Ohms full range PA speakers on bracket, false ceiling etc. with dual cone woofer 20 W peak Output, 100 Hz to 15KHz frequency with Line matching transformer for 95 dBA sound output. | C20: Nos | D20: 50 | E20: 0 | F20: =+E20*D20 -> 0
A22: 3.4 | B22: Supply, installation, testing & commissioning of 10 W RMS 4 Ohms full range Horn type PA speakers on bracket, false ceiling etc. with dual cone woofer 10 W peak Output, 100 Hz to 15KHz frequency with Line matching transformer for 95 dBA sound output. | C22: Nos | D22: 8 | E22: 0 | F22: =+E22*D22 -> 0
A24: 5 | B24: Supply, laying, testing & commissioning of cable for music system with 40/36 twin parallel FR PVC sheathed armoured Cable of approved make. End termination of FR cable with SIBG gland and required accesories. All complete as required and as per final direction & approval of the consultant | C24: Mtr | D24: 1900 | E24: 0 | F24: =D24*E24 -> 0
B26: TOTAL OF PUBLIC ADDRESS SYSTEM | F26: =SUM(F6:F25) -> 0

Sheet Access control
A1: PROJECT: MULTIPLEX FOR CINEPOLIS INDIA PVT. LTD
A2: REFURBISHMENT OF 4 SCREEN MULTIPLEX AT K. MALL JODHPUR
A3: BILL OF QUANTITIES FOR ACCESS CONTROL SYSTEM WORKS
A5: SR | B5: DESCRIPTION | C5: UNIT | D5: QTY | E5: RATE | F5: AMOUNT
A7: C | B7: ACCESS CONTROL SYSTEM
A8: 1 | B8: Supply, installation, testing and commissioning of standalone Access Control System C3-400B 4 door multidoor access controller for supporting Proximity Card or a Biometric readers. System should be capable of handling Card / Biometric data with power supply as spec`s below | C8: Set | D8: 1 | E8: 0 | F8: =+E8*D8 -> 0
B9: Multiple card / Biometric reading technologies supported, Inbuilt database backup to facilitate offline use Automatic locking & unlocking of the doors based on Fire Signal, System should support max 4 nos doors having Card cum Biometric readers located at different location System should be compatible for integrate with Clients Enterprise version (if required)
A11: 2 | B11: Supply, Installation, Testing and Commissioning of Smart Card Reader (KR500E) with read range of 3" | C11: Nos | D11: 6 | E11: 0 | F11: =+E11*D11 -> 0
A13: 3 | B13: Supply, Installation, Testing and Commissioning of normal exit & Emergency Release push button switch Polycarbonate housing. | C13: Nos | D13: 6 | E13: 0 | F13: =+E13*D13 -> 0
A15: 4 | B15: Supply, Installation, Testing and Commissioning of Electromagnetic lock-600 lb holding force | C15: Nos | D15: 6 | E15: 0 | F15: =+E15*D15 -> 0
A17: 5 | B17: Supply, Installation, Testing and Commissioning of Electromagneitc Lock with built in Magnetic contacts Single leaf Doors. 600 lbs capacity - L bracket as required (EM 600-LED ) | C17: Nos | D17: 6 | E17: 0 | F17: =+E17*D17 -> 0
A19: =A17+1 -> 6 | B19: Supply, Installation, Testing and Commissioning of Electromagneitc Lock with builtin Magnetic contacts double leaf Doors. 600 lbs capacity - U bracket as required (EM 600-LED ) | C19: Nos | D19: 6 | E19: 0 | F19: =+E19*D19 -> 0
A22: =A19+1 -> 7 | B22: Supply, Installation, Testing and Commissioning of Egress Switch | C22: Nos | D22: 6 | E22: 0 | F22: =+E22*D22 -> 0
A24: 8 | B24: Supply, Installation, Testing and Commissioning of Proximity cards (PVC) | C24: Nos | D24: 20 | E24: 0 | F24: =+E24*D24 -> 0
A26: 9 | B26: Supply, Installation, Testing and Commissioning of Proximity key fobs | C26: Nos | D26: 4 | E26: 0 | F26: =+E26*D26 -> 0
A28: 10 | B28: Supply, Installation, Testing and Commissioning of Access Control Enterprise version Server Software + Access Control Enterprise version Client License loaded on Client machines | C28: Set | D28: 1 | E28: 0 | F28: =+E28*D28 -> 0
A30: 11 | B30: Supply, Installation, Testing and Commissioning of following communication & power cables in the conduit/ LV receway.
A31: 11A | B31: Communication cables
A32: 11.1 | B32: Cat 6 | C32: RMT | D32: RO | E32: 0
A33: 11.2 | B33: Cat 6A | C33: RMT | D33: 50 | E33: 0 | F33: =+E33*D33 -> 0
A34: 11.3 | B34: Cat 7 | C34: RMT | E34: 0
A35: 11B | B35: Power cables
A36: 11.4 | B36: 8 C X 18 AWG Shielded cable | C36: RMT | D36: 40 | E36: 0 | F36: =+E36*D36 -> 0
A37: 11.5 | B37: 4c x 18 AWG Shielded cable | C37: RMT | D37: 300 | E37: 0 | F37: =+E37*D37 -> 0
A38: 11.6 | B38: 4c x 24 AWG Shielded cable | C38: RMT | D38: 250 | E38: 0 | F38: =+E38*D38 -> 0
A40: 12 | B40: Supply, Installation, Testing and Commissioning of Medium Grade - 25 mm FRPVC Conduit with fittings and accessories ISI Marked with GI saddle & spacers at every 0.3 Mtr and flexible conduits for all drops above false ceiling. | C40: Mtrs | D40: 60 | E40: 0 | F40: =+E40*D40 -> 0
A42: 13 | B42: Supply, Installation, Testing and Commissioning of Fully closed GI Powder coated trunking of 16 Gauge with GI supports at every 3 mtrs, and Aluminum Junction Boxes @ every 6 mtr
A43: =A42+0.1 -> 13.1 | B43: 50 x 50 mm | C43: Mtrs | D43: 45 | E43: 0 | F43: =+E43*D43 -> 0
A44: =A43+0.1 -> 13.2 | B44: 63 x 38 mm | C44: Mtrs | D44: RO | E44: 0
A45: =A44+0.1 -> 13.3 | B45: 83 x 38 mm | C45: Mtrs | D45: RO | E45: 0
A46: =A45+0.1 -> 13.4 | B46: 100 x 40 mm | C46: Mtrs | D46: RO | E46: 0
A48: 14 | B48: Supply, Installation, Testing and Commissioning of Piezo sounders for Fire Exits | C48: Nos | D48: 2 | E48: 0 | F48: =+E48*D48 -> 0
A50: 15 | B50: Supply, Installation, Testing and Commissioning of fingerprint Biometric cum card Reader, with Power + Control kit. | C50: Nos | D50: RO | E50: 0 | F50: 0
B52: TOTAL COST OF ACCESS CONTROL SYSTEM | F52: =SUM(F8:F50) -> 0
