Workbook

Sheet HVAC SUMMARY
A1: PROJECT | B1: TS-T2- WEX - BANGLORE
A2: SUB | B2: SUMMARY
A3: Sl. No. | B3: DESCRIPTION | C3: Amount
C4: Supply | D4: Installation | E4: Total
B5: LOW SIDE WORK
A6: C | B6: INSTALLATION OF CHW AHU , FCU & PIPING WORK | C6: ='HVAC LOW SIDE '!I73 -> 0 | D6: ='HVAC LOW SIDE '!J73 -> 0 | E6: =SUM(C6:D6) -> 0
A7: D | B7: SHEET METAL WORK & AIR TERMINATION | C7: ='HVAC LOW SIDE '!I233 -> 0 | D7: ='HVAC LOW SIDE '!J233 -> 0 | E7: =SUM(C7:D7) -> 0
A8: E | B8: INSULATION WORK | C8: ='HVAC LOW SIDE '!I244 -> 0 | D8: ='HVAC LOW SIDE '!J244 -> 0 | E8: =SUM(C8:D8) -> 0
A9: F | B9: TOTAL OF VRF WORK | C9: ='HVAC LOW SIDE '!I354 -> 0 | D9: ='HVAC LOW SIDE '!J354 -> 0 | E9: =SUM(C9:D9) -> 0
A10: G | B10: ELECTRICAL WORK | C10: ='HVAC LOW SIDE '!I378 -> 0 | D10: ='HVAC LOW SIDE '!J378 -> 0 | E10: =SUM(C10:D10) -> 0
A11: H | B11: TOTAL OF VAV WORKS -01 | C11: ='HVAC LOW SIDE '!I412 -> 0 | D11: ='HVAC LOW SIDE '!J412 -> 0 | E11: =SUM(C11:D11) -> 0
A12: I | B12: TOTAL OF VAV WORKS -02 | C12: ='HVAC LOW SIDE '!I432 -> 0 | D12: ='HVAC LOW SIDE '!J432 -> 0 | E12: =SUM(C12:D12) -> 0
B14: TOTAL HVAC OF LOW SIDE WORK | C14: =SUM(C6:C13) -> 0 | D14: =SUM(D6:D13) -> 0 | E14: =SUM(E6:E13) -> 0
B16: GST @18% | C16: =C14*18% -> 0 | D16: =D14*18% -> 0 | E16: =E14*18% -> 0
B18: GRAND TOTAL WITH GST ( LOW SIDE WORK) | C18: =SUM(C14:C17) -> 0 | D18: =SUM(D14:D17) -> 0 | E18: =SUM(E14:E17) -> 0

Sheet HVAC LOW SIDE 
A1: PROJECT | B1: TS-T2 - WEX- BANGLORE
A2: Sl. No. | B2: DESCRIPTION | C2: Office | D2: COMMON AREA | E2: TOTAL | F2: Unit | G2: Rate | I2: AMOUNT
C3: QTY | G3: SUPPLY | H3: INSTALLATION | I3: SUPPLY | J3: INSTALLATION
A4: A | B4: CHW AHU /CASSETTE/HIWALL & PIPING WORKS
A6: 1 | B6: Installation, testing & commissioning of Floor mounted AHU (Double Skin) as per specification
B7: Fan section with DIDW type centrifugal impeller with the motor shall be permanent magnet external rotor motor with integrated electronics and suitable for continuous operation, Chilled water coils of copper tube and aluminum fins construction section with six rows deep having 12-13 FPI with coil face velocity of 500 FPM, Filter section with synthetic fiber filters in corrugated shape rated for filter face velocity 500 FPM Prefilter, & MERV 13 Rating filters.IE-3 motor (inside AHU casing), , spring mounted vibration Isolators, Limit Switch, Emergency Light, UV Emitter section with UVC Lamps, Guard for Inspection Door. AHU motor should be minimum IE3 grade along with the necessary controller hosed in a panel. The internal wiring between the limit switches,without UV lamp & interlock to be part of AHU vendor scope. Fan Vendor should also provide the BacNet card for each AHU for BMS integration.
B8: The air-handling units shall be as per specifications with extruded aluminum framework having panels with outer pre-plasticised 0.6mm G.I / Galvalume sheets & inner plain 0.6mm GI / Galvalume sheet having injected 23- 25 mm PUF of 38 -kg/Cum density in between. The drain pan shall be of 18 G SS with 13mm thick nitrile rubber insulation. The frame for AHU shall be extruded aluminum. The entire AHU shall be mounted on GI base of min 70mm.
B9: Drain pan: 1.2 mm thick SS304 with 25mm Nitrile rubber sandwiched. Provide 40 mm SS threaded drain nipple.
B10: Dampers: Al. anodized low leakage aerofoil.
B11: Filter section: With Prefilter , Non-Combustible Filter, access doors filters in extruded al. box type frames with gasket arrangements around filter frames. This should include one set of commissioning filters
B12: Coil Section: Cu coils with hydrophilic coated al. fins,6 Row coil , CHW COIL
B13: Fan section: Centrifugal fans with access doors on both sides, inspection windows, limit switch to shut off fan on door opening, Emergency Light,UV Emitter section with UVC Lamp, VFD Starter Panel & cabling from control to fans shall be scope of HVAC VENDOR.
B14: Drive: IE-3 motor
B15: Vibration Isolators: For fans and mounting arrangements - Rust resistant spring
B16: Flexible connectors: Non flammable, weather and fungus proof
B17: FLOOR MOUNTED ESP-40 mm | E17: =C17+D17 -> 0 | I17: =+N($E17)*N(G17) -> 0 | J17: =+N($E17)*N(H17) -> 0
A18: 1.1 | B18: 16000 CFM with VFD & bypass starter | E18: =C18+D18 -> 0 | F18: Nos | I18: =+N($E18)*N(G18) -> 0 | J18: =+N($E18)*N(H18) -> 0
A19: 1.2 | B19: 12000 CFM with bypass starter | E19: =C19+D19 -> 0 | F19: Nos | I19: =+N($E19)*N(G19) -> 0 | J19: =+N($E19)*N(H19) -> 0
E20: =C20+D20 -> 0 | I20: =+N($E20)*N(G20) -> 0 | J20: =+N($E20)*N(H20) -> 0
A21: 1.3 | B21: CEILING SUSPENDED AHU ESP 25 mm | E21: =C21+D21 -> 0 | I21: =+N($E21)*N(G21) -> 0 | J21: =+N($E21)*N(H21) -> 0
B22: 12000 CFM with starter Panel | E22: =C22+D22 -> 0 | F22: Nos | I22: =+N($E22)*N(G22) -> 0 | J22: =+N($E22)*N(H22) -> 0
E23: =C23+D23 -> 0 | I23: =+N($E23)*N(G23) -> 0 | J23: =+N($E23)*N(H23) -> 0
E24: =C24+D24 -> 0 | I24: =+N($E24)*N(G24) -> 0 | J24: =+N($E24)*N(H24) -> 0
A25: 1.4 | B25: CEILING SUSPENDED AHU ESP 20 mm | E25: =C25+D25 -> 0 | I25: =+N($E25)*N(G25) -> 0 | J25: =+N($E25)*N(H25) -> 0
B26: 4400 CFM/20.0 TR with starter Panel | E26: =C26+D26 -> 0 | F26: Nos | I26: =+N($E26)*N(G26) -> 0 | J26: =+N($E26)*N(H26) -> 0
E27: =C27+D27 -> 0 | I27: =+N($E27)*N(G27) -> 0 | J27: =+N($E27)*N(H27) -> 0
A28: 1.3 | B28: DECORATIVE WALL MOUNTED FAN COIL UNITS | E28: =C28+D28 -> 0 | I28: =+N($E28)*N(G28) -> 0 | J28: =+N($E28)*N(H28) -> 0
B29: Installation, Testing, Commissioning of Decorative High Wall Mounted type Chilled Water based Fan Coil Units with energy efficient 3 speed motor, ABS plastic decorative casing, Low noise fan-motor combination, Synthetic washable filter, Semi Circular Chilled Water Cooling Coil & aluminium fins with corrossion resistant coating blue or golden, minimum 13 FPI, Copper tubes minimum 7mm dia, multi step design Coil section with minimum 2 Rows, an in-built factory fitted 2 way On/ Off control valve of minimum PN16 rating duly connected and wired, with combination of pair of brass ball valve with "Y" strainer set fixed outside FCU, flexible pipe/hose with required couplings to fit CHW field In/Out piping; All piping are to be insulated with closed cell elastomeric rubber insulation. Unit shall be equipped with self diagnostic function, temperature display and supplied with Digital Display type cordless remote with 3 speed fan switch & Temp Edit facility & Digital Temp Display, supplied with relevant power supply cable from nearest point to to FCU as required. Inbuilt BMS provision in the units, no additional equipments should be required for Backnet IP connectivity | E29: =C29+D29 -> 0 | I29: =+N($E29)*N(G29) -> 0 | J29: =+N($E29)*N(H29) -> 0
B30: 2.0 TR (Hub room & IT Room) | E30: =C30+D30 -> 0 | F30: Nos | I30: =+N($E30)*N(G30) -> 0 | J30: =+N($E30)*N(H30) -> 0
B31: 1.6 TR (UPS room) | E31: =C31+D31 -> 0 | F31: Nos | I31: =+N($E31)*N(G31) -> 0 | J31: =+N($E31)*N(H31) -> 0
B32: 1.0 TR (Battery room) | E32: =C32+D32 -> 0 | F32: Nos | I32: =+N($E32)*N(G32) -> 0 | J32: =+N($E32)*N(H32) -> 0
B33: 1.0 TR (IT STORE room ) | E33: =C33+D33 -> 0 | F33: Nos | I33: =+N($E33)*N(G33) -> 0 | J33: =+N($E33)*N(H33) -> 0
E34: =C34+D34 -> 0 | I34: =+N($E34)*N(G34) -> 0 | J34: =+N($E34)*N(H34) -> 0
A35: 1.4 | B35: HIGH STATIC DUCT FAN COIL UNIT ( FCU ) | E35: =C35+D35 -> 0 | I35: =+N($E35)*N(G35) -> 0 | J35: =+N($E35)*N(H35) -> 0
B36: Supply, installation, testing and commissioning of ceiling concealed type High Static Duct type Fan Coil Units, Eurovent Certified, single skin, draw through type with minimum 3 speed fan motor, minimum 3 row chilled water coil, with Al fins with corrossion resistant coating blue or gold, metallic centrifugal blower, washable filter minimum 20 micron, insulated enclosed double skin drain tray, hanging rods and accessories, copper piping connections, etc. of the following capacities. Starter panel with necessary controls, incoming cable from starter panel to unit, connected with Pressure Independent Control cum Balancing Valve DN25, with minimum 24V Modulating Actuators IP54 with 0-10VDC control, Digital Thermostat with Modbus connectivity, Fire retardant canvass connections with GI powdercoated finish angle flanges on both sides, etc. Additional auxillary tray should accommodate all valves as per the specifications and approved drawings. The external static pressure shall be as per specifictions below. he unit shall have provision for complete control and monitoring over BMS using Modbus/ Bacnet protocol, additional items and controllers if required shall also be provided. | E36: =C36+D36 -> 0 | I36: =+N($E36)*N(G36) -> 0 | J36: =+N($E36)*N(H36) -> 0
B37: 3.0 TR ( Server Room) | E37: =C37+D37 -> 0 | F37: Nos | I37: =+N($E37)*N(G37) -> 0 | J37: =+N($E37)*N(H37) -> 0
E38: =C38+D38 -> 0 | I38: =+N($E38)*N(G38) -> 0 | J38: =+N($E38)*N(H38) -> 0
A39: 2 | B39: Insulated chilled water piping, MS heavy duty 'C' Class (as per IS 1239 - Part I 2004) complete with bends, elbows, tees, vibration isolators, hangers, full round PU / rubber supports insulated with 25mm Thick Nitrile Rubber Insulation with 7 mil Cloth Pipe thickness: 6.3 mm thick for 200 - 250 dia pipes 8 mm thick for 300 - 350 dia pipes 10 mm thick for 400 - 600 dia pipes 12 mm thick for 650 - 1000 dia pipes Insulation thickness exposed to sun - 75 mm | E39: =C39+D39 -> 0 | I39: =+N($E39)*N(G39) -> 0 | J39: =+N($E39)*N(H39) -> 0
A40: 2.1 | B40: 80mm dia | E40: =C40+D40 -> 0 | F40: Rmt | I40: =+N($E40)*N(G40) -> 0 | J40: =+N($E40)*N(H40) -> 0
A41: 2.2 | B41: 50mm dia | E41: =C41+D41 -> 0 | F41: Rmt | I41: =+N($E41)*N(G41) -> 0 | J41: =+N($E41)*N(H41) -> 0
...
