Workbook

Sheet ELEC-SUMM 
A1: BILL OF QUANTITIES FOR ELECTRIFICATION WORKS. -HUL ICE CREAM,13TH FLOOR
A2: SL.NO | B2: DESCRIPTION | C2: Supply | D2: Installation | E2: Total Amount
A4: A | B4: WIRING SYSTEM | C4: ='ELEC '!I60 -> 0 | D4: ='ELEC '!J60 -> 0 | E4: =C4+D4 -> 0
E5: =C5+D5 -> 0
A6: B | B6: POWER SOCKETS | C6: ='ELEC '!I107 -> 0 | D6: ='ELEC '!J107 -> 0 | E6: =C6+D6 -> 0
E7: =C7+D7 -> 0
A8: C | B8: L.T. PANELS | C8: ='ELEC '!I133 -> 0 | D8: ='ELEC '!J133 -> 0 | E8: =C8+D8 -> 0
E9: =C9+D9 -> 0
A10: D | B10: DISTRIBUTION BOARDS | C10: ='ELEC '!I234 -> 0 | D10: ='ELEC '!J234 -> 0 | E10: =C10+D10 -> 0
E11: =C11+D11 -> 0
A12: E | B12: L.T. CABLES | C12: ='ELEC '!I318 -> 0 | D12: ='ELEC '!J318 -> 0 | E12: =C12+D12 -> 0
E13: =C13+D13 -> 0
A14: G | B14: CONDUIT & RACEWAYS FOR NETWORKING & POWER SYSTEM ONLY | C14: ='ELEC '!I389 -> 0 | D14: ='ELEC '!J389 -> 0 | E14: =C14+D14 -> 0
E15: =C15+D15 -> 0
A16: H | B16: EARTHING SYSTEM | C16: ='ELEC '!I431 -> 0 | D16: ='ELEC '!J431 -> 0 | E16: =C16+D16 -> 0
E17: =C17+D17 -> 0
A18: I | B18: MISCELLANEOUS ITEMS | C18: ='ELEC '!I459 -> 0 | D18: ='ELEC '!J459 -> 0 | E18: =C18+D18 -> 0
B20: TOTAL | C20: =SUM(C4:C19) -> 0 | D20: =SUM(D4:D19) -> 0 | E20: =SUM(E4:E19) -> 0
A22: J | B22: LGHTING | E22: =C22+D22 -> 0

Sheet ELEC 
B1: PROJECT : TABLE SPACE
B2: INTERIOR ELECTRICAL WORKS BOQ | I2: R0
A3: SL. NO | B3: DESCRIPTION | G3: RATE - RS. | I3: AMOUNT - RS.
C4: UNIT | D4: Common Area | E4: OFFICE | F4: Qty | G4: SUPPLY | H4: INSTALLATION | I4: SUPPLY | J4: INSTALLATION | K4: AMOUNT | M4: ESPL Remarks
A5: A | B5: WIRING SYSTEM
A7: 1 | B7: CIRCUIT MAINS
B9: Circuit mains using 1.1kV grade PVC insulated FRLS copper conductor (MSCC) wires / PVC insulated PVC sheathed single core cables drawn in PVCS conduit or in existing raceway. Rates quoted shall include supply of conduits, wires & other conduiting accessories, MS pull / junction boxes, G.I fish wire etc. Colour coding shall be used for conduits to differentiate lighting, RP, UPS, emergency lighting circuits & point wiring. All circuit terminations shall be provided with solder less crimping type copper sockets / lugs, ferrules indicating source code on load side & load code on source side. There shall not be any joints in the circuits, only looping is allowed in terminal blocks & in switches / socket outlets.
B11: NOTE:
B12: 1) Conduits running above false ceiling in multiples shall be supported by Slotted GI 'C' channel at distance not more than 0.5mtrs intervals.
B13: 2) Accessories shall includes Bends, Collars, junction boxes, Spacers, saddles, screws, Flexibles
B14: 3) Conduits shall be ISI marked
B15: 4) The number of wires drawn in each conduit shall be as per BIS 694 .
B16: 5) No different phases shall be drawn in same conduit
B17: 6) Conduit joints shall be done with threading proper accessories only
B18: 7) Use colour coding for each UPS & Raw power seperately
B19: 8) Black color conduit to be used / As per architect color approval
A21: 1.1 | B21: Lighting Circuit:
B22: Supply & Installation of wiring using 2X2.5 + 1X1.5 sqmm PVC insulated FRLS wire drawn in 2mm thick PVC conduit as lighting circuit. The circuit main shall be measured in running metres from respective distribution board upto first switch point / light point and looping between the switches (further onwards, it shall be deemed to be included in point wiring). (cost of conduit is included) | C22: M | D22: =(3+3)*45*1.1 -> 297 | E22: =(21+21)*45*1.1 -> 2079 | F22: =SUM(D22:E22) -> 2376 | I22: =+N($F22)*N(G22) -> 0 | J22: =+N($F22)*N(H22) -> 0 | K22: =J22+I22 -> 0 | M22: 1.5 is updated to 2.5 for phase & neutral
F23: =SUM(D23:E23) -> 0 | I23: =+N($F23)*N(G23) -> 0 | J23: =+N($F23)*N(H23) -> 0 | K23: =J23+I23 -> 0
A24: 1.2 | B24: Emergency lighting circuit: | F24: =SUM(D24:E24) -> 0 | I24: =+N($F24)*N(G24) -> 0 | J24: =+N($F24)*N(H24) -> 0 | K24: =J24+I24 -> 0
B25: Supply & Installation of wiring using 2X2.5 + 1X1.5 sqmm PVC insulated FRLS wire drawn in 2mm thick PVC conduit as lighting circuit. The circuit main shall be measured in running metres from respective distribution board upto first switch point / light point and looping between the switches (further onwards, it shall be deemed to be included in point wiring). (cost of conduit is included) | C25: M | D25: =3*45*1.1 -> 148.5 | E25: =8*45*1.1 -> 396 | F25: =SUM(D25:E25) -> 544.5 | I25: =+N($F25)*N(G25) -> 0 | J25: =+N($F25)*N(H25) -> 0 | K25: =J25+I25 -> 0
F26: =SUM(D26:E26) -> 0 | I26: =+N($F26)*N(G26) -> 0 | J26: =+N($F26)*N(H26) -> 0 | K26: =J26+I26 -> 0
A27: 1.3 | B27: VAV,FD & ,Convinient ,Security application Circuit : | F27: =SUM(D27:E27) -> 0 | I27: =+N($F27)*N(G27) -> 0 | J27: =+N($F27)*N(H27) -> 0 | K27: =J27+I27 -> 0
B28: Supply & Installation of wiring using 2X2.5 + 1X1.5 sqmm PVC insulated FRLS wire drawn in 2mm thick PVC conduit for third party services (cost of conduit is included) | C28: M | D28: =3*45*1.1 -> 148.5 | E28: =8*45*1.1 -> 396 | F28: =SUM(D28:E28) -> 544.5 | I28: =+N($F28)*N(G28) -> 0 | J28: =+N($F28)*N(H28) -> 0 | K28: =J28+I28 -> 0
F29: =SUM(D29:E29) -> 0 | I29: =+N($F29)*N(G29) -> 0 | J29: =+N($F29)*N(H29) -> 0 | K29: =J29+I29 -> 0
A30: 1.4 | B30: UPS Circuit W/S | F30: =SUM(D30:E30) -> 0 | I30: =+N($F30)*N(G30) -> 0 | J30: =+N($F30)*N(H30) -> 0 | K30: =J30+I30 -> 0
B31: Supply & Installation of 3 C x 2.5 Sqmm FRLS 1100V unarmoured double insulated flexible multicore cable in white and black colour for UPS & RP circuit respectively in existing conduits/raceways. (Conduit cost is excluded) | C31: M | D31: 200 | E31: =(28+28)*40*1.1 -> 2464 | F31: =SUM(D31:E31) -> 2664 | I31: =+N($F31)*N(G31) -> 0 | J31: =+N($F31)*N(H31) -> 0 | K31: =J31+I31 -> 0
F32: =SUM(D32:E32) -> 0 | I32: =+N($F32)*N(G32) -> 0 | J32: =+N($F32)*N(H32) -> 0 | K32: =J32+I32 -> 0
A33: 1.5 | B33: RP Circuit W/S | F33: =SUM(D33:E33) -> 0 | I33: =+N($F33)*N(G33) -> 0 | J33: =+N($F33)*N(H33) -> 0 | K33: =J33+I33 -> 0
B34: Supply & Installation of 3 C x 2.5 Sqmm FRLS 1100V unarmoured double insulated flexible multicore cable in white and black colour for UPS & RP circuit respectively in existing conduits/raceways. (Conduit cost is excluded) | C34: M | D34: 200 | E34: =(28+28)*40*1.1 -> 2464 | F34: =SUM(D34:E34) -> 2664 | I34: =+N($F34)*N(G34) -> 0 | J34: =+N($F34)*N(H34) -> 0 | K34: =J34+I34 -> 0
F35: =SUM(D35:E35) -> 0 | I35: =+N($F35)*N(G35) -> 0 | J35: =+N($F35)*N(H35) -> 0 | K35: =J35+I35 -> 0
A36: 1.6 | B36: UPS Circuit - MDF & IDF room rack | F36: =SUM(D36:E36) -> 0 | I36: =+N($F36)*N(G36) -> 0 | J36: =+N($F36)*N(H36) -> 0 | K36: =J36+I36 -> 0
B37: Supply & Installation of 3 C x 4 Sqmm FRLS 1100V unarmoured double insulated flexible multicore cable in white and black colour for UPS & RP circuit respectively in existing conduits/raceways.(Conduit cost is excluded) | C37: M | F37: =SUM(D37:E37) -> 0 | I37: =+N($F37)*N(G37) -> 0 | J37: =+N($F37)*N(H37) -> 0 | K37: =J37+I37 -> 0
F38: =SUM(D38:E38) -> 0 | I38: =+N($F38)*N(G38) -> 0 | J38: =+N($F38)*N(H38) -> 0 | K38: =J38+I38 -> 0
A39: 1.7 | B39: UPS Circuit - Server room rack | F39: =SUM(D39:E39) -> 0 | I39: =+N($F39)*N(G39) -> 0 | J39: =+N($F39)*N(H39) -> 0 | K39: =J39+I39 -> 0
B40: Supply & Installation of 3 C x 6 Sqmm FRLS 1100V unarmoured double insulated flexible multicore cable in white and black colour for UPS & RP circuit respectively in existing conduits/raceways.(Conduit cost is excluded) | C40: M | E40: =4*4*15*1.1 -> 264 | F40: =SUM(D40:E40) -> 264 | I40: =+N($F40)*N(G40) -> 0 | J40: =+N($F40)*N(H40) -> 0 | K40: =J40+I40 -> 0
F41: =SUM(D41:E41) -> 0 | I41: =+N($F41)*N(G41) -> 0 | J41: =+N($F41)*N(H41) -> 0 | K41: =J41+I41 -> 0
A42: A.1 | B42: POINT WIRING | F42: =SUM(D42:E42) -> 0 | I42: =+N($F42)*N(G42) -> 0 | J42: =+N($F42)*N(H42) -> 0 | K42: =J42+I42 -> 0
A43: A.1.1 | B43: POINT WIRING - SWITCH CONTROL | F43: =SUM(D43:E43) -> 0 | I43: =+N($F43)*N(G43) -> 0 | J43: =+N($F43)*N(H43) -> 0 | K43: =J43+I43 -> 0
F44: =SUM(D44:E44) -> 0 | I44: =+N($F44)*N(G44) -> 0 | J44: =+N($F44)*N(H44) -> 0 | K44: =J44+I44 -> 0
...

Sheet UPS BOQ
A1: Project | B1: : TABLE SPACE
A2: Consultants | B2: : E Sollutions Consultancy Pvt Ltd
A3: Subject | B3: : UPS BOQ
A4: Date | B4: : 30.04.2026
A5: Sl. No | B5: Descirption | C5: Unit | D5: Total Qty | E5: Unit Rate
E6: Supply | F6: Installation
A7: A | B7: UPS & BATTERY RELATED WORKS
A8: I | B8: EQUIPMENT | H8: =E11*2.5% -> 0
A10: A | B10: UPS
A11: 1 | B11: Design, manufacture, assembly, supply, installation, testing, delivery and commissioning of 100-kVA Frame size Modular UPS with 25 kVA X 3 modules in each frame with hot swapable Continuous rating, online, double conversion operating modular type 3 ph input and 3 ph output Modular UPS system with IGBT rectifier as per technical specifications. The UPS Module Cabinet shall consist of a Breaker & breaker cabinet, rectifier / charger, a three-phase inverter, static transfer switch, Maintenance Bi-pass Switch, logic, synchronizing equipment, protective devices and accessories as required for proper operation.The Modular system is selected in N+1 configuration. Routine tests needs to be done at factory & test reports need to be submitted. - The UPS System to be provided with Dual Input Card for both Modus Monitoring in BMS system and IP Monitoring over Network parallely including Parallel working configuration required accessories. | C11: No | D11: 1 | G11: =SUM(E11:F11)*N($D11) -> 0
G12: =SUM(E12:F12)*N($D12) -> 0
A13: =A11+1 -> 2 | B13: Supply, Installation, Testing and commissiong of required Ah of Valve regulated lead–acid (VRLA) Batteries of approved make suitable for 3x25 kVA sets @0.9PF to give minimum 15 minutes backup. The rate shall include bankwise battery monitoring system. Battery monitoring PC should be located in BMS room. | C13: Set | D13: 1 | G13: =SUM(E13:F13)*N($D13) -> 0
E14: 0 | F14: 0 | G14: =SUM(E14:F14)*N($D14) -> 0
A15: 3 | B15: CABLING SYSTEM | E15: 0 | F15: 0 | G15: =SUM(E15:F15)*N($D15) -> 0
E16: 0 | F16: 0 | G16: =SUM(E16:F16)*N($D16) -> 0
A17: =A15+0.1 -> 3.1 | B17: Supply, installation, testing and commissioning of 1100V grade multistrand, copper conductor, Uni Nyvin, unarmoured flexible cable of requisite size for interconnection between battery, battery breakers and the respective 3x25 kVA UPS Units. The cable shall conform to IS-694 | C17: LS | D17: 1 | G17: =SUM(E17:F17)*N($D17) -> 0
E18: 0 | F18: 0 | G18: =SUM(E18:F18)*N($D18) -> 0
A19: =A17+0.1 -> 3.2 | B19: Supply, installation and commissioning of 1100V grade multistrand, copper conductor, Uni Nyvin, unarmoured flexible cable termination with Single compression cable gland, Ring type copper lugs and necessary steel bolts for interconnection between battery, battery breakers and the respective 3x25 kVA UPS Units. | C19: LS | D19: 1 | G19: =SUM(E19:F19)*N($D19) -> 0
E20: 0 | F20: 0 | G20: =SUM(E20:F20)*N($D20) -> 0
A21: =A19+0.1 -> 3.3 | B21: Supply, installation and commissioning of 1100V grade multistrand, copper conductor, FRLS insulated, 4C x 1.5 Sq.mm unarmoured flexible cable & termination with Single compression cable gland, Ring type copper lugs and necessary steel bolts for interconnection between UPS & Battery breaker. | C21: LS | D21: 1 | G21: =SUM(E21:F21)*N($D21) -> 0
E22: 0 | F22: 0 | G22: =SUM(E22:F22)*N($D22) -> 0
A23: 4 | B23: MS SUPPORTING STRUCTURES | E23: 0 | F23: 0 | G23: =SUM(E23:F23)*N($D23) -> 0
E24: 0 | F24: 0 | G24: =SUM(E24:F24)*N($D24) -> 0
A25: =A23+0.1 -> 4.1 | B25: Supply & installation of fabricated MS frame approximately 600mm height suitable for 3x25 KVA UPS. MS Supports should be factory fabricated with Anticorrosive powder coating. The design of stool shall ensure uniform distribution of weight less than 400kg/Sq.m | C25: No | D25: 1 | G25: =SUM(E25:F25)*N($D25) -> 0
E26: 0 | F26: 0 | G26: =SUM(E26:F26)*N($D26) -> 0
A27: =A25+0.1 -> 4.2 | B27: Supply & installation of fabricated MS frame approximately 600mm height suitable for 3x25 KVA UPS Battery Bank. MS Supports should be factory fabricated with Anticorrosive powder coating. The design of stool shall ensure uniform distribution of weight less than 400kg/Sq.m | C27: No | D27: 1 | G27: =SUM(E27:F27)*N($D27) -> 0
E28: 0 | F28: 0 | G28: =SUM(E28:F28)*N($D28) -> 0
A29: 5 | B29: REMOTE ALARM PANEL | E29: 0 | F29: 0 | G29: =SUM(E29:F29)*N($D29) -> 0
E30: 0 | F30: 0 | G30: =SUM(E30:F30)*N($D30) -> 0
A31: 5.1 | B31: Supply, installation, testing and commissioning of Remote Alarm Panel with buzzer and display for 1 Nos 3x25 kVA UPS unit as required with interconnecting signal cables drawn in MS conduit and flexible MS conduits, fixing of conduit with necessary accessories, supports etc. Complete as per technical specification. The quoted rate shall be inclusive of metal conduits, flexible metal conduits and necessary fixing accessories, supports etc. Remote Alarm Panel with hooter and cable till BMS room need to be considered for monitoring of UPS units. | C31: No | D31: 1 | G31: =SUM(E21:F21)*N($D21) -> 0
E32: 0 | F32: 0 | G32: =SUM(E32:F32)*N($D32) -> 0
A33: 6 | B33: LOAD TESTING | E33: 0 | F33: 0 | G33: =SUM(E33:F33)*N($D33) -> 0
E34: 0 | F34: 0 | G34: =SUM(E34:F34)*N($D34) -> 0
A35: 6.1 | B35: Site testing of 3x25 kVA online, double conversion UPS systems including load testing with all necessary cables, Load bank of resistive Load @ site for testing etc. complete for UPS System | C35: LS | D35: 1 | G35: =SUM(E35:F35)*N($D35) -> 0
B37: TOTAL - UPS - WORK STATION | G37: =SUM(G11:G36) -> 0
A39: B | B39: Conventional UPS - Emegency Lighting
A40: 1 | B40: Design, manufacture, assembly, supply, installation, testing, delivery and commissioning of 6 kVA Conventional UPS Continuous rating, online, double conversion operating modular type 1 ph input and 1 ph output UPS system with IGBT rectifier as per technical specifications. The UPS Cabinet shall consist of a Breaker & breaker cabinet, rectifier / charger, a three-phase inverter, static transfer switch, Maintenance Bi-pass Switch, logic, synchronizing equipment, protective devices and accessories as required for proper operation.The UPS system is selected in N configuration. Routine tests needs to be done at factory & test reports need to be submitted. - The UPS System to be provided with Dual Input Card for both Modus Monitoring in BMS system and IP Monitoring over Network parallely including Parallel working configuration required accessories. | C40: No | D40: 1 | G40: =SUM(E40:F40)*N($D40) -> 0
E41: 0 | F41: 0 | G41: =SUM(E41:F41)*N($D41) -> 0
A42: 2 | B42: Supply, Installation, Testing and commissiong of required Ah of Valve regulated lead–acid (VRLA) Batteries of approved make suitable for 6 kVA sets to give minimum 90 minutes backup. The rate shall include bankwise battery monitoring system. Power factor 0.93 to be considered for battery sizing. | C42: Set | D42: 1 | G42: =SUM(E42:F42)*N($D42) -> 0
E43: 0 | F43: 0 | G43: =SUM(E43:F43)*N($D43) -> 0
...
