Workbook

Sheet Master - Summary
A1: PROJECT : DHL - Chennai | D1: Project Area in SFT | E1: 70000
A2: BOQ : MEP
A3: SL. NO | B3: ITEM DESCRIPTION | C3: TOTAL AMOUNT (INR) | D3: RATE / SFT | E3: REMARKS
A5: 1 | B5: HVAC | C5: ='Summary - HVAC'!C18 -> 26373771 | D5: =C5/E$1 -> 376.76815
A6: =A5+1 -> 2 | B6: Electrical | C6: ='Summary - Electrical'!C9 -> 0 | D6: =C6/E$1 -> 0
A7: =A6+1 -> 3 | B7: ELV | C7: ='ELV Summary'!C11 -> 0 | D7: =C7/E$1 -> 0
A8: =A7+1 -> 4 | B8: Networking | C8: =Networking!F61 -> 0 | D8: =C8/E$1 -> 0
A9: 5 | B9: Plumbing & Fire Fighting | C9: ='Summary - Plumbing & Fire Fight'!C11 -> 0 | D9: =C9/E$1 -> 0
A10: 6 | B10: BMS | C10: =BMS!I95 -> 0 | D10: =C10/E$1 -> 0
B12: GRAND TOTAL | C12: =SUM(C5:C11) -> 26373771 | D12: =C12/E$1 -> 376.76815

Sheet Summary - HVAC
A1: PROJECT : DHL - Chennai
A2: HVAC SUMMARY
A3: S.NO. | B3: ITEM DESCRIPTION | C3: AMOUNT(INR) | D3: REMARKS
A5: 1 | B5: =HVAC!B5 -> EQUIPMENTS | C5: =HVAC!F22 -> 943750
A6: 2 | B6: =HVAC!B24 -> CO2 & FLUSHING | C6: =HVAC!F67 -> 96880
A7: 3 | B7: =HVAC!B69 -> PIPING & ACCESSERIES | C7: =HVAC!F107 -> 944040
A8: 4 | B8: =HVAC!B109 -> DUCTING & AIR TERMINAL WORKS | C8: =HVAC!F193 -> 9271260.7
A9: 5 | B9: =HVAC!B195 -> INSULATION | C9: =HVAC!F215 -> 1672720
A10: 6 | B10: =HVAC!B217 -> VFD & Starter Panel | C10: =HVAC!F234 -> 171000
A11: 7 | B11: =HVAC!B236 -> EQUIPMENT | C11: =HVAC!F293 -> 3390912
A12: 8 | B12: =HVAC!B295 -> PIPING | C12: =HVAC!F341 -> 1311060
A13: 9 | B13: =HVAC!B343 -> ELECTRICAL WORKS | C13: =HVAC!F427 -> 335230
A14: 10 | B14: =HVAC!B429 -> VAV BOXES WORKS | C14: =HVAC!F483 -> 3235250
A15: 11 | B15: =HVAC!B485 -> HYDROGEN EXHAUST | C15: =HVAC!F577 -> 159350
A16: 12 | B16: FAHU System | C16: ='FAHU System'!I50 -> 4842318
B18: GRAND TOTAL | C18: =SUM(C5:C16) -> 26373771

Sheet HVAC
A1: PROJECT : DHL - Chennai
A2: SUBJECT : HVAC
A3: SL.NO | B3: ITEM DESCRIPTION | C3: UNIT | D3: QTY | E3: RATE (INR) | F3: AMOUNT (INR)
A5: 1 | B5: EQUIPMENTS
A7: =A5+0.01 -> 1.01 | B7: AIR HANDLING UNITS FLOOR MOUNTED OR CEILING SUSPENDED
B8: Supply, installation, testing and commissioning of factory fabricated Double Skinned Chilled Water Air- handling unit floor mounted (Horizontal / Vertical to suit site) or ceiling suspended horizontal type, fabricated out of extruded aluminium section with 0.6mm pre-plasticized / pre-coated Galvanised steel sheet outside & 0.6 mm plain Galvanised steel sheet inside with EC Plug Fans IE5 type motor, 4/6/8 Row cooling coil made of Aluminium finned Copper tube with coil section of copper header and MS adaptor, filter section with filters as mentioned below,UV section of 200 mm in length complete with UV lamps, polished stainless steel drain pan made out of 20 G sheet duly insulated. Drain pan insulation shall be minimum 19mm closed cell nitrile.The AHU panels shall be insulated with 48 mm thick & 48 Kg/m³ density PU foam. The maximum permissible sound pressure level of the AHU shall not exceed 50-60 dbA measured at 1.5 m from AHU surface for the recommended range of operation.The motor & fan assembly shall be mounted on Aluminium extruded section only. The complete AHU shall conform to standard specification. AHU shall be supplied with commissioning filter of both type wherever applicable as specified above which shall be replaced with actual pre and esp filters. The capacity of Air-handlers shall be as follows. Mixing box with aluminium volume control dampers for return air and fresh air complete as per specifications and drawings.
B9: The AHU panel shall be insulated with 48 mm thick injected fire retardent PUF of density 40+/-2 Kg/m³ . Marine light with limit switch shall be provided . The complete AHU shall conform to standard spec.The face velocity across cooling / heating coil, filters should not exceed 500 FPM. The capacities of airhandling shall be as follows, All paint shall be Low VOS as per IGBC
B10: The polished stainless steel drain pan of 1.25 mm (18 G) thick duly insulated with 13 mm thick nitrile rubber under cooling coil shall be provided. Motor & belt drive package/ direct driven arrangement, belt guard etc for belt driven blower without face and bypass dampers.
B11: NOTE (1) The Air velocity across the filter should not be more then 500 FPM. (2) CSU- Ceiling Suspended Units | FM- Floor Mounted (3) All CSU shall be provided with drain Pumps (4) All AHUs shall be with S.A damper. (5) Chilled water coil should have inlet and outlet temperature as 6.7°C & 12.2°C respectively. (6) Suitable Rubber bellow required for chilled water pipes to avoid the direct contact . (7) All fans should be AMCA certified. (8) All AHUs shall be provided with EC Plug Fan & ESP filter (Electrostatic Precipiator) of suitable capacity
B13: CSU AHU -2000 CFM, 5.0 TR with 50mm S.P. with MERV-7 filters, with 4 row deep cooling Coil. | C13: Nos | D13: 6 | E13: 150000 | F13: =E13*D13 -> 900000
A15: =A7+0.01 -> 1.02 | B15: Electronic Thermostat BMS compatible
B16: Supply of Electronic Heating and Cooling Thermostat (AC 220 V and DC 24 V) with LCD display with necessary control cabling for AHUs & FCUs complete as required. The thermostat shall have provision of setting of space temperature and display of the same, fixing of suitable transformer complete with interconnecting wiring between 2 way modulating valve and thermostat.
B17: Supply, Installation & Testing Temperature control with Wiring complete as required for AHU's. All Thermostats for Summer/Winter System of AHUs/ CSUs Shall be Heat Cool with change over. | C17: Nos | D17: 6 | E17: 4200 | F17: =E17*D17 -> 25200
A19: =A15+0.01 -> 1.03 | B19: FLEXIBLE CANVASS CONNECTIONS
B20: Supply, Installation, Testing of 125mm deep antivibration flexible joints at the outlet of air handling units/inline fans. Flexible connections shall be constructed using imported fire retardant fabric with extruded aluminium frame/flange on both sides of approved make. | C20: RMT | D20: 7 | E20: 2650 | F20: =E20*D20 -> 18550
B22: TOTAL ITEM NO. 1 (EQUIPMENT) | F22: =SUM(F5:F21) -> 943750
A24: 2 | B24: CO2 & FLUSHING
A26: =A24+0.01 -> 2.01 | B26: CO2 SENSOR for rooms with display
B27: SITC of CO2 Sensor for rooms only with display with (WiFi Enable/BMS Compatible) | C27: Nos | D27: 6 | E27: 11980 | F27: =E27*D27 -> 71880
A29: =A26+0.01 -> 2.02 | B29: INDOOR AIR QUALITY MONITOR WITHOUT DISPLAY
B30: Supply, Installation, Testing & commissioning of IAQ Monitor to measure the levels of PM 2.5, VOCs, CO2, Temperature, Humidity on a real time basis. The IAQ Monitor shall be RS485 enabled and should be capable of getting connected with Wi-Fi. Units should have dedicated data browse i.e. sim card etc. The Monitor should be capable of sending the indoor air quality information on display Screen/Mobile/Workstation as per Client's requirement. The Monitor should indicate the quality of air through changing the colours as per the NAAQS standards and should meet the WELL building standards. The monitor should be a 3 tier architecture including sensor Hardware, secure cloud infrastructure, monitoring apps including dashboard, android/IOS. Quoted price shall be inclusive of all necessary arrangement as required to make the unit proper functional. (LED Screen not included.) Quoted shall also be inclusive of individual network arrangement as required for monitoring/integration. Note: The System should provide Soft Assistance in form of Notifications and Alerts for Periodic Preventive Maintenance. | C30: Nos
A32: 2.03 | B32: Central Air Cleaner for AHUs
B33: Electrically Charged Filter Supply, Installtion, Testing & Commissioning of hybrid Air purification for ceiling suspended Ductable indoor units and AHU The air purification system should be suitable suitable to reduce harmful pollutants like particulate matter (PMx), PM 2.5, allergens, smoke, bacteria, pathogens etc. based on below principle technology viz; Impingement, Polarization and Agglomeration for passive air purification. It should be a slim structured unit specifically designed for integration in Return Air path of ceiling suspended indoor units and AHUs. EAC shall be equivalent to Merv-14 or Higher efficiency for AHU and Ductable Units with low pressure drop. It should have 3x working principles and it should be aluminum based or powder coated steel casing and should be self-contained. The EAC shall have UL certified core components. The units shall meet ANSI/ASHRAE 52.2/ISO16890 standards and have valid test report to verify filtration efficiency. The Supplier shall carry UL2998 certificate for testing against Zero Ozone Emission either as Whole unit or included components. The filter shall be capable of effectively reducing haze particles, smoke, mold spores, and airborne bacteria, and shall be supported by test reports from NABL-accredited laboratories verifying its performance. The Electronic Air Cleaner shall be GreenPro certified by CII–IGBC (Confederation of Indian Industry – Indian Green Building Council to support ECBC compliance by ensuring energy-efficient operation, low pressure drop, and improved indoor air quality . The test report for pressure drop need to be submitted for passive air purification and the same shall be demonstrated at site."
B34: Electronic filters should consist of an Internet of Things (IoT) based Smart Filtration option employing a 3-Tier Architecture. This architecture would serve to identify pressure drops across the filter, indicating when a cleaning & replacement is necessary due to clogged filters.
B35: Vendor to study local ambient air data and quality of air before proposing & finalizing air cleaner. Unit should be suitable to meet all IAQ parameters i.e. PM 2.5, PM-10 etc. as per ASHRAE/ANSI/ NEA & OSHA etc.
B36: Technical submittals with supported catalog shall be submitted for approval prior to procurement. Quoted price shall be inclusive of all necessary arrangement as required for fixing of filter section within AHU and control wiring etc.
A37: a | B37: 12600 CFM Floor Mounted AHU | C37: Nos
A38: b | B38: 12150 CFM Floor Mounted AHU | C38: Nos
A39: c | B39: 11700 CFM Floor Mounted AHU | C39: Nos
A40: d | B40: 10350 CFM Floor Mounted AHU | C40: Nos
A41: e | B41: 2000 CFM Ceiling Suspended AHU | C41: Nos
A43: 2.04 | B43: Active Purification System (BIO POLAR IONISER)
B44: The Active Air Purification system should consist of Supply, Installation, Testing and commissioning of Bipolar Ionisation System. The Bipolar Ionisation System must be a combination of Tube Based Model and Needle Point Model (Needle Point should have Nitinol (nickel titanium) Needles) and Carbon Fibre Brush Model, System should produce positive and negative ions for creating a Bio Climate rich in ions and hence neutralising harmful pollutants including pathogens, Volatile Organic Compounds and Particulate Matter. Product should have UL 867 and UL 2998 certification (for zero ozone emission). The OEM shall have Efficacy test report on COVID from any Internationally/Nationally recognised Laboratory. The technology shall also have UL 2043 for Fire and Smoke safety certificate , ISO 16000 for safety against any Organic Byproduct and CSA C22.2#187 , CARB certification.
B45: Manufacturers shall provide Test report from Internationally/Nationally recognized Lab for proven efficacy on below pathogens with minimum kill rates for the following pathogens given the allotted time and in a space condition: a) SARS-CoV-2 (COVID-19) Human Strain b) MS2 Bacteriophage (Surrogates COVID-19) c) Omicron Variant of SARS-CoV-2 d) H1N1 e) Total Bacterial Count Reduction rate of more than 90% from NABL Accredited Lab f) Yeas & Mold/Total fungal count Reduction rate of more than 90% from NABL Accredited Lab
B46: Total Nos. of ionisers shall be as per air quantity distributed in individual duct drawn from main plenum/ AHUs in approved shop drawing.
A47: a | B47: 12600 CFM Floor Mounted AHU | C47: Nos
A48: b | B48: 12150 CFM Floor Mounted AHU | C48: Nos
A49: c | B49: 11700 CFM Floor Mounted AHU | C49: Nos
A50: d | B50: 10350 CFM Floor Mounted AHU | C50: Nos
A51: e | B51: 2000 CFM Ceiling Suspended AHU | C51: Nos
...

Sheet FAHU System
A1: PROJECT : DHL - Chennai
A2: SUBJECT : FAHU System
A3: SL.NO | B3: ITEM DESCRIPTION | C3: UNIT | D3: QTY | E3: SUPPLY RATE (INR) | F3: INSTALLATION RATE (INR) | G3: SUPPLY AMOUNT (INR) | H3: INSTALLATION AMOUNT (INR) | I3: TOTAL AMOUNT (INR)
A6: 1 | B6: Part A
A8: 1.01 | B8: Treated Fresh Air Handling Units VRF Compatible
B9: SITC of Factory built and Site assembled Vertically floor mounted TFA.DX type double skin air handing units complete with
B10: Double skin construction : Inner skin 0.8 mm GI and outer skin 0.8 mm thk precoated GI. Thickness of insulation- 45 mm CFC free PUF injected with density of 40+/-42 kg/cum.
B11: Frame work: Thermal break aluminium profile with thermal barrier & Coving.
B12: Unit Base ; Heavy Duty GSS
B13: Drain pan : 18 G stainless steel duly insulated with 12 mm thick nitrile rubber (Armacell Class O Only)
B14: 8 row deep DX cooling coil – Multiple distributors. (Coil Surface area ≤ 500 FPM)
B15: Fan Section: DIDW Backward curve centrifugal fan, EFF-2 motor, (The Fan Section to be provided with double glass view window, light fixtures and Limit switch), Screen protection door, fire proof double canvass connections (Fungal Resistant and Lint free).
B16: SA section with manual gear operated SA damper.
A17: a | B17: VERTICAL FLOOR MOUNTED 1580 CFM @ 50 mm WG (EXTERNAL STATIC PRESSURE), (TFA-01) | C17: Nos | D17: 6 | E17: 60840 | F17: 7500 | G17: =+E17*D17 -> 365040 | H17: =+D17*F17 -> 45000 | I17: =H17+G17 -> 410040 | J17: QUOTED FOR 5.5TR VRF TFA INDOOR UNIT
A19: 1.02 | B19: Supply, installation, commissioning and testing of imported Air - cooled type VRF system with Inveter DC Twin Rotary with enviroment friendly green Refrigerant R-410A. (Supply of Variable Refrigerant Volume / Flow Out Door package consisting of high efficiency scroll type compressors, condensers, fans, control panels etc. The Compressor installed in the Outdoor Unit shall be equipped with Invertor Controller, and capable of changing the rotating speed to follow variations in cooling. The outdoor unit shall be with all necessary safety devices such as high pressure switch, low pressure switch, fuse, crankcase heater, fusible plug, over current protection for invertor and short recycling guard timer. All Outdoor Units shall have necessary Anti-corrosive treatments complete with all necessary valves, accessories and supports.)
B20: Outdoor Units
B21: 10 HP (Top Discharge) | C21: Nos | D21: 6 | E21: 301560 | F21: 10000 | G21: =+E21*D21 -> 1809360 | H21: =+D21*F21 -> 60000 | I21: =H21+G21 -> 1869360
A23: 2 | B23: PART -B : Low Side Works
A25: 2.01 | B25: All refrigerant Soft/Hard drawn copper piping interconnecting Refrigerant Copper piping between Indoor & Outdoor units covered with Nitrile Rubber Insulation
A26: a | B26: Gas Line - 19 mm thick Insulation | C26: Rmt | D26: 91 | E26: 1358 | F26: 280 | G26: =+E26*D26 -> 123578 | H26: =+D26*F26 -> 25480 | I26: =H26+G26 -> 149058
A27: b | B27: Liquid Line - 13 mm thick Insulation | C27: Rmt | D27: 91 | E27: 550 | F27: 240 | G27: =+E27*D27 -> 50050 | H27: =+D27*F27 -> 21840 | I27: =H27+G27 -> 71890
A29: 2.02 | B29: All communication / control cabling works between all indoor and outdoors units. | C29: Rmt | D29: 183 | E29: 113 | F29: 26 | G29: =+E29*D29 -> 20679 | H29: =+D29*F29 -> 4758 | I29: =H29+G29 -> 25437
A31: 2.03 | B31: PVC Drain piping for the units with insultion | C31: Rmt | D31: 91 | E31: 60 | F31: 20 | G31: =+E31*D31 -> 5460 | H31: =+D31*F31 -> 1820 | I31: =H31+G31 -> 7280
A33: 2.04 | B33: UV coating on exposed ref. pipe | C33: Rmt | D33: 183 | E33: 250 | F33: 50 | G33: =+E33*D33 -> 45750 | H33: =+D33*F33 -> 9150 | I33: =H33+G33 -> 54900
A35: 2.05 | B35: MS stand painted with two coats of red oxide and two coats of enamel paint. | C35: Nos | D35: 6 | E35: 6000 | F35: 500 | G35: =+E35*D35 -> 36000 | H35: =+D35*F35 -> 3000 | I35: =H35+G35 -> 39000
A37: 2.06 | B37: Electrical Panel with Voltage Scanner for preventig of Under voltage/over volta ge/single phasing/phase reverse. | C37: Nos | D37: 1 | E37: 80000 | F37: 2500 | G37: =+E37*D37 -> 80000 | H37: =+D37*F37 -> 2500 | I37: =H37+G37 -> 82500
A39: 2.07 | B39: Control cabling between panel and VRF units. | C39: Rmt | D39: 274 | E39: 837 | F39: 30 | G39: =+E39*D39 -> 229338 | H39: =+D39*F39 -> 8220 | I39: =H39+G39 -> 237558
A41: 2.08 | B41: GSS Ducting Work-24 G | C41: Sqm | D41: 883 | E41: 945 | F41: 240 | G41: =D41*E41 -> 834435 | H41: =F41*D41 -> 211920 | I41: =H41+G41 -> 1046355
A43: 2.09 | B43: Thermal insulation of ducting with fire retardant closed cell nitrile rubber (Class-O) insulation with aluminum foil. 19 mm thick. | C43: Sqm | D43: 1059 | E43: 520 | F43: 160 | G43: =+E43*D43 -> 550680 | H43: =+D43*F43 -> 169440 | I43: =H43+G43 -> 720120
A45: 2.1 | B45: UP coating of exposed duct | C45: Sqm | D45: 139 | E45: 240 | F45: 120 | G45: =+E45*D45 -> 33360 | H45: =+D45*F45 -> 16680 | I45: =H45+G45 -> 50040
A47: 2.11 | B47: Supply air grille with VCD | C47: Sqm | D47: 6 | E47: 9630 | F47: 3500 | G47: =+E47*D47 -> 57780 | H47: =+D47*F47 -> 21000 | I47: =H47+G47 -> 78780
B48: The frame and blades shall be of high quality extuded aluminium construction with the advantages of corrosion resistance and rigidity. Louvered type core shall be fxed to the frame with aluminium pins loaded with steel springs. Core can be easily removable and interchangeable to allow for maximum fexibility in installation, maintenance and damper adjustment. Damper shall be fxed rigidly to the frame by aluminium rivets. Fixing by spring clips as option. Damper blades shall be separated from its frame by nylon bushes. Opposed blade damper shall be screw operated from the face opening of the diffuser after removing the internal core
B50: GRAND TOTAL | G50: =SUM(G11:G49) -> 4241510 | H50: =SUM(H11:H49) -> 600808 | I50: =SUM(I11:I49) -> 4842318

Sheet Summary - Electrical
A1: PROJECT : DHL - Chennai
A2: ELECTRICAL SUMMARY
A3: SR. NO. | B3: ITEM DESCRIPTION | C3: AMOUNT (INR) | D3: REMARKS
A5: 1 | B5: Electrical Works | C5: ='Electrical Work'!F437 -> 0
A6: 2 | B6: Lighting Works | C6: ='Light Fixture'!L26 -> 0
A7: 3 | B7: UPS & Batteries | C7: ='UPS & Batteries'!F72 -> 0
B9: GRAND TOTAL | C9: =SUM(C5:C8) -> 0

Sheet Electrical Work
A1: PROJECT : DHL - Chennai
A2: SUBJECT : Electrical Work
A3: SL.NO | B3: ITEM DESCRIPTION | C3: UNIT | D3: QTY | E3: SUPPLY & INSTALLATION RATE (INR) | F3: TOTAL AMOUNT (INR)
A5: 1 | B5: PANEL & DBs
A7: =A5+0.01 -> 1.01 | B7: Supply, Installation, testing & commissioning of LT switchboards compartmental cubicle type freestanding with appropriate cable entries, front operating, front maintained wherever required complete with base frame etc. as required and as per IS 8623, Technical specifications & Single line diagram. Panels shall be CPRI approved & NFPA 70E complied, fabricated out of 14 / 16 SWG CRCA sheet, and surface treated with phosphating seven tank process and duly powder coated with RAL 9016. NOTE:- 1)TEST AT MANUFACTURERS WORK All routine tests specified in IEC 61439-1 & 2: • HV test • IR Test before & after HV Test • Primary/Secondary injection tests 2) ALL FLOOR MOUNTED PANEL SHALL BE TYPE TESTED AS PER THE IEC61439 - 1 & 2 - Following 13 type tests to be carried and certified by OEMs - a) Strength of material and parts, b) Degree of protection of enclosures, c) Clearances and creepage distances, d) Effective continuity between parts and PE, e) Effectiveness of the ASSEMBLY for external faults, f) Incorporating of apparatus Internal electrical circuits and connections, g) Terminals for external conductors, h) Power frequency withstand voltage, i) Impulse withstand voltage, j) Temperature rise limits, k) Short - circuit withstand strength, l) EMC, m) Mechanical operation. 3) Vendor to consider testing guidelines as per IEC61439 and testing refer the technical specification section A4. 4) Vendor to consider the LOTO (Lock Out Tag Out) Arrangement for all the panels/DB's. 5)Vendor to submit the GA drawings along with offer. 6)Electrical design shall include fully rated (for available fault current) equipment. 7)Provision shall be top/bottom entries to be considered with aluminum gland plate of 3 mm thickness. 8)Provision for Door earthing to be considered. 9) Refer SLD. Ref no BLK/SLD/01
B8: i) All MCCBS shall be with Extended type Front door operating handle, Phase Spreaders & Phase Barriers.
B9: ii) Metering CT's burden & accuracy class will be as per the SLD.
B10: iii)CT's shall be "CAST RESIN" type .
B11: iv)MCCB's up to and including 200 Amp shall be with adjustable thermal-magnetic release for over current and short circuit protection with EFR on CBCT. MCCB 250 amp and above shall be with Microprocessor based release for over current, instantaneous, short circuit protection and earth fault protection(LSIG). All MCCBs with Thermal Magnetic Protection will be adjustable from 70-100 %.
B12: v) All indication lights shall be LED type.
B13: vi) All meter shall be "DIGITAL" type with LCD display.
B14: vii) Breaking Capacity of all MCCB's are Ics Service Breaking Capacity
B15: viii) Degree of Protection shall be IP:42 for indoor panel & IP:65 for outdoor panel
B16: ix) Panel Manufacturer should have authorization from International Certifying agency or Indian government lab for manufacturing LT switchboards as per IEC 61439.
B17: x) "R,Y,B,ON,OFF,TRIP " Indicating lamp shall be provided for all 3 phase MCCB incoming and outgoing feeders.
B18: xi) Control SP MCB's of 2A Rating shall be provided for each metering circuit.
B19: xii) 30% spare control terminal to be provided.
... B24: All panels to have provision for panele fire speration tubing, routing and required cutouts
A26: a | B26: UPS INPUT PANEL | C26: Nos | D26: 1 | F26: =D26*E26 -> 0
B27: Main Incomer - 2 x 250 Amp 4P MCCB (36 KA)
B28: Metering & Indication - Multi Function Meter (PM 5000) with suitable size of CT and 3 Nos. phase indicating lamp
B29: Provide TVSS 40kA. class-II
B30: Provide CBCT with 1-10A ELR
B31: Buscoupler - 1 x250 Amp 4P MCCB (50 KA)
B32: Busbars -300 Amp TPN Al
B33: Outgoings :
B34: 3x 200 A TPN MCCB (36 KA)
B35: 4x 100 A TPN MCCB (36 KA)
B36: 3x 63A TPN MCCB (36 KA)
B37: 1x 63A TPN MCB (10 KA)
A38: b | B38: SDB- L&P | C38: Nos | D38: 1 | F38: =D38*E38 -> 0
B39: Main Incomer -2x 250 Amp 4P MCCB (36 KA)
B40: Metering & Indication - Multi Function Meter (PM 2130) with suitable size of CT and 3 Nos. phase indicating lamp
B41: Provide TVSS 40kA. class-II
B42: Provide CBCT with 1-10A ELR
B43: Busbars - 300 Amp TPN Al
B44: Buscoupler - 1 x 250 Amp 4P MCCB (50 KA) with mechanical interlocking 3 lock + 2keys
B45: Outgoings :
B46: 2x 100 A TPN MCCB (36 KA)
B47: 2x 100 A TPN MCCB (36 KA) with KWH
...

Sheet Light Fixture
A1: PROJECT : DHL - Chennai
A2: SUBJECT : Light Fixture
A3: SL.NO | B3: LIGHT TYPE AS PER DRAWING | C3: ITEM DESCRIPTION | D3: REF. IMAGE | E3: LOCATION | F3: UNIT | G3: QTY | H3: SUPPLY RATE(INR) | I3: INSTALLATION RATE (INR) | J3: SUPPLY AMOUNT (INR) | K3: INSTALLATION AMOUNT (INR) | L3: TOTAL AMOUNT (INR)
C4: Supply, Installation, Testing and Commissioning of Light fixtures and lamps with all accessories, fixing on the wall / ceiling/false ceiling with wooden blocks, screws ,hardware's ,suspended chain hooks as required as per the site conditions (including the earthing of fixture)
C5: Note : All light fixtures should have CRI < 80, luminaire System efficacy of >110 lm/watt, PF >0.95, CCT 5000K, Anti glare diffuser. It is proposed to achieve USGBC LEED Gold Certification for this Project. Vendor to go through the LEED documents & comply to the requirement in reference to this BOQ & Specification.
A6: 1 | B6: DOWNLIGHT | C6: Recessed LED Downlighter ,made up of pressure die cast aluminum housing with high efficiency PS diffuser, LED Used shall be SMD type and fixture should have minimum efficacy at System level 120 lumens/watt with Minimum system Lumens 1200 , CCT of 4000K (SDCM<=5), CRI Ra >=80, PF >0.9, an Operating working temp range - 0°C < Ta < 45°C & operating Voltage Range of 160-270 V AC. Minimum Internal Surge Protection 2.5KV. Manufacturer shall have inhouse lab approved by NABL or ministry of science of govt of India. LM 79 and LM80 reports need to be submitted from a NABL/UL accredited lab to verify above parameters. Both the fixture and Driver should have separate BIS approval. | E6: Cabins, Washroom & Meeting Rooms, Support Areas | F6: Nos. | G6: 335 | J6: =H6*G6 -> 0 | K6: =I6*G6 -> 0 | L6: =K6+J6 -> 0
A7: 2 | B7: HANGING CYLINDER LIGHT | C7: Supply of Suspended Cylinderical Downlight, 1000 lm, Having CCT option of 4000K, SDCM<5, CRI≥80, Efficacy ≥100lm/W, Surge 2.5kV internal, THD ≤10% (At Full Load), pf ≥0.9. The luminaire housing shall be Extruded aluminum housing, White/Black finish , Product Dia 55mm, Height 150mm. The product should have beam angle option of 40° beam angle. The operating volateg range shall be 140-270V. The product shall be Class B serviceability. Manufacturer shall have inhouse lab approved by NABL or ministry of science of govt of India. LM 79 and LM80 reports need to be submitted from a NABL/UL accredited lab to verify above parameters. Both the fixture and Driver should have separate BIS approval. | E7: Workstation Areas | F7: Nos. | G7: 290 | J7: =H7*G7 -> 0 | K7: =I7*G7 -> 0 | L7: =K7+J7 -> 0
A8: 3 | B8: 2 X 2 PANEL LIGHT | C8: Supply of recessed mounted 2X2 LED panel ,made of CRCA housing with high efficiency PS Diffuser. LED Used shall be SMD type and fixture should have minimum efficacy at System level >=100 lumens/watt with Minimum system Lumens 3600 & Max , Life of fixture : 50000 burning Hrs. @ L70B50 Lumen maintenance,CCT-4000K/5700K/6500K, (SDCM<=5), CRI Ra >=80, THD<10%, PF >0.95, an operating Voltage Range of 140 - 270 VAC.Minimum Internal Surge Protection 3.0KV & IP20/IK02 protection, Manufacturer shall have inhouse lab approved by NABL or ministry of science of govt of India. LM 79 and LM80 reports need to be submitted from a NABL/UL accredited lab to verify above parameters. Both the fixture and Driver should have separate BIS approval . | E8: Store & Support Room & Critical Room | F8: Nos. | G8: 60 | J8: =H8*G8 -> 0 | K8: =I8*G8 -> 0 | L8: =K8+J8 -> 0
A9: 4 | B9: LINEAR LIGHT 1500mm | C9: Supply of continues Suspended 5ft slim Linear LED made of extruded Aluminium with white/black powder coaed finish with high efficiency Opal Diffuser.The luminaire shall have a width of not more than 50mm(± 3mm), and shall be available in multiple lengths. LED Used shall be SMD type with approx system Lumens 2750 (+-10%) & efficacy 100lm/W, Life of fixture : 50000 burning Hrs. @ L70B50 Lumen maintenance, CCT of 4000K (SDCM<=5), CRI 80, PF ≥0.95, THD≤ 10%, an Operating working temp range - 0°C < Ta < 45°C & operating Voltage Range of 140-270 V AC having Class - I protection & serviceability of Class B. Minimum Internal Surge Protection 3.5kV. The manufacturer shall submit the following reports before supply of material for approvals LM79 issued by NABL accredited lab, LM80 issued by LED manufacturer, | E9: Linear Workstations | F9: Nos. | G9: 182 | J9: =H9*G9 -> 0 | K9: =I9*G9 -> 0 | L9: =K9+J9 -> 0
A10: 5 | B10: SUSPENDED HANGING LIGHT | C10: Suspended Curvilinear Slim 50mm Flushed Flat Micro prismatic Diffuser 50mm height x 1000mm length. Fixture to be made of extrusion Aluminum housing white/Black powder coating. LED Used shall be SMD type with Minimum system Lumens 1800 Lumen with System efficacy >100lm/W, UGR<19 Life of fixture : 50000 burning Hrs. @ L70B50 Lumen maintenance, CCT of 400k.(SDCM<=5), CRI 80, an Operating working temp range - 0°C < Ta < 45°C & operating Voltage Range of 140-270 V AC. Minimum Internal Surge Protection 4KV. Current Ripple necessarily <10%.Luminaire with Ingress & IK protection Rating of of IP20 & IK02.The driver shall be compliant to IEC61347-2-13, IEC62384 & IEC6100-3-2. Driver should be D4I Certified & compliant to DALI Part 251/252/253 with Rated input voltage range 202-254, Power factor 0.99%, efficiency of ≥ 91% Output current ripple LF<4%. The driver & Luminaire shall be BIS registered.The driver & Luminaire shall be BIS registered. The driver shall be designed for continuous operation of minimum 12-15Hrs a day. The luminaire driver shall be of the same make/manufacturer as that of LED luminaires. Luminaire manufacturer must have In-house NABL accredited lab in India to conduct LM79, Type test as per IS10322, "FAT" before dispatch as per IS 10322 & IK Test. The successful bidder must submit the NABL accreditation certificate for Luminaire manufacturer along with before supply of LED Luminaires for approval. Successful bidder shall submit the following reports before supply of material for approvals LM79 issued by NABL accredited lab, LM80 issued by LED manufacturer, Type Test Certificate for luminaire as issued by NABL accredited lab, IK Test Report issued by NABL accredited lab, RoHS compliance issued by LED luminaire manufacturer, BIS certificate for LED. | E10: Passage & 120 degree Workstations, Collab, Breakout Areas | F10: RMT | G10: =980 -> 980 | J10: =H10*G10 -> 0 | K10: =I10*G10 -> 0 | L10: =K10+J10 -> 0
A11: 6 | B11: SURFACE PROFILE LED LIGHT ( 20 nos) | C11: Supply of continues surface Linear LED made of extruded Aluminium with white/black powder coaed finish with high efficiency Opal Diffuser.The luminaire shall have a width of not more than 50mm(± 3mm), and shall be available in multiple lengths. LED Used shall be SMD type with approx system Lumens 2200 (+-10%) & efficacy 100lm/W, Life of fixture : 50000 burning Hrs. @ L70B50 Lumen maintenance, CCT of 4000K (SDCM<=5), CRI 80, PF ≥0.95, THD≤ 10%, an Operating working temp range - 0°C < Ta < 45°C & operating Voltage Range of 140-270 V AC having Class - I protection & serviceability of Class B. Minimum Internal Surge Protection 3.5kV. The manufacturer shall submit the following reports before supply of material for approvals LM79 issued by NABL accredited lab, LM80 issued by LED manufacturer, | E11: Cabins, Command Centre, Training Room | F11: RMT | G11: 252 | J11: =H11*G11 -> 0 | K11: =I11*G11 -> 0 | L11: =K11+J11 -> 0
A12: 7 | B12: SUSPENDED PROFILE LED LIGHT ( 7 nos) | C12: Supply of continues Suspended 4ft slim Linear LED made of extruded Aluminium with white/black powder coaed finish with high efficiency Opal Diffuser.The luminaire shall have a width of not more than 50mm(± 3mm), and shall be available in multiple lengths. LED Used shall be SMD type with approx system Lumens 2200 (+-10%) & efficacy 100lm/W, Life of fixture : 50000 burning Hrs. @ L70B50 Lumen maintenance, CCT of 4000K (SDCM<=5), CRI 80, PF ≥0.95, THD≤ 10%, an Operating working temp range - 0°C < Ta < 45°C & operating Voltage Range of 140-270 V AC having Class - I protection & serviceability of Class B. Minimum Internal Surge Protection 3.5kV. The manufacturer shall submit the following reports before supply of material for approvals LM79 issued by NABL accredited lab, LM80 issued by LED manufacturer, | E12: Meeting Room 6PAX | F12: RMT | G12: =15.6*4 -> 62.4 | J12: =H12*G12 -> 0 | K12: =I12*G12 -> 0 | L12: =K12+J12 -> 0
A13: 8 | B13: PENDANT LIGHT | C13: Tense pendant hanging light set of 4 700mm Dia – 1 Qty 600mm Dia – 2 Qty 450mm Dia – 1 Qty" | E13: Reception | F13: Nos. | G13: 1 | J13: =H13*G13 -> 0 | K13: =I13*G13 -> 0 | L13: =K13+J13 -> 0
A14: 9 | B14: DECORATIVE LIGHT - 4PAX MEETING ROOM | C14: Rectangular ribbon suspended linear light with curved edges, black body, size – 1200 x 1200 mm, with 20 W/mtr, CRI < 80, luminaire system efficacy of >110 lm/watt, with flicker-free DALI dimmable driver. | E14: Meeting Room 4PAX | F14: Nos. | G14: 1 | J14: =H14*G14 -> 0 | K14: =I14*G14 -> 0 | L14: =K14+J14 -> 0
A15: 10 | B15: DECORATIVE LIGHT - BREAKOUT AREA, RECEPTION | C15: Rectangular linear light with curved edges, black body, size – 2700 x 2100 mm, continuous rectangular shape with 1 driver for every 4 mtr, CRI < 80, luminaire system efficacy of >110 lm/watt, with flicker-free DALI dimmable driver. | E15: Reception, Breakout Area | F15: Nos. | G15: 9 | J15: =H15*G15 -> 0 | K15: =I15*G15 -> 0 | L15: =K15+J15 -> 0
A16: 11 | B16: DECORATIVE LIGHT - BREAKOUT AREA | C16: Rectangular linear light with curved edges, black body, size – 3900 x 2400 mm, continuous rectangular shape with 1 driver for every 4 mtr, CRI < 80, luminaire system efficacy of >110 lm/watt, with flicker-free DALI dimmable driver. | E16: Breakout Area | F16: Nos. | G16: 2 | J16: =H16*G16 -> 0 | K16: =I16*G16 -> 0 | L16: =K16+J16 -> 0
A17: 12 | B17: DECORATIVE LIGHT - BOARDROOM | C17: Custom linear light, black body, size – 5800 x 1850 mm. | E17: Boardroom | F17: Nos. | G17: 1 | J17: =H17*G17 -> 0 | K17: =I17*G17 -> 0 | L17: =K17+J17 -> 0
A18: 13 | B18: DECORATIVE LIGHT - INTERVIEW ROOM | C18: Hanging decorative light | E18: Interview Room | F18: Nos. | G18: 2 | J18: =H18*G18 -> 0 | K18: =I18*G18 -> 0 | L18: =K18+J18 -> 0
A19: 14 | B19: DECORATIVE LIGHT - ULD | C19: ULD – decorative light | E19: ULD | F19: Nos. | G19: 2 | J19: =H19*G19 -> 0 | K19: =I19*G19 -> 0 | L19: =K19+J19 -> 0
A20: 15 | B20: DECORATIVE LIGHT - MEETING ROOMS | C20: Rectangular linear light with edges, black body | E20: Meeting Rooms - 4/8/12PAX | F20: RMT | G20: 325 | J20: =H20*G20 -> 0 | K20: =I20*G20 -> 0 | L20: =K20+J20 -> 0
A21: 16 | B21: DECORATIVE LIGHT - BREAKOUT AREA | C21: Hanging light | E21: Breakout Area | F21: Nos. | G21: 15 | J21: =H21*G21 -> 0 | K21: =I21*G21 -> 0 | L21: =K21+J21 -> 0
A22: 17 | B22: INDIRECT LIGHT - WASHROOM, PANTRY | C22: Indirect LED light | E22: Washroom, Pantry | F22: RMT | G22: 310 | J22: =H22*G22 -> 0 | K22: =I22*G22 -> 0 | L22: =K22+J22 -> 0
A23: 18 | C23: Supplying, installing, testing and commissioning of suitable size of dimmer panel for 10 Nos. circuit with 6 to 8 Nos light fixture on each circuit 2000W light load, complete as required | F23: Nos. | G23: 4 | J23: =H23*G23 -> 0 | K23: =I23*G23 -> 0 | L23: =K23+J23 -> 0
A24: 19 | C24: DALLI Ballast for dimmer panel | F24: Nos. | G24: 30 | J24: =H24*G24 -> 0 | K24: =I24*G24 -> 0 | L24: =K24+J24 -> 0
A25: 20 | C25: SITC for Meeting room , touch switch all all fixing accessries complete as required. | F25: Nos. | G25: 18 | J25: =H25*G25 -> 0 | K25: =I25*G25 -> 0 | L25: =K25+J25 -> 0
C26: GRAND TOTAL | L26: =SUM(L6:L25) -> 0

Sheet UPS & Batteries
A1: PROJECT : DHL - Chennai
A2: SUBJECT : UPS & Batteries
A3: BILL OF QUANTITIES FOR UPS & BATTERIES SYSTEM
A4: Note 1: Rate should be inclusive of getting RESISTIVE 20 kW load at site & required connection with UPS set for 110% load testing as stipulated in specifications. Entire cost is to be born by Vendors .The cost of leads from Basement floor for load bank to the UPS room, Load bank etc to be borne by vendor. UPS vendor to retain load bank and load bank attendant for minimum seven days at site till the completion of testing.
A5: Note 2: To conduct factory and site load test for UPS & ISOLATION TRANSFORMER as per requirement as stated in the tender specification including sufficient sized load bank in order to perform load sharing and full load testing as required. For factory & test to & fro travel, lodging & boarding expenditure of 2person for Complete duration of Factory Testing.
A6: Note 3: For each item the specification attached to be referred. Any deviation can be filled in the specification sheet.
A7: Note 4 : All UPS are to be installed on 10th floor in Clients UPS Room. Floor UPS vendor to include the necessary lifting cost of UPS ,Battery racks ,Batteries & all other equipments, cables, termination kits, panels etc upto 10th floor in Clients UPS Room.
A8: Note 5 : UPS Vendor to study UPS Room Layout drawings & to confirm the room sizes. Also Confirm on the Cable tray sizing & routing for Battery cables. For Any changes in Battery Breaker Location, Vendor to revise the cable Tray layout & Submit the same along with tender. Cable Tray is in the scope of Eectrical Contractor.
A9: Note 6 : UPS Vendor to Study Site & Confirm Horizontal & Vertical Transportation of UPS upto UPS Room without Dismantling any component after Factory Testing is Conducted. The Lift may not be available for vertical transportation . Vendor to make all constructional damages good which occured to any part of the building during transportation.
A10: Note 7 : During integrated system testing UPS vendor to appoint two service engineers for entire tenure of IST alongwith required tools,tackles and power analysers.
A11: Note 8 : factory test to & fro travel, lodging & boarding expenditure of three person for Complete Duration of Factory Testing.
A12: SL.NO | B12: ITEM DESCRIPTION | C12: UNIT | D12: QTY | E12: RATE (INR) | F12: AMOUNT (INR) | G12: REMARK
B14: Note : Vendor to consider below items for BMS Connectivity : (Also refer UPS Specification)
A15: a | B15: Serial communication in the form of MODBUS / IP chained between all UPS & one output given including all software integration. Cabling for Daisy chaining to be considered.
A16: b | B16: Minimum Five nos of Hardwire Potential free contacts of all & critical Alarms for each UPS to be extended to BMS.The PFC terminals to be wired up to a ABS IP54 junction box with Elmex terminals ( both Junction box and terminals included by UPS vendor) for further extension by BMS vendor.
A17: c | B17: 1 no of NO + 1 no. of NC Aux. Contact to be Provided with I/P , Battery , BYPASSS , OUTPUT Breakers, Battery breaker switch outside the battery room etc.
A18: d | B18: SNMP CARD & Network card
A19: e | B19: Parallel redundant Kit
A20: f | B20: Load Bus Synchronising Kit
A21: g | B21: Temperature sensors
A23: 1 | B23: SITC of 30 KVA, 3 Phase Input 3 Phase Output Conventional UPS System with inbuilt isolation transformer High Efficiency, Low Input Current Harmonic Distortion of < 3 % and High Input Power Factor of > 0.99. Batteries for 30 kVA UPS back up time will be 15minutes each . The battery room shall be maintained at 25 deg C and UPS vendor to consider the rating accordingly. Cost to be inclusive of Batter Rack as per drawing. Each UPS to have one strings of batteries. VRLA Batteries for 30 kVA UPS considering 30 kVA as load .The UPS back up time will be 15 minutes each for 30 kVA load. The battery room will be maintained at 25 deg C and UPS vendor to consider the rating accordingly . Cost to be inclusive of Battery Rack where in battery monitoring system will be part of battery rack wherein battery IR , Current , Temperature & voltage will be monitored at real time . Warranty 2 years on Batteries. 450 mm(H) Base Frame to consider for Battery Rack matching with false flooring Battery sizing parameters:At full KVA rating,0.9 PF,10% ageing factor. Declaration will be submitted along with offer from respective battery manufacturer for battery back up calculation stating valid for end of life. | C23: Nos. | D23: 0 | F23: =E23*D23 -> 0
B24: Three Phase Input: 415V AC 3PH 4 wire, +20%, -40% 50HZ +/- 5HZ
B25: Rectifier technology: IGBT Based Rectifier
B26: Input P.F.: >0.99
B27: Input Current Harmonics: <3% | F27: =E27
B28: Three Phase output: 415V AC +/- 1%, 3Ph, 4 wire, 50HZ +/- 0.01% (Async mode)
B29: Inverter Technology: PWM IGBT
B30: High overall efficiency: 96.5% | F30: =E30
B31: M.S. Rack (Open type) with battery MCCB , interlinks & UPS to battery cable | F31: =E31
B32: Warranty 1 years on UPS | F32: =E32
B33: Network card | F33: =E33
B34: Temperature sensors | F34: =E34
F35: =E35
A36: 2 | B36: SITC of 120 KVA, 3 Phase Input 3 Phase Output Conventional UPS System with inbuilt isolation transformer High Efficiency, Low Input Current Harmonic Distortion of < 3 % and High Input Power Factor of > 0.99. Batteries for 30 kVA UPS back up time will be 15minutes each . The battery room shall be maintained at 25 deg C and UPS vendor to consider the rating accordingly. Cost to be inclusive of Batter Rack as per drawing. Each UPS to have one strings of batteries. VRLA Batteries for 120 kVA UPS considering 120 kVA as load .The UPS back up time will be 15 minutes each for 120 kVA load. The battery room will be maintained at 25 deg C and UPS vendor to consider the rating accordingly . Cost to be inclusive of Battery Rack where in battery monitoring system will be part of battery rack wherein battery IR , Current , Temperature & voltage will be monitored at real time . Warranty 2 years on Batteries. 450 mm(H) Base Frame to consider for Battery Rack matching with false flooring Battery sizing parameters:At full KVA rating,0.9 PF,10% ageing factor. Declaration will be submitted along with offer from respective battery manufacturer for battery back up calculation stating valid for end of life. | C36: Nos. | D36: 2 | F36: =E36*D36 -> 0
B37: Three Phase Input: 415V AC 3PH 4 wire, +20%, -40% 50HZ +/- 5HZ
B38: Rectifier technology: IGBT Based Rectifier
B39: Input P.F.: >0.99
B40: Input Current Harmonics: <3% | F40: =E40
B41: Three Phase output: 415V AC +/- 1%, 3Ph, 4 wire, 50HZ +/- 0.01% (Async mode)
B42: Inverter Technology: PWM IGBT
...

Sheet ELV Summary
A1: PROJECT : DHL - Chennai
A2: SUBJECT: | B2: ELV SUMMARY
A3: SR. NO. | B3: ITEM DESCRIPTION | C3: AMOUNT (INR) | D3: REMARKS
E4: `
A5: 1 | B5: FA&PA | C5: ='FA&PA'!F74 -> 0
A6: 2 | B6: Water Leak Detection | C6: ='Water Leak Detection'!F17 -> 0
A7: 3 | B7: Rodent | C7: =Rodent!F13 -> 0
A8: 4 | B8: Exit Signage | C8: ='Exit Signage'!F14 -> 0
A9: 5 | B9: Vesda | C9: =Vesda!F28 -> 0
B11: GRAND TOTAL | C11: =SUM(C5:C10) -> 0

Sheet FA&PA
A1: PROJECT : DHL - Chennai
A2: SUBJECT : FA&PA
A3: SL.NO | B3: ITEM DESCRIPTION | C3: UNIT | D3: QTY | E3: SUPPLY & INSTALLATION
E4: RATE (INR) | F4: AMOUNT (INR)
B6: INTELLIGENT ADDRESSABLE FIRE ALARM AND EVACUATION SYSTEM
B7: The Panel shall be suitable for BMS connectivity. Provide bacnet card for BMS integration.
B8: The Builder Main Fire Panel shall have 2 way communication with Main Fire Panel. In case of fire signal all the access control doors shall deactivate.
B9: The access control doors will get de activated for people evacuation
B10: Emergency evacuation message will pass through public address system automatically
B11: Dampers will get deactivated through the modules to close the air movement.
B12: The Flow switch shall be monitored on our Fire Panel.
B13: Supply, Installation, Testing and Commissioning of the following:
A15: 1 | B15: UL listed & FM Approved Intelligent Addressable Rate of Rise Heat detectors with blinking LED and standard base, being capable of addressed electronically. Manual Addressing Detector shall have Automatic device mapping capability. | C15: Nos | D15: 20 | F15: =E15*D15 -> 0
A17: 2 | B17: UL listed & FM Approved Intelligent Addressable Smoke detector, optical type with blinking LED and standard base, being capable of addressed electronically. Manual Addressing. Detector shall have Automatic device mapping capability. | C17: Nos | D17: 350 | F17: =E17*D17 -> 0
A19: 3 | B19: UL listed & FM Approved Intelligent Addressable Smoke detector, optical type with blinking LED and being capable of addressed electronically with Sounder Base. Manual Addressing Detector shall have Automatic device mapping capability. | C19: Nos | D19: 70 | F19: =E19*D19 -> 0
A21: 4 | B21: UL listed & FM Approved Intelligent Addressable Multi-Criteria smoke cum Heat detector, optical type with blinking LED and standard base, being capable of addressed electronically. Manual Addressing. Detector shall have Automatic device mapping capability. | C21: Nos | D21: 0 | F21: =E21*D21 -> 0
A23: 5 | B23: Response Indicator | C23: Nos | D23: 105 | F23: =E23*D23 -> 0
A25: 6 | B25: UL Listed & FM Approved Intelligent Addressable Double action manual pull station, capable of being addressed electronically. Manual Addressing, it shall have Automatic device mapping capability complete as required.and as per specifications.The MCP should be with double pole manual break glass for breaking glass and fire status . | C25: Nos | D25: 14 | F25: =E25*D25 -> 0
A27: 7 | B27: UL Listed & FM Approved Fire Alarm Hooter (sound output of minimum 90 dB upto a distance of 30 meters) cum Strobe (Selectable 15, 30, 75, or 110 cd), made Addressable with the help of Intelligent Addressable Signal Module (cost of the Module to be included), module capable of being addressed electronically. Manual Addressing, with seperate power supply arrangement complete as required. Module shall have Automatic device mapping capability. | C27: Nos | D27: 14 | F27: =E27*D27 -> 0
A29: 8 | B29: UL Listed & FM Approved Addressable control module complete as required for switching ON of smoke extraction fans / Pressurisation Fans etc. and switching off AHU' s, capable of being addressed electronically. Manual Addressing complete as required.and as per specifications. It shall have Automatic device mapping capability. | C29: Nos | D29: 25 | F29: =E29*D29 -> 0
A31: 9 | B31: UL Listed & FM Approved Addressable Monitor module complete as required for monitoring flow switches/ interface with any third party equipment capable of being addressed electronically. Manual Addressing , complete as required.and as per specifications. It shall have Automatic device mapping capability. | C31: Nos | D31: 30 | F31: =E31*D31 -> 0
A33: 10 | B33: UL Listed & FM Approved Addressable Fault Isolator module complete as required for determining the short in a circuit and separating the segment having the short capable of being addressed electronically. Manual Addressing, complete as required.and as per specifications. It shall have Automatic device mapping capability. | C33: Nos | D33: 20 | F33: =E33*D33 -> 0
A35: 11 | B35: UL Listed & FM Approved 2W High Fidelity (520 Hz) Ceiling Mounted speaker with capacity to have 2 watt tapping, working at 84dB compatible with amplifier complete as required. | C35: Nos | D35: 96 | F35: =E35*D35 -> 0
A37: 12 | B37: UL Listed & FM Approved 2W High Fidelity (520 Hz) Wall/Surface Mounted speaker and 2 watt tapping, working at 84dB compatible with amplifier complete as required.Provide circular back boxes for the above speakers | C37: Nos | D37: 35 | F37: =E37*D37 -> 0
... A43: 15 | B43: UL Listed Telephone handset for fire fighters telephone system with suitable enclosure. | C43: Nos | D43: 2 | F43: =E43*D43 -> 0
A45: 16 | B45: Microprocessor based Multi-loop, True Peer-to-Peer Networkable Addressable Fire Alarm Control Panel with minimum 600 characters LCD display, 4000 event plus 1000 alarm log history events, QWERTY keypad for programming. The panel should be equipped with sufficient numbers of loops considering 20% spare capacity in each loop. Each loop shall have a capacity of minimum 300 analog addressable devices. The panel shall work in degrade mode in case of CPU failure, Products not having this feature may offer Redundant CPU. Four access levels, flash EPROM, 240 volts AC power supply, automatic battery charger, 24 volts sealed lead acid batteries sufficient for 24 hours normal working and 30 mins in alarm condition. The panel shall be complete with Integrated 8 channel Digital Voice Evacuation System Controller capable of broadcasting Evacuation Messages on same peer-to-peer Network. The system shall be equipped with necessary Digital Audio Amplifier capable of processing one of 8 audio channels and amplifiers as per the speakers requirement at 70.7 VRMS output along with necessary enclosures. The DAA shall be fully monitored for fault and alarm reporting. The proposed Digital Amplifiers shall not be rail mounted / dependant on Fire Panel CPU for operation. Failure of Fire Panel CPU shall not result in failure of Amplifier operation. The Digital Amplifier Loop shall have N+1 Redundancy concept to avoid chances of failure. The Fire Fighters Telephone System shall be capable of having minimum 20 Telephones on conference. The panel shall have a built in power supply and battery charger along with maintenance free 24 AH, 2 x 12 volt SMF Lead acid batteries capable of running for a minimum of 8 hours with battery charger complete as required. The panel should have a plug in Microphone for important manual messaging if required.
A46: a | B46: 16 Loop Panel | C46: Nos | D46: 0 | F46: =E46*D46 -> 0
A47: b | B47: 8 Loop Panel | C47: Nos | D47: 0 | F47: =E47*D47 -> 0
A48: c | B48: 6 Loop Panel | C48: Nos | D48: 1 | F48: =E48*D48 -> 0
B50: it shall also include the following :
B51: The FACP shall contain all equipment required for all audio control, 100 W amplifier telephone system control, signalling and supervisory functions. This includes speaker zone indication, telephone circuit indication and control, digital voice units, microphone and main telephone handset. The amplifier rating shall be as per the speakers quantities
B52: Function: The EVAC system equipment shall perform following functions:
B53: Operate as a two-way emergency telephone system control center.
B54: Audibly and visually annunciate the active or trouble condition of every speaker circuit and telephone circuit.
B55: Audibly and visually annunciate any trouble condition of tone generators and digital voice units required for normal operation of the system.
B56: Provide automatic, digitally-recorded voice messages and tones which may be field-programmed through the microphone.
B57: Suitable nos. of Digital Audio Amplifier ( 100 Watts each ) capable of processing One of 8 audio channels at 70.7 VRMS output along with necessary enclosures. The Digital Audio Amplifier shall be fully monitored for fault and alarm reporting. The proposed Digital Audio Amplifiers shall (be Wall/Panel Mounted) not be rail mounted / dependant on Fire Panel CPU for operation. Failure of Fire Panel CPU shall not result in failure of Amplifier operation. rate of the same shall be included in above fire panel item. The Amplifier size shall be 20% extra.
B58: Necessary Integration Facility with BMS for following functions:-
B59: Alarm, Trouble condition, Supervisory alerts to BMS
B60: Share Graphics of Security, Fire and HVAC
...

Sheet Water Leak Detection
A1: PROJECT : DHL - Chennai
A2: SUBJECT : Water Leak Detection
A3: SL.NO | B3: ITEM DESCRIPTION | C3: UNIT | D3: QTY | E3: SUPPLY & INSTALLATION
E4: RATE (INR) | F4: AMOUNT (INR)
A6: 1 | B6: Supply Installation, Testing and comissioning of Conventional Water Leak Detection Panel, The Panel should be complete with Power Supply units for Hooter mounted outside each critical room. | C6: Nos. | D6: 4 | F6: =E6*D6 -> 0
A8: 2 | B8: Supply Installation, Testing and comissioning of Sensor interface module. Mounted on false floor pedestal with sutable clamp. Note:- SIM should be able to provide PF Contact for FAS/BMS Integration. | C8: Nos. | D8: 4 | F8: =E8*D8 -> 0
A10: 3 | B10: Supply Installation, Testing and comissioning of "UL Listed" WLD Digital sensing cable : Cable shall have Jacket on top to avoid false alarm, Hold Down Clips with adhesive backs, cable connectors, end termination plugs etc.
A11: a | B11: 15 Mtrs. Length | C11: Nos. | D11: 6 | F11: =E11*D11 -> 0
A13: 4 | B13: Supply Installation, Testing and comissioning of Communication Cable for networking between WLD Serial Interface Modules and Panel : (Beldon 8723 or Equivalent as ratified by the WLD OEM) Typical Specs : FRLS 1 Twisted Pair x 1.5 mm2, Multistrand Copper conductor, (Armoured or flexible in GI Conduit including the conduit), Black in Colour, Shielded individually with Al-Mylar Tape, and 0.5 mm2 Drain wire. Complete with GI Junction Boxes, lugs, cable compression glands, cable tags and Ferruling. | C13: Mtr | D13: 60 | F13: =E13*D13 -> 0
A15: 5 | B15: Supply Installation, Testing and comissioning of Hooter cum strobe for WLD system complete with required accessories. Location - Outside each critical room | C15: Nos. | D15: 4 | F15: =E15*D15 -> 0
B17: GRAND TOTAL | F17: =SUM(F6:F16) -> 0

Sheet Rodent
A1: PROJECT : DHL - Chennai
A2: SUBJECT : Rodent
A3: SL.NO | B3: ITEM DESCRIPTION | C3: UNIT | D3: QTY | E3: SUPPLY & INSTALLATION
E4: RATE (INR) | F4: AMOUNT (INR)
B6: Supply, Installation & Commissioning of Rodent Systems.
A7: 1 | B7: Supply Installation, Testing and comissioning of Main Panel wall mounting type with facility to connect 24 satellites in one zone. | C7: Nos | D7: 4 | F7: =E7*D7 -> 0
A9: 2 | B9: Supply Installation, Testing and comissioning of Transducer Satellite Stations capable of Emitting Ultrasonic sound of frequencies 20 Khz and higher, with blinking LED Indication & shall capable to covering area of 500 Sq.ft. complete with required mounting accessories. | C9: Nos | D9: 40 | F9: =E9*D9 -> 0
A11: 3 | B11: Supply Installation of FRLS 1 pair Armoured 14/40 SWG Specially coated wire, PVC sheathed Cable on surface with hot dip GI Saddels and spacers at evry 0.3 meter. | C11: Mtrs | D11: 280 | F11: =E11*D11 -> 0
B13: GRAND TOTAL | F13: =SUM(F6:F12) -> 0

Sheet Exit Signage
A1: PROJECT : DHL - Chennai
A2: SUBJECT : Exit Signage
A3: SL.NO | B3: ITEM DESCRIPTION | C3: UNIT | D3: QTY | E3: SUPPLY & INSTALLATION
E4: RATE (INR) | F4: AMOUNT (INR)
B6: Note : Vendor to visit the construction site, understanding the building, structure, beams, roofs, ceiling etc., for the benefit of quoting completely on several perspectives such as mobilisation, Logistics, storage, Instalation, Support systems to the I beams Purlins etc.,
B7: Note: It is proposed to achieve LEED Gold Certification for this building. Vendor to go through the LEED documents & comply to the requirement in reference to this BOQ & Specification.
A9: 1 | B9: Supply, Installation, Testing and Commissioning of Self contained Emergency Exit Signages comprising of following :
A10: a | B10: Supply Installation Testing and comissioning of FLUSH MOUNT DUAL SIDED, Maintained 3 Watt LED, FIRE Exit luminaires, Sheet metal Body, Painted to RAL 9010, Pictogram 280 (I) X 130(W), with spring supports, Legend with clear acrylic/engraved pattern to be fully compliant with requirements of designed and installed to meet the fire and safety code of practice & the respective EN 60598-2-22 and the system designed in compliance with EN50171, EN50272-2, EN50172, and EN1838 standards EN Standards, IP 20 with NiCad 2 x 1.2V Battery Backup for 90 Minutes operation in following formats as per Layouts : Right Arrow, Left Arrow, Down Arrow, Both sides etc. Input Supply : 220 V AC ±10% | C10: Nos | D10: 36 | F10: =E10*D10 -> 0
A12: b | B12: Supply Installation Testing and comissioning of SURFACE MOUNT SINGLE SIDED, Maintained 3 Watt LED, FIRE Exit luminaires, Sheet metal Body, Painted to RAL 9010, Pictogram 280 (I) X 130(W), Legend with clear acrylic/engraved pattern to be fully compliant with requirements of designed and installed to meet the fire and safety code of practice & the respective EN 60598-2-22 and the system designed in compliance with EN50171, EN50272-2, EN50172, and EN1838 standards EN Standards, IP 20 with NiCad 2 x 1.2V Battery Backup for 90 Minutes operation in following formats as per Layouts : Right Arrow, Left Arrow, Down Arrow, Both sides etc. Input Supply : 220 V AC ±10% | C12: Nos | D12: 20 | F12: =E12*D12 -> 0
B14: GRAND TOTAL | F14: =SUM(F10:F13) -> 0

Sheet Vesda
A1: PROJECT : DHL - Chennai
A2: SUBJECT : Vesda
A3: SL.NO | B3: ITEM DESCRIPTION | C3: UNIT | D3: QTY | E3: SUPPLY & INSTALLATION
E4: RATE (INR) | F4: AMOUNT (INR)
B6: VESDA ASPIRATING SMOKE DETECTION SYSTEM
B7: For Hub Rooma and server rooms.
B8: 1. Should be BMS Compatible
B9: 2. Modbus and interface card over RS485 output to be provided
B10: 3. Termination of cables in the respective device
B11: Make : Honeywell /Xtralis
A12: 1 | B12: Supply, installation, testing and commissioning of the following VESDA (Very Early Smoke Detection and Alarm System).
B13: The Panels Shall be BMS comptable.
B14: Supply, installation, testing and commissioning of UL & FM certified Laser-Based Absolute Smoke Detection system with single pipe inlet aspiration detector for Up to 500 m2 (5000 sq. ft.) coverage; 50m linear pipe & 30m branched pipe; Wide sensitivity range; 3 alarm levels; High efficiency aspirator; Clean air barrier optics protection; Easy to replace air filter; 3 relays; AutoLearn; Referencing; Event log. Alarm Threshold Setting Range: (0.005%–20% obs/m) & Instant Fault Finder. The cost should includes power supply unit for the controller VESDA Model Similar to VLF 500 [Vendor to selct the model as per room dimension given with sampling holes to be consider for room & false floor & also return air path] | C14: Nos. | D14: 4 | F14: =E14*D14 -> 0
A16: 2 | B16: Power supply unit for above detector | C16: Nos. | D16: 4 | F16: =E16*D16 -> 0
A18: 3 | B18: Aspiration tubes UPVC | C18: RM | D18: 50 | F18: =E18*D18 -> 0
A20: 4 | B20: Capillary tubes | C20: Nos. | D20: 16 | F20: =E20*D20 -> 0
A22: 5 | B22: Air termination ( Nozzles) | C22: Nos. | D22: 32 | F22: =E22*D22 -> 0
A24: 6 | B24: Electronic Hooter | C24: Nos | D24: 4 | F24: =E24*D24 -> 0
A26: 7 | B26: Supply and surface laying of 2 c x 1.5 sq mm armoured copper cable | C26: RM | D26: 60 | F26: =E26*D26 -> 0
B28: GRAND TOTAL | F28: =SUM(F14:F27) -> 0

Sheet Networking
A1: PROJECT : DHL CHENNAI
A2: BOQ : Networking
A3: SL.NO | B3: ITEM DESCRIPTION | C3: UNIT | D3: QTY | E3: RATE (INR) | F3: Amount(INR)
A5: Supply Components-DATA Nodes-Cat6
A7: 1 | B7: Cat 6 UTP Mounting Cord,7 ft, Color Light Blue for User ends | C7: Nos. | D7: 1986 | F7: =E7*D7 -> 0
A8: 2 | B8: 1-port face plate of size 3x3 with shutter, Color White | C8: Nos. | D8: 25 | F8: =E8*D8 -> 0
A9: 3 | B9: 2-port face plate of size 3x3 with Shutter, Color White | C9: Nos. | D9: 914 | F9: =E9*D9 -> 0
A10: 4 | B10: 4-port face plate of size 3x3 with Shutter, Color White | C10: Nos. | D10: 69 | F10: =E10*D10 -> 0
A11: 5 | B11: Cat 6 UTP Information Outlets, Color Blue for User ends | C11: Nos. | D11: 1986 | F11: =E11*D11 -> 0
A12: 6 | B12: 4-Pair, Cat6, UTP Cable (305 mt. Roll) | C12: Roll | D12: 359 | F12: =E12*D12 -> 0
A13: 7 | B13: Patch Panel, unloaded, 24-port -Angular Data | C13: Nos. | D13: 83 | F13: =E13*D13 -> 0
A14: 8 | B14: Cat 6 UTP Information Outelts,Color Blue for Rack ends | C14: Nos. | D14: 1992 | F14: =E14*D14 -> 0
A15: 9 | B15: Cat 6 UTP Mounting Cord, 7 ft, Color Light Blue Rack end | C15: Roll | D15: 1986 | F15: =E15*D15 -> 0
A17: Supply Components-Fiber Cable & Fiber Accessories--2Runs x 6Core Fiber MM
A19: 1 | B19: 6-Core MM 50/125 micron OM4 Armoured Fiber Cable, LSZH | C19: Mtr | D19: 250 | F19: =E19*D19 -> 0
A20: 2 | B20: High Density 1U Sliding fiber Splice Panel, accepts (4) G2 modules, providing up to 48 duplex LC ports, accepts splice wallets, | C20: Nos | D20: 0 | F20: =E20*D20 -> 0
A21: 3 | B21: 360G2 Cartridge, 12-LC-LS-AQ-Pigtails, LazrSPEED, Aqua w/Pigtails | C21: Nos | D21: 0 | F21: =E21*D21 -> 0
A22: 4 | B22: RoloSplice Kit E/W 2 Fusion Splice Trays, for 1U Shelf | C22: Nos | D22: 0 | F22: =E22*D22 -> 0
A23: 5 | B23: Blank Panel | C23: Nos | D23: 0 | F23: =E23*D23 -> 0
A24: 6 | B24: LC-LC Style MM 50/125 micron Duplex OM4 Patch Cord, 3 Meter | C24: Nos | D24: 0 | F24: =E24*D24 -> 0
A25: 7 | B25: LC-LC Style MM 50/125 micron Duplex OM4 Patch Cord, 5 Meter | C25: Nos | D25: 0 | F25: =E25*D25 -> 0
A27: Supply Components-Network Rack & Accessories
A29: 1 | B29: 42U Rack/Powder Coated | C29: Nos | D29: 6 | F29: =E29*D29 -> 0
A30: 2 | B30: High Density Vertical Cable Organiser/8 inch/Front & Back | C30: Nos | D30: 14 | F30: =E30*D30 -> 0
A31: 3 | B31: Run-Way Kit-20Inch | C31: Nos | D31: 7 | F31: =E31*D31 -> 0
A32: 4 | B32: Mounting Hardware/OR/Pk-20 | C32: Nos | D32: 5 | F32: =E32*D32 -> 0
A33: 5 | B33: IT Rack mount power distribution unit, 1Ph, 230V, 16A, 50/60Hz, 2U standard with 6 X Indian Round Pin 5/15A, Inlet Plug type 16A Indian Round Pin, 16A MCB - | C33: Nos | D33: 14 | F33: =E33*D33 -> 0
A35: Supply Components-Misc Items for Cabling
